Workbook

Sheet Test cases 
A1: ID | B1: Scenario ID | C1: Title | D1: Test Suite | E1: Page | F1: Severity | G1: Priority | H1: Execution Status | I1: Test Type | J1: Environment | K1: Preconditions | L1: Test Data | M1: Test Steps | N1: Expected Result | O1: Actual Result | P1: Assumption Ref | Q1: Defect ID | R1: Traceability | S1: Note | T1: Review Status
A2: TC-001 | B2: TS-001 | C2: MOE HQ User accesses national MOEFAS budget management view | D2: F6.1 Access & Authorization | E2: FAS Budget Management | F2: S1 (highest) | G2: Critical | H2: Not Run | I2: Functional | J2: Admin Portal: http://localhost:5173 Needs: ENV-R6-01 | K2: 1. Active MOE HQ user exists in IAM (moehq / Mei Lin Tan). 2. User is signed in to Admin Portal. | L2: User: Mei Lin Tan (moehq), Scheme: MOEFAS | M2: 1. Open Admin Portal. 2. Navigate to budget management view (menu name to be confirmed when built). 3. Observe page view and FAS scheme. | N2: 1. MOE HQ user successfully accesses budget management view. 2. FAS Type displays 'MOEFAS' as read-only label. 3. Budget amount input field is accessible for configuration. | P2: ASM-R6-13 | R2: FS06: 1.2, 5.1.3, BR6.01, R6-02 | S2: Navigation path provisional until UI built. | T2: Draft
A3: TC-002 | B3: TS-001 | C3: MOE HQ User views national MOEFAS budget without school restrictions | D3: F6.1 Access & Authorization | E3: FAS Budget Management | F3: S2 | G3: High | H3: Not Run | I3: Functional | J3: Admin Portal: http://localhost:5173 Needs: ENV-R6-01 | K3: 1. Signed in as MOE HQ User (Mei Lin Tan). | L3: Scheme: MOEFAS | M3: 1. Open MOEFAS budget management view. 2. Check scope indicators. | N3: 1. View displays national scheme-level scope. 2. User is not locked to or restricted by any specific school ID. | P3: N/A | R3: FS06: 1.2, BR6.01, R6-02 | S3: HQ national scope confirmation. | T3: Approve
A4: TC-003 | B4: TS-002 | C4: School User accesses SBFAS budget view pre-populated with assigned school | D4: F6.1 Access & Authorization | E4: FAS Budget Management | F4: S1 (highest) | G4: Critical | H4: Not Run | I4: Functional | J4: Admin Portal: http://localhost:5173 Needs: ENV-R6-01 | K4: 1. School Admin signed in (Bukit View Primary School, Lan Nguyen). | L4: User: Lan Nguyen, School: Bukit View Primary School (BVP-0012) | M4: 1. Open budget management view. 2. Inspect displayed School name and FAS Type. | N4: 1. Page displays School name 'Bukit View Primary School' as read-only text. 2. FAS Type displays 'SBFAS' as read-only text. 3. School user cannot change the school name. | P4: N/A | R4: FS06: 1.2, 5.2.3, BR6.01, R6-03 | S4: School Admin scoped access. | T4: Approve
A5: TC-004 | B5: TS-003 | C5: School User calling SBFAS API with another school ID receives 403 Forbidden | D5: F6.1 Access & Authorization | E5: FAS Budget Management | F5: S1 (highest) | G5: Critical | H5: Not Run | I5: Security | J5: API Gateway: http://localhost:5273 Needs: ENV-R6-01 | K5: 1. Authenticated as School Admin of Bukit View Primary (BVP-0012). | L5: Assigned School: BVP-0012, Target School: MRS-0012 (Meridian Secondary) | M5: 1. Send API GET or POST request to SBFAS budget endpoint supplying schoolId = 'MRS-0012'. 2. Inspect HTTP status code and response body. | N5: 1. API rejects request with HTTP 403 Forbidden. 2. Response body contains message: 'Access denied. You do not have permission to access or modify this budget record.' | P5: N/A | R5: FS06: 1.2, BR6.01, R6-09 | S5: Data isolation boundary enforcement. | T5: Approve
A6: TC-005 | B6: TS-003 | C6: School User calling MOEFAS budget API receives 403 Forbidden | D6: F6.1 Access & Authorization | E6: FAS Budget Management | F6: S1 (highest) | G6: Critical | H6: Not Run | I6: Security | J6: API Gateway: http://localhost:5273 Needs: ENV-R6-01 | K6: 1. Authenticated as School Admin (Lan Nguyen). | L6: Endpoint: /api/fas/v1/budgets/moefas | M6: 1. Send POST/PUT request to MOEFAS budget endpoint with valid payload. 2. Inspect response status code. | N6: 1. API rejects request with HTTP 403 Forbidden. 2. School Admin is prohibited from modifying MOEFAS national budget. | P6: N/A | R6: FS06: 1.2, BR6.01, R6-02 | S6: Cross-role security boundary. | T6: Approve
A7: TC-006 | B7: TS-003 | C7: MOE HQ User calling SBFAS school budget API directly receives 403 Forbidden | D7: F6.1 Access & Authorization | E7: FAS Budget Management | F7: S2 | G7: High | H7: Not Run | I7: Security | J7: API Gateway: http://localhost:5273 Needs: ENV-R6-01 | K7: 1. Authenticated as MOE HQ (Mei Lin Tan). | L7: Endpoint: /api/fas/v1/budgets/sbfas, SchoolId: BVP-0012 | M7: 1. Send POST/PUT request to set SBFAS budget for BVP-0012 directly. 2. Inspect response status code. | N7: 1. API rejects request with HTTP 403 Forbidden. 2. MOE HQ cannot override individual school SBFAS budget without delegation. | P7: N/A | R7: FS06: 1.2, BR6.01, R6-03 | S7: HQ to School boundary isolation. | T7: Approve
A8: TC-007 | B8: TS-003 | C8: Unauthenticated user redirected to login when accessing budget routes | D8: F6.1 Access & Authorization | E8: Login Page | F8: S2 | G8: High | H8: Not Run | I8: Security | J8: Admin Portal: http://localhost:5173 Needs: ENV-R6-01 | K8: 1. Browser session has no JWT token or authentication cookie. | L8: URL: http://localhost:5173/fas-budget-management | M8: 1. Directly input budget management URL into browser address bar. 2. Press Enter. | N8: 1. System redirects immediately to login page. 2. No budget data or dashboard elements are rendered. | P8: ASM-R6-13 | R8: FS06: 5.1.2, 5.2.2 | S8: Route guard check. | T8: Draft
A9: TC-008 | B9: TS-004 | C9: Configure MOEFAS budget with valid whole number amount | D9: F6.2 MOEFAS Budget Setup | E9: FAS Budget Management | F9: S1 (highest) | G9: Critical | H9: Not Run | I9: Functional | J9: Admin Portal: http://localhost:5173 Needs: ENV-R6-01 | K9: 1. Signed in as MOE HQ (Mei Lin Tan). 2. MOEFAS budget configuration form open. | L9: Budget Amount: 5000000 | M9: 1. Enter 5000000 into Budget Amount input field. 2. Click Save button. | N9: 1. Budget amount is saved successfully. 2. System displays confirmation message: 'Budget amount has been successfully configured and saved.' 3. Configured Budget Amount displays 'S$ 5,000,000.00'. | P9: ASM-R6-09 | R9: FS06: 5.1.4, AC-R6.1.1, R6-04 | S9: Happy path integer budget. | T9: Draft
A10: TC-009 | B10: TS-004 | C10: Configure MOEFAS budget with valid 2-decimal places (cents) | D10: F6.2 MOEFAS Budget Setup | E10: FAS Budget Management | F10: S2 | G10: High | H10: Not Run | I10: Functional | J10: Admin Portal: http://localhost:5173 Needs: ENV-R6-01 | K10: 1. Signed in as MOE HQ. 2. Form open. | L10: Budget Amount: 7500000.50 | M10: 1. Enter 7500000.50 into Budget Amount field. 2. Click Save button. | N10: 1. Budget is saved successfully. 2. Configured Budget Amount displays 'S$ 7,500,000.50'. | P10: ASM-R6-09 | R10: FS06: 5.1.4, R6-04 | S10: Valid decimal cents input. | T10: Draft
A11: TC-010 | B11: TS-004 | C11: Configure MOEFAS budget with 0.00 as valid initial allocated budget | D11: F6.2 MOEFAS Budget Setup | E11: FAS Budget Management | F11: S2 | G11: High | H11: Not Run | I11: Functional | J11: Admin Portal: http://localhost:5173 Needs: ENV-R6-01 | K11: 1. Signed in as MOE HQ. | L11: Budget Amount: 0.00 | M11: 1. Enter 0.00 into Budget Amount field. 2. Click Save button. | N11: 1. Budget amount 0.00 is accepted and saved. 2. Configured Budget Amount displays 'S$ 0.00'. | P11: ASM-R6-09 | R11: FS06: 5.1.4, BR6.03, R6-04 | S11: Zero budget valid initial state. | T11: Draft
A12: TC-011 | B12: TS-004 | C12: Validation error when MOEFAS Budget Amount is left empty | D12: F6.2 MOEFAS Budget Setup | E12: FAS Budget Management | F12: S2 | G12: High | H12: Not Run | I12: Functional | J12: Admin Portal: http://localhost:5173 Needs: ENV-R6-01 | K12: 1. Signed in as MOE HQ. 2. Budget Amount field cleared. | L12: Budget Amount: (empty) | M12: 1. Leave Budget Amount field empty. 2. Click Save button. | N12: 1. Save operation is blocked. 2. Field validation displays error: 'Budget amount is required.' | P12: N/A | R12: FS06: 5.1.3 | S12: Required field validation. | T12: Approve
A13: TC-012 | B13: TS-004 | C13: Validation error when entering alphabetic characters in Budget Amount | D13: F6.2 MOEFAS Budget Setup | E13: FAS Budget Management | F13: S2 | G13: High | H13: Not Run | I13: Functional | J13: Admin Portal: http://localhost:5173 Needs: ENV-R6-01 | K13: 1. Signed in as MOE HQ. | L13: Input: 'five million' | M13: 1. Enter 'five million' into Budget Amount field. 2. Click Save button. | N13: 1. Field validation displays error: 'Budget amount must be a valid numeric value.' 2. Form submission is prevented. | P13: N/A | R13: FS06: 5.1.3 | S13: Non-numeric input rejected. | T13: Approve
... A57: TC-056 | B57: TS-018 | C57: Separate budget tracking view for MOEFAS national scheme | D57: F6.7 Budget Tracking | E57: FAS Budget Tracking | F57: S2 | G57: High | H57: Not Run | I57: Functional | J57: Admin Portal: http://localhost:5173 Needs: ENV-R6-01, ENV-R6-03 | K57: 1. Signed in as MOE HQ. 2. National MOEFAS budget configured. | L57: Scheme: MOEFAS | M57: 1. Open MOEFAS Budget Tracking view. | N57: 1. View displays national MOEFAS Budget Amount, national Subsidy Amount Used, and Remaining Budget. 2. Values reflect nationwide aggregation. | P57: N/A | R57: FS06: 5.7.1, R6.3.1 | S57: Dedicated MOEFAS tracking. | T57: Approve

Sheet Defect Reports
A1: Defect ID | B1: Defect Summary | C1: Severity | D1: Priority | E1: Status | F1: Defect Type | G1: Environment | H1: Preconditions | I1: Steps to Reproduce | J1: Expected Result | K1: Actual Result | L1: Linked Test Case(s) | M1: Evidence | N1: Notes

Sheet Scenarios
A1: Scenario ID | B1: Test suite | C1: Scenario | D1: Objective | E1: Technique | F1: FS source | G1: Test cases | H1: Approve | I1: Draft | J1: Block | K1: Status
A2: TS-001 | B2: F6.1 Access & Authorization | C2: MOE HQ User Access & Navigation | D2: Verify MOE HQ can access MOEFAS budget management without school barriers. | E2: Equivalence partitioning | F2: FS06: 1.2, 5.1 | G2: =COUNTIF('Test cases '!$B$2:$B$57,$A2) | H2: =COUNTIFS('Test cases '!$B$2:$B$57,$A2,'Test cases '!$T$2:$T$57,"Approve") | I2: =COUNTIFS('Test cases '!$B$2:$B$57,$A2,'Test cases '!$T$2:$T$57,"Draft") | J2: =COUNTIFS('Test cases '!$B$2:$B$57,$A2,'Test cases '!$T$2:$T$57,"Block") | K2: =IF(J2=G2,"Block",IF(J2>0,"Partly blocked",IF(I2>0,"Draft","Approve")))
A3: TS-002 | B3: F6.1 Access & Authorization | C3: School User Access & Pre-population | D3: Verify School User accesses SBFAS with pre-filled school name and locked scope. | E3: Equivalence partitioning | F3: FS06: 1.2, 5.2 | G3: =COUNTIF('Test cases '!$B$2:$B$57,$A3) | H3: =COUNTIFS('Test cases '!$B$2:$B$57,$A3,'Test cases '!$T$2:$T$57,"Approve") | I3: =COUNTIFS('Test cases '!$B$2:$B$57,$A3,'Test cases '!$T$2:$T$57,"Draft") | J3: =COUNTIFS('Test cases '!$B$2:$B$57,$A3,'Test cases '!$T$2:$T$57,"Block") | K3: =IF(J3=G3,"Block",IF(J3>0,"Partly blocked",IF(I3>0,"Draft","Approve")))
A4: TS-003 | B4: F6.1 Access & Authorization | C4: Data Isolation & Security Guards | D4: Ensure strict 403 Forbidden on cross-school budget access and redirect on unauthenticated. | E4: Security testing | F4: FS06: BR6.01, R6-09 | G4: =COUNTIF('Test cases '!$B$2:$B$57,$A4) | H4: =COUNTIFS('Test cases '!$B$2:$B$57,$A4,'Test cases '!$T$2:$T$57,"Approve") | I4: =COUNTIFS('Test cases '!$B$2:$B$57,$A4,'Test cases '!$T$2:$T$57,"Draft") | J4: =COUNTIFS('Test cases '!$B$2:$B$57,$A4,'Test cases '!$T$2:$T$57,"Block") | K4: =IF(J4=G4,"Block",IF(J4>0,"Partly blocked",IF(I4>0,"Draft","Approve")))
A5: TS-004 | B5: F6.2 MOEFAS Budget Setup | C5: MOEFAS Budget Input Validation | D5: Validate required, numeric, positive, decimals, max cap, and whitespace handling. | E5: Boundary & Negative | F5: FS06: 5.1.3, BR6.03 | G5: =COUNTIF('Test cases '!$B$2:$B$57,$A5) | H5: =COUNTIFS('Test cases '!$B$2:$B$57,$A5,'Test cases '!$T$2:$T$57,"Approve") | I5: =COUNTIFS('Test cases '!$B$2:$B$57,$A5,'Test cases '!$T$2:$T$57,"Draft") | J5: =COUNTIFS('Test cases '!$B$2:$B$57,$A5,'Test cases '!$T$2:$T$57,"Block") | K5: =IF(J5=G5,"Block",IF(J5>0,"Partly blocked",IF(I5>0,"Draft","Approve")))
A6: TS-005 | B6: F6.2 MOEFAS Budget Setup | C6: MOEFAS Save, Cancel & Display | D6: Verify save persistence, toast messages, and cancel action reverting changes. | E6: Functional testing | F6: FS06: 5.1.4, AC-R6.1.1 | G6: =COUNTIF('Test cases '!$B$2:$B$57,$A6) | H6: =COUNTIFS('Test cases '!$B$2:$B$57,$A6,'Test cases '!$T$2:$T$57,"Approve") | I6: =COUNTIFS('Test cases '!$B$2:$B$57,$A6,'Test cases '!$T$2:$T$57,"Draft") | J6: =COUNTIFS('Test cases '!$B$2:$B$57,$A6,'Test cases '!$T$2:$T$57,"Block") | K6: =IF(J6=G6,"Block",IF(J6>0,"Partly blocked",IF(I6>0,"Draft","Approve")))
A7: TS-006 | B7: F6.3 SBFAS Budget Setup | C7: SBFAS School Scoping & Read-only Type | D7: Verify school name and SBFAS scheme cannot be tampered with. | E7: Security & Functional | F7: FS06: 5.2.3, BR6.01 | G7: =COUNTIF('Test cases '!$B$2:$B$57,$A7) | H7: =COUNTIFS('Test cases '!$B$2:$B$57,$A7,'Test cases '!$T$2:$T$57,"Approve") | I7: =COUNTIFS('Test cases '!$B$2:$B$57,$A7,'Test cases '!$T$2:$T$57,"Draft") | J7: =COUNTIFS('Test cases '!$B$2:$B$57,$A7,'Test cases '!$T$2:$T$57,"Block") | K7: =IF(J7=G7,"Block",IF(J7>0,"Partly blocked",IF(I7>0,"Draft","Approve")))
A8: TS-007 | B8: F6.3 SBFAS Budget Setup | C8: SBFAS Budget Input Validation & Save | D8: Verify input validations and successful save for school admin. | E8: Equivalence partitioning | F8: FS06: 5.2.4, AC-R6.1.2 | G8: =COUNTIF('Test cases '!$B$2:$B$57,$A8) | H8: =COUNTIFS('Test cases '!$B$2:$B$57,$A8,'Test cases '!$T$2:$T$57,"Approve") | I8: =COUNTIFS('Test cases '!$B$2:$B$57,$A8,'Test cases '!$T$2:$T$57,"Draft") | J8: =COUNTIFS('Test cases '!$B$2:$B$57,$A8,'Test cases '!$T$2:$T$57,"Block") | K8: =IF(J8=G8,"Block",IF(J8>0,"Partly blocked",IF(I8>0,"Draft","Approve")))
A9: TS-008 | B9: F6.3 SBFAS Budget Setup | C9: Persistence & Idempotent Save | D9: Verify budget persistence across reload and idempotent save handling. | E9: Functional testing | F9: FS06: 5.2.5, R6-04 | G9: =COUNTIF('Test cases '!$B$2:$B$57,$A9) | H9: =COUNTIFS('Test cases '!$B$2:$B$57,$A9,'Test cases '!$T$2:$T$57,"Approve") | I9: =COUNTIFS('Test cases '!$B$2:$B$57,$A9,'Test cases '!$T$2:$T$57,"Draft") | J9: =COUNTIFS('Test cases '!$B$2:$B$57,$A9,'Test cases '!$T$2:$T$57,"Block") | K9: =IF(J9=G9,"Block",IF(J9>0,"Partly blocked",IF(I9>0,"Draft","Approve")))
A10: TS-009 | B10: F6.4 Budget Adjustments | C10: Edit Existing Budget Flow | D10: Verify edit button opens adjustment modal with existing values. | E10: Functional testing | F10: FS06: 5.3.2, G2 | G10: =COUNTIF('Test cases '!$B$2:$B$57,$A10) | H10: =COUNTIFS('Test cases '!$B$2:$B$57,$A10,'Test cases '!$T$2:$T$57,"Approve") | I10: =COUNTIFS('Test cases '!$B$2:$B$57,$A10,'Test cases '!$T$2:$T$57,"Draft") | J10: =COUNTIFS('Test cases '!$B$2:$B$57,$A10,'Test cases '!$T$2:$T$57,"Block") | K10: =IF(J10=G10,"Block",IF(J10>0,"Partly blocked",IF(I10>0,"Draft","Approve")))
A11: TS-010 | B11: F6.4 Budget Adjustments | C11: Save Budget Adjustment Details | D11: Verify adjusted amount and reason are captured and saved. | E11: Functional testing | F11: FS06: 5.1.6, G2, G12 | G11: =COUNTIF('Test cases '!$B$2:$B$57,$A11) | H11: =COUNTIFS('Test cases '!$B$2:$B$57,$A11,'Test cases '!$T$2:$T$57,"Approve") | I11: =COUNTIFS('Test cases '!$B$2:$B$57,$A11,'Test cases '!$T$2:$T$57,"Draft") | J11: =COUNTIFS('Test cases '!$B$2:$B$57,$A11,'Test cases '!$T$2:$T$57,"Block") | K11: =IF(J11=G11,"Block",IF(J11>0,"Partly blocked",IF(I11>0,"Draft","Approve")))
A12: TS-011 | B12: F6.4 Budget Adjustments | C12: Debouncing & Double-click Guard | D12: Verify double clicks do not produce duplicate HTTP requests or records. | E12: Non-functional | F12: FS06: Robustness standard | G12: =COUNTIF('Test cases '!$B$2:$B$57,$A12) | H12: =COUNTIFS('Test cases '!$B$2:$B$57,$A12,'Test cases '!$T$2:$T$57,"Approve") | I12: =COUNTIFS('Test cases '!$B$2:$B$57,$A12,'Test cases '!$T$2:$T$57,"Draft") | J12: =COUNTIFS('Test cases '!$B$2:$B$57,$A12,'Test cases '!$T$2:$T$57,"Block") | K12: =IF(J12=G12,"Block",IF(J12>0,"Partly blocked",IF(I12>0,"Draft","Approve")))
A13: TS-012 | B13: F6.5 MOEFAS Statistics | C13: National MOEFAS Subsidy Aggregation | D13: Verify MOE HQ views total subsidies granted across all schools. | E13: Functional testing | F13: FS06: 5.4.3, AC-R6.2.1 | G13: =COUNTIF('Test cases '!$B$2:$B$57,$A13) | H13: =COUNTIFS('Test cases '!$B$2:$B$57,$A13,'Test cases '!$T$2:$T$57,"Approve") | I13: =COUNTIFS('Test cases '!$B$2:$B$57,$A13,'Test cases '!$T$2:$T$57,"Draft") | J13: =COUNTIFS('Test cases '!$B$2:$B$57,$A13,'Test cases '!$T$2:$T$57,"Block") | K13: =IF(J13=G13,"Block",IF(J13>0,"Partly blocked",IF(I13>0,"Draft","Approve")))
... A31: TS-030 | B31: F6.10 Edge Cases & Security | C31: XSS Sanitization & Server-side Validation | D31: Verify XSS protection in reason and server-side zero-trust validation. | E31: Security testing | F31: FS06: BR6.03, Security standard | G31: =COUNTIF('Test cases '!$B$2:$B$57,$A31) | H31: =COUNTIFS('Test cases '!$B$2:$B$57,$A31,'Test cases '!$T$2:$T$57,"Approve") | I31: =COUNTIFS('Test cases '!$B$2:$B$57,$A31,'Test cases '!$T$2:$T$57,"Draft") | J31: =COUNTIFS('Test cases '!$B$2:$B$57,$A31,'Test cases '!$T$2:$T$57,"Block") | K31: =IF(J31=G31,"Block",IF(J31>0,"Partly blocked",IF(I31>0,"Draft","Approve")))

Sheet Summary
A1: R6 FAS Budget & Statistics: Test Cases v1.0, Summary
A2: Phạm vi: Toàn bộ các test cases chức năng, phân quyền, giao diện, tính toán số dư, cảnh báo và kiểm soát phi ngăn chặn (Non-blocking) cho Requirement R6 theo FS06.md.
A3: Căn cứ: FS06.md (v0.1 Draft) đối chiếu FS04 (FAS Applications & Schemes) và quy tắc kiểm tra hợp lệ R6_FAS_Validation_Rules.md.
A5: Test cases
A6: Measure | B6: Count
A7: Total test cases | B7: =COUNTA('Test cases '!$A$2:$A$57)
A8: Scenarios | B8: =COUNTA(Scenarios!$A$2:$A$31)
A9: Open assumptions and environment items | B9: =COUNTIF(Assumptions!$I$2:$I$20,"Open")
A10: Questions to answer | B10: =COUNTA(Questions!$A$2:$A$25)
A12: By Review Status
A13: Review Status | B13: Count
A14: Approve | B14: =COUNTIF('Test cases '!$T$2:$T$57,"Approve")
A15: Draft | B15: =COUNTIF('Test cases '!$T$2:$T$57,"Draft")
A16: Block | B16: =COUNTIF('Test cases '!$T$2:$T$57,"Block")
A17: Reject | B17: =COUNTIF('Test cases '!$T$2:$T$57,"Reject")
A19: By Execution Status
A20: Execution Status | B20: Count
A21: Not Run | B21: =COUNTIF('Test cases '!$H$2:$H$57,"Not Run")
A22: Passed | B22: =COUNTIF('Test cases '!$H$2:$H$57,"Passed")
A23: Failed | B23: =COUNTIF('Test cases '!$H$2:$H$57,"Failed")
A24: Blocked | B24: =COUNTIF('Test cases '!$H$2:$H$57,"Blocked")
A26: By Severity
A27: Severity | B27: Count
A28: S1 (highest) | B28: =COUNTIF('Test cases '!$F$2:$F$57,"S1 (highest)")
A29: S2 | B29: =COUNTIF('Test cases '!$F$2:$F$57,"S2")
A30: S3 | B30: =COUNTIF('Test cases '!$F$2:$F$57,"S3")
A31: S4 (lowest) | B31: =COUNTIF('Test cases '!$F$2:$F$57,"S4 (lowest)")
A33: By Priority
A34: Priority | B34: Count
A35: Critical | B35: =COUNTIF('Test cases '!$G$2:$G$57,"Critical")
A36: High | B36: =COUNTIF('Test cases '!$G$2:$G$57,"High")
A37: Medium | B37: =COUNTIF('Test cases '!$G$2:$G$57,"Medium")
A38: Low | B38: =COUNTIF('Test cases '!$G$2:$G$57,"Low")
A40: By Test Type
A41: Test Type | B41: Count
A42: Functional | B42: =COUNTIF('Test cases '!$I$2:$I$57,"Functional")
A43: Integration | B43: =COUNTIF('Test cases '!$I$2:$I$57,"Integration")
A44: API | B44: =COUNTIF('Test cases '!$I$2:$I$57,"API")
A45: Security | B45: =COUNTIF('Test cases '!$I$2:$I$57,"Security")
A46: UI | B46: =COUNTIF('Test cases '!$I$2:$I$57,"UI")
...

Sheet Assumptions
A1: ID | B1: Type | C1: Scope | D1: Original gap | E1: Assumption | F1: FS source | G1: Reason | H1: If the answer differs | I1: State | J1: Resolution | K1: Cases that make this assumption | L1: Owner
A2: ENV-R6-01 | B2: Environment | C2: Test Stack | D2: No hosted prototype url specified in FS06 | E2: Testing is performed against Localhost Admin Portal (http://localhost:5173) and API Gateway (http://localhost:5273). | F2: FS06: 1.1 | G2: Standard local dev stack | H2: Tests re-targeted to hosted staging URL. | I2: Open | J2: None yet | K2: All test cases | L2: Dev/QA
A3: ENV-R6-02 | B3: Environment | C3: Concurrency | D3: Need two user sessions for concurrency collision | E3: Two distinct browser contexts/sessions signed in as different admin personas. | F3: FS06: Robustness | G3: Testing optimistic concurrency | H3: Single session testing only. | I3: Open | J3: None yet | K3: TC-048 | L3: QA
A4: ENV-R6-03 | B4: Environment | C4: Seed Grants | D4: Need pre-existing student subsidies in DB for stats and tracking | E4: Database has pre-seeded FAS applications and student subsidies across schools. | F4: FS06: 5.4.2 | G4: Required for statistics aggregation | H4: Seed data script must be run before test. | I4: Open | J4: None yet | K4: TC-026, TC-027, TC-029, TC-030, TC-032, TC-035, TC-036, TC-038 | L4: QA
A5: ASM-R6-01 | B5: Rule | C5: Budget Period | D5: Gap G1: Budget Period definition | E5: Ngân sách được thiết lập và theo dõi theo từng Năm học (Academic Year, ví dụ 2026) với bộ lọc năm học trên giao diện. | F5: FS06: 5.1.6, G1 | G5: Hệ thống trường học Singapore tổ chức niên khóa theo Academic Year | H5: Nếu theo năm tài chính (FY), trường chọn năm và nhãn giao diện đổi thành Financial Year. | I5: Open | J5: None yet | K5: TC-028 | L5: BA
A6: ASM-R6-02 | B6: Rule | C6: Budget Adjustments | D6: Gap G2, G12: Budget Editing & History | E6: Cho phép chỉnh sửa ngân sách; lưu vết điều chỉnh qua Adjustment Modal kèm Reason vào fas_budget_adjustments. | F6: FS06: 5.1.6, 5.3.2, G2, G12 | G6: FS06 mục 9 loại audit log ra nhưng bảng CSDL fas_budget_adjustments đã được dev tạo | H6: Nếu không cho sửa hoặc không cần reason, bỏ modal và lưu đè trực tiếp. | I6: Open | J6: None yet | K6: TC-023, TC-024, TC-049 | L6: BA
A7: ASM-R6-03 | B7: Rule | C7: Warning Threshold 80% | D7: Gap G3: Warning thresholds | E7: Hệ thống hiển thị Warning Banner màu vàng (MSG-R6-W01) khi tỷ lệ sử dụng đạt từ 80.0% đến dưới 100%. | F7: FS06: R6-11, BR6.06 vs Section 9 | G7: Cần có ngưỡng cảnh báo trước khi hết ngân sách | H7: Nếu chỉ cảnh báo khi hết (100%), bỏ ngưỡng 80% và các case tương ứng. | I7: Open | J7: None yet | K7: TC-038, TC-039, TC-040, TC-045 | L7: BA
A8: ASM-R6-04 | B8: Rule | C8: Exhaustion & Deficit UI | D8: Gap G3: Over-budget presentation | E8: Khi Remaining Budget <= 0, hiển thị Alert Banner màu cam đỏ (MSG-R6-W02) và số âm màu đỏ kèm nhãn Deficit. | F8: FS06: R6-11, BR6.06, G3 | G8: Chuẩn kế toán hiển thị số dư âm thâm hụt | H8: Nếu không hiển thị số âm, số dư dừng ở S$ 0.00. | I8: Open | J8: None yet | K8: TC-041, TC-042 | L8: BA
A9: ASM-R6-05 | B9: Architecture | C9: Real-time Sync | D9: Gap G11: Statistics Refresh | E9: Thống kê và số dư ngân sách được cập nhật ngay lập tức khi một đơn FAS được phê duyệt qua DB Trigger/Event. | F9: FS06: 5.7.3, G11 | G9: Đảm bảo tính chính xác tức thì cho quản trị viên | H9: Nếu theo lịch định kỳ, số dư chỉ đổi sau khi batch job chạy. | I9: Open | J9: None yet | K9: TC-035 | L9: Dev
A10: ASM-R6-06 | B10: Boundary | C10: Max Budget Ceiling | D10: Gap G10: Number and currency formatting | E10: Trần ngân sách tối đa là S$ 999,999,999.99 (DECIMAL(11,2)). Đây là đề xuất của QA, không phải giới hạn toán học của DECIMAL(18,2). | F10: FS06: G10 | G10: Ngăn chặn tràn giao diện số học | H10: Nếu cho phép lớn hơn, cập nhật lại validation rule và case kiểm thử. | I10: Open | J10: None yet | K10: TC-015, TC-047 | L10: QA
A11: ASM-R6-07 | B11: Contradiction | C11: MOEFAS Approval Flow | D11: Contradiction with FS04 | E11: Trong FS04, MOE HQ không có nút bấm Approve MOEFAS (hệ thống tự duyệt theo rank khi đóng form). Case manual approve bị Block. | F11: FS04 vs FS06: BR6.06, G4 | G11: Mâu thuẫn thiết kế giữa hai tài liệu FS | H11: BA xác nhận lại luồng grant MOEFAS để mở khóa ca kiểm thử. | I11: Open | J11: None yet | K11: TC-044 | L11: BA
A12: ASM-R6-08 | B12: Rule | C12: Subsidy Amount Definition | D12: Gap G4: Definition of Subsidy Amount Granted | E12: Trong FS04, School Admin chọn Tier (phần trăm hỗ trợ), không nhập số tiền cố định. Số tiền subsidy tính trên học phí. | F12: FS04 vs FS06: G4 | G12: Mô hình trợ cấp học phí theo ma trận | H12: Nếu subsidy là số tiền cố định độc lập, cập nhật lại luồng grant. | I12: Open | J12: None yet | K12: TC-043 | L12: BA
... A17: ASM-R6-13 | B17: UI | C17: Provisional Navigation | D17: No navigation defined in FS06 | E17: Đường dẫn 'Financial Assistance > Budget Management' là tên tạm thời cho đến khi UI Portal chính thức được host. | F17: FS06: 1.1 | G17: Cần đường dẫn để hướng dẫn tester | H17: Cập nhật đường dẫn thực tế khi dev hoàn thiện menu. | I17: Open | J17: None yet | K17: TC-001, TC-007 | L17: UX

Sheet Questions
A1: Assumption Ref | B1: Topic | C1: Question description | D1: Why it matters | E1: Proposed default | F1: FS source | G1: Cases affected | H1: Status | I1: Answer
A2: ASM-R6-01 | B2: G1: Budget Period | C2: BA: Ngân sách MOEFAS/SBFAS được thiết lập theo năm học (Academic Year) hay năm tài chính (Financial Year)? | D2: Quyết định bộ lọc thời gian và chu kỳ quản lý ngân sách. | E2: Mặc định theo Academic Year (ví dụ 2026). | F2: FS06: 5.1.6, G1, Question 1 | G2: TC-028 | H2: Open | I2: None yet
A3: ASM-R6-02 | B3: G2: Budget Editing | C3: BA: Người dùng có được chỉnh sửa ngân sách đã lưu không? Nếu có, có cần nhập lý do (Reason) và lưu lịch sử không? | D3: Quyết định việc hiển thị nút Edit, modal lý do và bảng fas_budget_adjustments. | E3: Cho phép sửa kèm modal nhập Reason (lưu vào fas_budget_adjustments). | F3: FS06: 5.1.6, G2, Question 2 | G3: TC-023, TC-024, TC-049 | H3: Open | I3: None yet
A4: ASM-R6-03 | B4: G3: Warning vs Section 9 | C4: BA: Mục 9 loại 'cảnh báo ngân sách sắp hết hoặc đã hết' ra ngoài phạm vi, nhưng R6-11 và BR6.06 lại yêu cầu cảnh báo khi hết. Ngưỡng cảnh báo cụ thể là gì? | D4: Mâu thuẫn nội tại giữa mục 9 và mục 2/3 trong FS06. | E4: Tuân theo R6-11 và BR6.06: cảnh báo khi hết (100%), và đề xuất ngưỡng 80% cảnh báo vàng. | F4: FS06: R6-11, BR6.06, G3, Section 9 | G4: TC-038, TC-039, TC-040, TC-041 | H4: Open | I4: None yet
A5: ASM-R6-08 | B5: G4: Subsidy Amount | C5: BA: 'Subsidy Amount Granted' được tính từ Grant Amount cố định hay tính theo phần trăm giảm trừ học phí theo FS04? | D5: FS04 chỉ cho School Admin chọn Tier, không nhập số tiền trực tiếp. | E5: Đề xuất tính bằng tổng tiền thực tế giảm trừ cho học sinh trong kỳ. | F5: FS06: 5.6.5, G4, Question 3 | G5: TC-043 | H5: Open | I5: None yet
A6: ASM-R6-01 | B6: G5: Additional Stats | C6: BA: Có cần hiển thị số lượng học sinh thụ hưởng (Student Count), số lượng Grant và phân tích theo khối/lớp không? | D6: Ảnh hưởng đến các cột trong bảng Subsidy Statistics Table. | E6: Giai đoạn 1 chỉ hiển thị Total Subsidy Amount Granted theo FS. | F6: FS06: 5.4.3, G5, Question 7 | G6: TC-026, TC-029 | H6: Open | I6: None yet
A7: ASM-R6-04 | B7: G6: Budget Usage | C7: BA: Những khoản trợ cấp nào được tính là đã sử dụng ngân sách? Chỉ các đơn Approved/Granted hay cả đơn Pending? | D7: Tránh tính trùng hoặc tính thiếu số tiền đã giải ngân. | E7: Chỉ tính các khoản đã Approved/Granted chính thức. | F7: FS06: BR6.04, G6, Question 4 | G7: TC-027, TC-032 | H7: Open | I7: None yet
A8: ASM-R6-10 | B8: G7: Grant Revocation | C8: BA: Khi một khoản trợ cấp bị thu hồi hoặc hủy, ngân sách có được hoàn lại số tiền tương ứng không? | D8: Mục 9 ghi thu hồi grant là ngoài phạm vi nhưng 5.7.5 lại đặt câu hỏi. | E8: Đề xuất tự động trừ Used và hoàn lại Remaining Budget. | F8: FS06: 5.7.5, G7, Section 9 | G8: TC-036 | H8: Open | I8: None yet
A9: ASM-R6-04 | B9: G8: Remaining Budget | C9: BA: Chức năng Remaining Budget có bắt buộc trong bản đầu tiên không? Công thức chính thức là gì? | D9: Xác nhận hiển thị thẻ số dư còn lại trên giao diện. | E9: Bắt buộc hiển thị theo công thức: Remaining = Budget - Used. | F9: FS06: 5.9.2, G8, Question 5 | G9: TC-032, TC-042 | H9: Open | I9: None yet
A10: ASM-R6-09 | B10: G9: Utilization Rate | C10: BA: Tỷ lệ sử dụng ngân sách (Budget Utilization %) có bắt buộc hiển thị trên dashboard không? | D10: Xác nhận thanh tiến độ và chỉ số phần trăm. | E10: Bắt buộc hiển thị định dạng ##0.0% với bảo vệ chia cho 0. | F10: FS06: 5.7.3, G9, Question 6 | G10: TC-033, TC-034 | H10: Open | I10: None yet
A11: ASM-R6-09 | B11: G10: Currency Format | C11: BA: Định dạng tiền tệ và số thập phân hiển thị như thế nào? | D11: Đảm bảo tính đồng nhất trên toàn hệ thống. | E11: Hiển thị Đô la Singapore S$ #,##0.00. | F11: FS06: 5.6.2, G10 | G11: TC-030 | H11: Open | I11: None yet
A12: ASM-R6-05 | B12: G11: Refresh Schedule | C12: Dev/BA: Thống kê và theo dõi ngân sách được cập nhật tức thời hay chạy theo lịch đồng bộ định kỳ? | D12: Ảnh hưởng đến cách kiểm thử Integration và kỳ vọng kết quả ngay lập tức. | E12: Đề xuất cập nhật tức thời qua event khi đơn được duyệt. | F12: FS06: G11, Question 8 | G12: TC-035 | H12: Open | I12: None yet
... A14: ASM-R6-07 | B14: FS04 Conflict | C14: BA: Trong FS04, MOE HQ không có quyền bấm Approve MOEFAS thủ công. Vậy quy tắc 'không chặn khi hết budget' ở MOEFAS được áp dụng lúc nào? | D14: Mâu thuẫn kiến trúc giữa FS04 và FS06. | E14: Áp dụng vào thời điểm hệ thống tự động batch-approve khi đóng form MOEFAS. | F14: FS04 vs FS06: BR6.06 | G14: TC-044 | H14: Open | I14: None yet

Sheet FS Trace
A1: FS item | B1: Kind | C1: Statement | D1: Test cases that cite it | E1: Count | F1: Covered
A2: 1.1 | B2: Overview | C2: R6 provides budget management, subsidy statistics, and budget tracking via Admin Portal. | D2: TC-001, TC-003 | E2: =IF(D2="None",0,ROUND((LEN(D2)-LEN(SUBSTITUTE(D2,"TC-","")))/3,0)) | F2: =IF(E2>0,"Yes","No")
A3: 1.2 | B3: Actors & Scopes | C3: MOE HQ User manages MOEFAS nationally; School User manages SBFAS for assigned school. | D3: TC-001, TC-002, TC-003, TC-004, TC-005, TC-006 | E3: =IF(D3="None",0,ROUND((LEN(D3)-LEN(SUBSTITUTE(D3,"TC-","")))/3,0)) | F3: =IF(E3>0,"Yes","No")
A4: 2.0 (R6-01) | B4: Requirement | C4: System supports budget management for MOEFAS and SBFAS. | D4: TC-004, TC-008, TC-019 | E4: =IF(D4="None",0,ROUND((LEN(D4)-LEN(SUBSTITUTE(D4,"TC-","")))/3,0)) | F4: =IF(E4>0,"Yes","No")
A5: 2.0 (R6-02) | B5: Requirement | C5: MOE HQ User can configure MOEFAS budget within authorized scope. | D5: TC-001, TC-002, TC-005 | E5: =IF(D5="None",0,ROUND((LEN(D5)-LEN(SUBSTITUTE(D5,"TC-","")))/3,0)) | F5: =IF(E5>0,"Yes","No")
A6: 2.0 (R6-03) | B6: Requirement | C6: School User can configure SBFAS budget for assigned school. | D6: TC-003, TC-006, TC-019 | E6: =IF(D6="None",0,ROUND((LEN(D6)-LEN(SUBSTITUTE(D6,"TC-","")))/3,0)) | F6: =IF(E6>0,"Yes","No")
A7: 2.0 (R6-04) | B7: Requirement | C7: System saves and displays configured Budget Amount. | D7: TC-008, TC-009, TC-010, TC-019, TC-021, TC-053 | E7: =IF(D7="None",0,ROUND((LEN(D7)-LEN(SUBSTITUTE(D7,"TC-","")))/3,0)) | F7: =IF(E7>0,"Yes","No")
A8: 2.0 (R6-05) | B8: Requirement | C8: MOE HQ User can view statistics of granted MOEFAS subsidies. | D8: TC-026 | E8: =IF(D8="None",0,ROUND((LEN(D8)-LEN(SUBSTITUTE(D8,"TC-","")))/3,0)) | F8: =IF(E8>0,"Yes","No")
A9: 2.0 (R6-06) | B9: Requirement | C9: School User can view statistics of granted SBFAS subsidies at own school. | D9: TC-029 | E9: =IF(D9="None",0,ROUND((LEN(D9)-LEN(SUBSTITUTE(D9,"TC-","")))/3,0)) | F9: =IF(E9>0,"Yes","No")
A10: 2.0 (R6-07) | B10: Requirement | C10: System displays Total Subsidy Amount Granted per FAS type within user scope. | D10: TC-026, TC-027 | E10: =IF(D10="None",0,ROUND((LEN(D10)-LEN(SUBSTITUTE(D10,"TC-","")))/3,0)) | F10: =IF(E10>0,"Yes","No")
A11: 2.0 (R6-08) | B11: Requirement | C11: System tracks budget usage based on Budget Amount and Subsidy Used. | D11: TC-032 | E11: =IF(D11="None",0,ROUND((LEN(D11)-LEN(SUBSTITUTE(D11,"TC-","")))/3,0)) | F11: =IF(E11>0,"Yes","No")
A12: 2.0 (R6-09) | B12: Requirement | C12: System restricts statistics and budget views strictly to authorized scope. | D12: TC-004 | E12: =IF(D12="None",0,ROUND((LEN(D12)-LEN(SUBSTITUTE(D12,"TC-","")))/3,0)) | F12: =IF(E12>0,"Yes","No")
A13: 2.0 (R6-10) | B13: Requirement | C13: System calculates and displays Remaining Budget. | D13: TC-032 | E13: =IF(D13="None",0,ROUND((LEN(D13)-LEN(SUBSTITUTE(D13,"TC-","")))/3,0)) | F13: =IF(E13>0,"Yes","No")
... A61: 8.0 (G12) | B61: Gap | C61: Budget History recording. | D61: TC-024 | E61: =IF(D61="None",0,ROUND((LEN(D61)-LEN(SUBSTITUTE(D61,"TC-","")))/3,0)) | F61: =IF(E61>0,"Yes","No")

Sheet Seed Data
A1: Seed data for R6 test cases (FS06 Draft v0.1 & EduFAMS Project Schemas)
A2: Reset rules: Use standard project seed scripts. To reset state, execute roles/dev/seed-data.cmd or database restore.
A3: Sample date: 26/10/2026. Academic Year: 2026.
A5: Data ID | B5: Entity | C5: Identifier | D5: Description / Persona | E5: Attributes & Initial Values
A6: SEED-R6-01 | B6: User Account | C6: moehq | D6: MOE HQ Administrator (Mei Lin Tan) | E6: Role: MOE HQ, Scope: National (All Schools), Status: Active
A7: SEED-R6-02 | B7: User Account | C7: school | D7: School Admin (Bukit View Primary, Lan Nguyen) | E7: Role: School Admin, SchoolId: BVP-0012, Status: Active
A8: SEED-R6-03 | B8: User Account | C8: school_meridian | D8: School Admin (Meridian Secondary, Farah Tan) | E8: Role: School Admin, SchoolId: MRS-0012, Status: Active
A9: SEED-R6-04 | B9: School | C9: BVP-0012 | D9: Bukit View Primary School | E9: School Type: Primary, Level: P1-P6, Active: Yes
A10: SEED-R6-05 | B10: School | C10: MRS-0012 | D10: Meridian Secondary School | E10: School Type: Secondary, Level: S1-S5, Active: Yes
A11: SEED-R6-06 | B11: Academic Year | C11: 2026 | D11: Current Academic Year 2026 | E11: Year: 2026, StartDate: 2026-01-01, EndDate: 2026-12-31, IsActive: 1
A12: SEED-R6-07 | B12: Academic Year | C12: 2029 | D12: Future Empty Academic Year 2029 | E12: Year: 2029, IsActive: 0, Used for empty state testing
A13: SEED-R6-08 | B13: FAS Scheme | C13: MOEFAS | D13: Ministry of Education Financial Assistance Scheme | E13: Type: National, ManagedBy: MOE HQ
A14: SEED-R6-09 | B14: FAS Scheme | C14: SBFAS | D14: School-Based Financial Assistance Scheme | E14: Type: School-Based, ManagedBy: Individual Schools
A15: SEED-R6-10 | B15: Initial Budget | C15: BUD-MOE-2026 | D15: National MOEFAS Budget 2026 | E15: Scheme: MOEFAS, SchoolId: NULL, AllocatedBudgetAmount: S$ 5,000,000.00
A16: SEED-R6-11 | B16: Initial Budget | C16: BUD-BVP-2026 | D16: SBFAS Budget Bukit View Primary 2026 | E16: Scheme: SBFAS, SchoolId: BVP-0012, AllocatedBudgetAmount: S$ 150,000.00
... A21: SEED-R6-16 | B21: Student Subsidy | C21: SUB-BVP-002 | D21: Approved SBFAS Subsidy (Uniform) | E21: Student: Alex Tan, Scheme: SBFAS, Status: Granted, Amount: S$ 150.00
