Workbook

Sheet Summary
A1: R1 Education Account Test Cases v2.2: Summary (Tender requirement R1, MOE Finance System, baseline FS R1 V1.0 and F03 of the first FS)
A2: Scope: functional and integration cases only. Performance and security are excluded. All counts are formulas over TestCases, Scenarios, Checkpoint, Assumptions and Questions. No test case has been executed.
A4: Test cases by Status
A5: Status | B5: Count | C5: Percent | D5: Meaning
A6: Approve | B6: =COUNTIF(TestCases!$V$2:$V$158,A6) -> 93 | C6: =B6/B10 -> 0.59235669 | D6: The expected result is stated by the FS ([CR], [TD] or an untagged criterion), the tender or a client answer, or the open assumption was resolved. Assumption Ref is N/A.
A7: Draft | B7: =COUNTIF(TestCases!$V$2:$V$158,A7) -> 40 | C7: =B7/B10 -> 0.25477707 | D7: The expected result rests on an open assumption (FS tag [WA] or an inference). Assumption Ref names it and its source. Each open assumption is a question in Questions.
A8: Block | B8: =COUNTIF(TestCases!$V$2:$V$158,A8) -> 15 | C8: =B8/B10 -> 0.095541401 | D8: Information exists but no assumption can settle it: the FS defers the feature ([Deferred]) or two sources conflict. Dependency Ref lists the blocking questions.
A9: Reject | B9: =COUNTIF(TestCases!$V$2:$V$158,A9) -> 9 | C9: =B9/B10 -> 0.057324841 | D9: No testable expectation exists in the sources. Steps are not written.
A10: Total | B10: =SUM(B6:B9) -> 157 | C10: =SUM(C6:C9) -> 1
A12: Status by Priority
A13: Priority | B13: Approve | C13: Draft | D13: Block | E13: Reject | F13: Total
A14: Critical | B14: =COUNTIFS(TestCases!$H$2:$H$158,$A14,TestCases!$V$2:$V$158,"Approve") -> 18 | C14: =COUNTIFS(TestCases!$H$2:$H$158,$A14,TestCases!$V$2:$V$158,"Draft") -> 12 | D14: =COUNTIFS(TestCases!$H$2:$H$158,$A14,TestCases!$V$2:$V$158,"Block") -> 1 | E14: =COUNTIFS(TestCases!$H$2:$H$158,$A14,TestCases!$V$2:$V$158,"Reject") -> 2 | F14: =SUM(B14:E14) -> 33
A15: High | B15: =COUNTIFS(TestCases!$H$2:$H$158,$A15,TestCases!$V$2:$V$158,"Approve") -> 50 | C15: =COUNTIFS(TestCases!$H$2:$H$158,$A15,TestCases!$V$2:$V$158,"Draft") -> 18 | D15: =COUNTIFS(TestCases!$H$2:$H$158,$A15,TestCases!$V$2:$V$158,"Block") -> 11 | E15: =COUNTIFS(TestCases!$H$2:$H$158,$A15,TestCases!$V$2:$V$158,"Reject") -> 1 | F15: =SUM(B15:E15) -> 80
A16: Medium | B16: =COUNTIFS(TestCases!$H$2:$H$158,$A16,TestCases!$V$2:$V$158,"Approve") -> 22 | C16: =COUNTIFS(TestCases!$H$2:$H$158,$A16,TestCases!$V$2:$V$158,"Draft") -> 10 | D16: =COUNTIFS(TestCases!$H$2:$H$158,$A16,TestCases!$V$2:$V$158,"Block") -> 3 | E16: =COUNTIFS(TestCases!$H$2:$H$158,$A16,TestCases!$V$2:$V$158,"Reject") -> 5 | F16: =SUM(B16:E16) -> 40
A17: Low | B17: =COUNTIFS(TestCases!$H$2:$H$158,$A17,TestCases!$V$2:$V$158,"Approve") -> 3 | C17: =COUNTIFS(TestCases!$H$2:$H$158,$A17,TestCases!$V$2:$V$158,"Draft") -> 0 | D17: =COUNTIFS(TestCases!$H$2:$H$158,$A17,TestCases!$V$2:$V$158,"Block") -> 0 | E17: =COUNTIFS(TestCases!$H$2:$H$158,$A17,TestCases!$V$2:$V$158,"Reject") -> 1 | F17: =SUM(B17:E17) -> 4
A18: Total | B18: =SUM(B14:B17) -> 93 | C18: =SUM(C14:C17) -> 40 | D18: =SUM(D14:D17) -> 15 | E18: =SUM(E14:E17) -> 9 | F18: =SUM(F14:F17) -> 157
A20: Status by Severity (1 is the most severe)
A21: Severity | B21: Approve | C21: Draft | D21: Block | E21: Reject | F21: Total
A22: 1 | B22: =COUNTIFS(TestCases!$I$2:$I$158,$A22,TestCases!$V$2:$V$158,"Approve") -> 18 | C22: =COUNTIFS(TestCases!$I$2:$I$158,$A22,TestCases!$V$2:$V$158,"Draft") -> 12 | D22: =COUNTIFS(TestCases!$I$2:$I$158,$A22,TestCases!$V$2:$V$158,"Block") -> 2 | E22: =COUNTIFS(TestCases!$I$2:$I$158,$A22,TestCases!$V$2:$V$158,"Reject") -> 2 | F22: =SUM(B22:E22) -> 34
A23: 2 | B23: =COUNTIFS(TestCases!$I$2:$I$158,$A23,TestCases!$V$2:$V$158,"Approve") -> 50 | C23: =COUNTIFS(TestCases!$I$2:$I$158,$A23,TestCases!$V$2:$V$158,"Draft") -> 19 | D23: =COUNTIFS(TestCases!$I$2:$I$158,$A23,TestCases!$V$2:$V$158,"Block") -> 10 | E23: =COUNTIFS(TestCases!$I$2:$I$158,$A23,TestCases!$V$2:$V$158,"Reject") -> 1 | F23: =SUM(B23:E23) -> 80
A24: 3 | B24: =COUNTIFS(TestCases!$I$2:$I$158,$A24,TestCases!$V$2:$V$158,"Approve") -> 23 | C24: =COUNTIFS(TestCases!$I$2:$I$158,$A24,TestCases!$V$2:$V$158,"Draft") -> 9 | D24: =COUNTIFS(TestCases!$I$2:$I$158,$A24,TestCases!$V$2:$V$158,"Block") -> 3 | E24: =COUNTIFS(TestCases!$I$2:$I$158,$A24,TestCases!$V$2:$V$158,"Reject") -> 6 | F24: =SUM(B24:E24) -> 41
A25: 4 | B25: =COUNTIFS(TestCases!$I$2:$I$158,$A25,TestCases!$V$2:$V$158,"Approve") -> 2 | C25: =COUNTIFS(TestCases!$I$2:$I$158,$A25,TestCases!$V$2:$V$158,"Draft") -> 0 | D25: =COUNTIFS(TestCases!$I$2:$I$158,$A25,TestCases!$V$2:$V$158,"Block") -> 0 | E25: =COUNTIFS(TestCases!$I$2:$I$158,$A25,TestCases!$V$2:$V$158,"Reject") -> 0 | F25: =SUM(B25:E25) -> 2
A26: Total | B26: =SUM(B22:B25) -> 93 | C26: =SUM(C22:C25) -> 40 | D26: =SUM(D22:D25) -> 15 | E26: =SUM(E22:E25) -> 9 | F26: =SUM(F22:F25) -> 157
A28: Priority by Severity (test cases)
A29: Priority | B29: Severity 1 | C29: Severity 2 | D29: Severity 3 | E29: Severity 4 | F29: Total
A30: Critical | B30: =COUNTIFS(TestCases!$H$2:$H$158,$A30,TestCases!$I$2:$I$158,1) -> 33 | C30: =COUNTIFS(TestCases!$H$2:$H$158,$A30,TestCases!$I$2:$I$158,2) -> 0 | D30: =COUNTIFS(TestCases!$H$2:$H$158,$A30,TestCases!$I$2:$I$158,3) -> 0 | E30: =COUNTIFS(TestCases!$H$2:$H$158,$A30,TestCases!$I$2:$I$158,4) -> 0 | F30: =SUM(B30:E30) -> 33
A31: High | B31: =COUNTIFS(TestCases!$H$2:$H$158,$A31,TestCases!$I$2:$I$158,1) -> 1 | C31: =COUNTIFS(TestCases!$H$2:$H$158,$A31,TestCases!$I$2:$I$158,2) -> 79 | D31: =COUNTIFS(TestCases!$H$2:$H$158,$A31,TestCases!$I$2:$I$158,3) -> 0 | E31: =COUNTIFS(TestCases!$H$2:$H$158,$A31,TestCases!$I$2:$I$158,4) -> 0 | F31: =SUM(B31:E31) -> 80
A32: Medium | B32: =COUNTIFS(TestCases!$H$2:$H$158,$A32,TestCases!$I$2:$I$158,1) -> 0 | C32: =COUNTIFS(TestCases!$H$2:$H$158,$A32,TestCases!$I$2:$I$158,2) -> 1 | D32: =COUNTIFS(TestCases!$H$2:$H$158,$A32,TestCases!$I$2:$I$158,3) -> 39 | E32: =COUNTIFS(TestCases!$H$2:$H$158,$A32,TestCases!$I$2:$I$158,4) -> 0 | F32: =SUM(B32:E32) -> 40
A33: Low | B33: =COUNTIFS(TestCases!$H$2:$H$158,$A33,TestCases!$I$2:$I$158,1) -> 0 | C33: =COUNTIFS(TestCases!$H$2:$H$158,$A33,TestCases!$I$2:$I$158,2) -> 0 | D33: =COUNTIFS(TestCases!$H$2:$H$158,$A33,TestCases!$I$2:$I$158,3) -> 2 | E33: =COUNTIFS(TestCases!$H$2:$H$158,$A33,TestCases!$I$2:$I$158,4) -> 2 | F33: =SUM(B33:E33) -> 4
A34: Total | B34: =SUM(B30:B33) -> 34 | C34: =SUM(C30:C33) -> 80 | D34: =SUM(D30:D33) -> 41 | E34: =SUM(E30:E33) -> 2 | F34: =SUM(F30:F33) -> 157
A36: Severity scale (Test plan 1.0.7)
A37: Severity | B37: Meaning
A38: 1 | B38: Blocks a core flow or corrupts a financial record
A39: 2 | B39: Other major failure
A40: 3 | B40: Lower impact, a workaround exists
A41: 4 | B41: Cosmetic
A43: Status by Sprint (1 is the Sprint 1 MVP in the FS header, TBD waits for a decision, a next sprint feature or the CPF Transfer)
A44: Sprint | B44: Approve | C44: Draft | D44: Block | E44: Reject | F44: Total
A45: 1 | B45: =COUNTIFS(TestCases!$D$2:$D$158,$A45,TestCases!$V$2:$V$158,"Approve") -> 93 | C45: =COUNTIFS(TestCases!$D$2:$D$158,$A45,TestCases!$V$2:$V$158,"Draft") -> 28 | D45: =COUNTIFS(TestCases!$D$2:$D$158,$A45,TestCases!$V$2:$V$158,"Block") -> 2 | E45: =COUNTIFS(TestCases!$D$2:$D$158,$A45,TestCases!$V$2:$V$158,"Reject") -> 0 | F45: =SUM(B45:E45) -> 123
A46: TBD | B46: =COUNTIFS(TestCases!$D$2:$D$158,$A46,TestCases!$V$2:$V$158,"Approve") -> 0 | C46: =COUNTIFS(TestCases!$D$2:$D$158,$A46,TestCases!$V$2:$V$158,"Draft") -> 12 | D46: =COUNTIFS(TestCases!$D$2:$D$158,$A46,TestCases!$V$2:$V$158,"Block") -> 13 | E46: =COUNTIFS(TestCases!$D$2:$D$158,$A46,TestCases!$V$2:$V$158,"Reject") -> 9 | F46: =SUM(B46:E46) -> 34
...

Sheet TestCases
A1: TC ID | B1: Requirement (Tender clause) | C1: Module | D1: Sprint | E1: Scenario ID | F1: Title | G1: Objective | H1: Priority | I1: Severity | J1: Type | K1: Precondition | L1: Postcondition | M1: Test Data | N1: Steps | O1: Expected Result | P1: Actual Result | Q1: Traceability Requirement | R1: Checkpoint Ref | S1: Assumption Ref | T1: Dependency Ref | U1: Test Type | V1: Status | W1: Reason
A2: TC-R1-01-01 | B2: R1 | C2: Education Account | D2: 1 | E2: SCN-R1-01 | F2: Account is created on the 7th birthday | G2: A Singapore Citizen who turns 7 on the business date gets an Active account, and a citizen who turns 7 the next day does not. Case: Account is created on the 7th birthday | H2: Critical | I2: 1 | J2: boundary | K2: 1. The SIT environment is ready and both synchronizations can be run for a chosen business date (ASM-R1-01) 2. The Mock Government Citizen API holds the records of the Test Data. Every record has a Full Name and a Gender and has no address unless the Test Data says otherwise (ASM-R1-32) 3. The Initial Synchronization has already run 4. Student A is a Singapore Citizen in the Mock Government Citizen API and has no Education Account | L2: Data created or changed by the steps stays in the SIT test data | M2: Student A: NRIC T9901011D, Singapore Citizen, DOB 15 Oct 2019. Business date 15 Oct 2026 (turns 7 that day) | N2: 1. Set the business date to 15 Oct 2026 2. Run the Daily Incremental Synchronization 3. Look up the Education Account of student A by NRIC T9901011D | O2: 1. The System creates one Education Account for student A 2. The Account Status is Active | P2: Not Executed | Q2: Tender R1 (Education Account); FS R1 V1.0 F01-AC02, 1.1.5 step 9, 1.1.6 age examples | R2: CP-R1-02 | S2: N/A | T2: ASM-R1-01, ASM-R1-02, ASM-R1-03, ASM-R1-14, ASM-R1-32 | U2: Functional | V2: Approve | W2: F01-AC02 says the Daily Sync creates the account for a citizen who just turned 7. The age example in 1.1.6 (DOB 15/06/2019, processing date 15/06/2026) gives the same offset.
A3: TC-R1-01-02 | B3: R1 | C3: Education Account | D3: 1 | E3: SCN-R1-01 | F3: No account the day before the 7th birthday | G3: A Singapore Citizen who turns 7 on the business date gets an Active account, and a citizen who turns 7 the next day does not. Case: No account the day before the 7th birthday | H3: High | I3: 2 | J3: boundary | K3: 1. The SIT environment is ready and both synchronizations can be run for a chosen business date (ASM-R1-01) 2. The Mock Government Citizen API holds the records of the Test Data. Every record has a Full Name and a Gender and has no address unless the Test Data says otherwise (ASM-R1-32) 3. The Initial Synchronization has already run 4. Student B is a Singapore Citizen in the Mock Government Citizen API and has no Education Account | L3: Data created or changed by the steps stays in the SIT test data | M3: Student B: NRIC T9901021A, Singapore Citizen, DOB 16 Oct 2019. Business date 15 Oct 2026 (6 years and 364 days old) | N3: 1. Set the business date to 15 Oct 2026 2. Run the Daily Incremental Synchronization 3. Look up the Education Account of student B by NRIC T9901021A | O3: 1. The System creates no Education Account for student B | P3: Not Executed | Q3: Tender R1 (Education Account); FS R1 V1.0 F01-AC04, 1.1.6 age examples | R3: CP-R1-02 | S3: N/A | T3: ASM-R1-01, ASM-R1-02, ASM-R1-03, ASM-R1-14, ASM-R1-32 | U3: Functional | V3: Approve | W3: The age example in 1.1.6 (DOB 15/06/2019, processing date 14/06/2026) says the citizen is not yet 7 and gets no account. F01-AC04 says the same for a citizen under 7.
A4: TC-R1-02-01 | B4: R1 | C4: Education Account | D4: 1 | E4: SCN-R1-02 | F4: No account for a citizen below 7 | G4: A citizen below 7 or from 16 on, with no account, gets none. Case: No account for a citizen below 7 | H4: Medium | I4: 3 | J4: negative | K4: 1. The SIT environment is ready and both synchronizations can be run for a chosen business date (ASM-R1-01) 2. The Mock Government Citizen API holds the records of the Test Data. Every record has a Full Name and a Gender and has no address unless the Test Data says otherwise (ASM-R1-32) 3. The Initial Synchronization has not run yet and can be run again for this case 4. Student A is a Singapore Citizen in the Mock Government Citizen API and has no Education Account | L4: Data created or changed by the steps stays in the SIT test data | M4: Student A: NRIC T9902011Z, Singapore Citizen, DOB 15 Oct 2022. Business date 15 Oct 2026 (4 years old) | N4: 1. Set the business date to 15 Oct 2026 2. Run the Initial Synchronization 3. Look up the Education Account of student A by NRIC T9902011Z | O4: 1. The System creates no Education Account for student A | P4: Not Executed | Q4: Tender R1 (Education Account); FS R1 V1.0 F01-AC04, F01-AF02, 1.1.4 step 2 | R4: CP-R1-02 | S4: N/A | T4: ASM-R1-01, ASM-R1-02, ASM-R1-03, ASM-R1-14, ASM-R1-32 | U4: Functional | V4: Approve | W4: F01-AC04 and F01-AF02 say a citizen under 7 gets no account.
A5: TC-R1-02-02 | B5: R1 | C5: Education Account | D5: 1 | E5: SCN-R1-02 | F5: No account for a citizen aged 18 | G5: A citizen below 7 or from 16 on, with no account, gets none. Case: No account for a citizen aged 18 | H5: Medium | I5: 3 | J5: negative | K5: 1. The SIT environment is ready and both synchronizations can be run for a chosen business date (ASM-R1-01) 2. The Mock Government Citizen API holds the records of the Test Data. Every record has a Full Name and a Gender and has no address unless the Test Data says otherwise (ASM-R1-32) 3. The Initial Synchronization has not run yet and can be run again for this case 4. Student A is a Singapore Citizen in the Mock Government Citizen API and has no Education Account | L5: Data created or changed by the steps stays in the SIT test data | M5: Student A: NRIC T9902021G, Singapore Citizen, DOB 15 Oct 2008. Business date 15 Oct 2026 (18 years old) | N5: 1. Set the business date to 15 Oct 2026 2. Run the Initial Synchronization 3. Look up the Education Account of student A by NRIC T9902021G | O5: 1. The System creates no Education Account for student A | P5: Not Executed | Q5: Tender R1 (Education Account); FS R1 V1.0 F01-AC05, F01-AF02, F01-BR05 | R5: CP-R1-02 | S5: N/A | T5: ASM-R1-01, ASM-R1-02, ASM-R1-03, ASM-R1-14, ASM-R1-32 | U5: Functional | V5: Approve | W5: F01-AC05 and F01-BR05 say a citizen from 16 on who has no account gets none.
A6: TC-R1-02-03 | B6: R1 | C6: Education Account | D6: 1 | E6: SCN-R1-02 | F6: No account for a citizen who turns 16 today | G6: A citizen below 7 or from 16 on, with no account, gets none. Case: No account for a citizen who turns 16 today | H6: High | I6: 2 | J6: boundary | K6: 1. The SIT environment is ready and both synchronizations can be run for a chosen business date (ASM-R1-01) 2. The Mock Government Citizen API holds the records of the Test Data. Every record has a Full Name and a Gender and has no address unless the Test Data says otherwise (ASM-R1-32) 3. The Initial Synchronization has not run yet and can be run again for this case 4. Student A is a Singapore Citizen in the Mock Government Citizen API and has no Education Account | L6: Data created or changed by the steps stays in the SIT test data | M6: Student A: NRIC T9902031D, Singapore Citizen, DOB 15 Oct 2010. Business date 15 Oct 2026 (turns 16 that day) | N6: 1. Set the business date to 15 Oct 2026 2. Run the Initial Synchronization 3. Look up the Education Account of student A by NRIC T9902031D | O6: 1. The System creates no Education Account for student A | P6: Not Executed | Q6: Tender R1 (Education Account); FS R1 V1.0 F01-BR05, F01-AC05, 1.1.6 age examples, F02-BR01 [CR] | R6: CP-R1-02 | S6: N/A | T6: ASM-R1-01, ASM-R1-02, ASM-R1-03, ASM-R1-04, ASM-R1-14, ASM-R1-32, Question on 16th birthday rule | U6: Functional | V6: Approve | W6: 1.1.6 gives DOB 15/06/2019 and processing date 15/06/2035 (16th birthday) as no new account. F02-BR01 [CR] closes at 16, so the same day is the upper boundary.
A7: TC-R1-03-01 | B7: R1 | C7: Education Account | D7: 1 | E7: SCN-R1-03 | F7: Singapore Citizen gets an account | G7: Citizenship decides whether an account is created. Case: Singapore Citizen gets an account | H7: Critical | I7: 1 | J7: positive | K7: 1. The SIT environment is ready and both synchronizations can be run for a chosen business date (ASM-R1-01) 2. The Mock Government Citizen API holds the records of the Test Data. Every record has a Full Name and a Gender and has no address unless the Test Data says otherwise (ASM-R1-32) 3. The Initial Synchronization has already run 4. Student A is in the Mock Government Citizen API and has no Education Account | L7: Data created or changed by the steps stays in the SIT test data | M7: Student A: NRIC T9903011E, Singapore Citizen, DOB 15 Oct 2019. Business date 15 Oct 2026 | N7: 1. Set the business date to 15 Oct 2026 2. Run the Daily Incremental Synchronization 3. Look up the Education Account of student A by NRIC T9903011E | O7: 1. The System creates one Education Account for student A 2. The Account Status is Active | P7: Not Executed | Q7: Tender R1 (Education Account); FS R1 V1.0 F01-BR01 [CR], F01-AC02 | R7: CP-R1-01 | S7: N/A | T7: ASM-R1-01, ASM-R1-02, ASM-R1-14, ASM-R1-32 | U7: Functional | V7: Approve | W7: F01-BR01 [CR] gives the account to Singapore Citizens.
A8: TC-R1-03-02 | B8: R1 | C8: Education Account | D8: 1 | E8: SCN-R1-03 | F8: Dual citizen gets an account | G8: Citizenship decides whether an account is created. Case: Dual citizen gets an account | H8: High | I8: 2 | J8: positive | K8: 1. The SIT environment is ready and both synchronizations can be run for a chosen business date (ASM-R1-01) 2. The Mock Government Citizen API holds the records of the Test Data. Every record has a Full Name and a Gender and has no address unless the Test Data says otherwise (ASM-R1-32) 3. The Initial Synchronization has already run 4. Student A is in the Mock Government Citizen API and has no Education Account | L8: Data created or changed by the steps stays in the SIT test data | M8: Student A: NRIC T9903021B, citizen of Singapore and another country (shown as Singapore Citizen, ASM-R1-31), DOB 15 Oct 2019. Business date 15 Oct 2026 | N8: 1. Set the business date to 15 Oct 2026 2. Run the Daily Incremental Synchronization 3. Look up the Education Account of student A by NRIC T9903021B | O8: 1. The System creates one Education Account for student A 2. The Account Status is Active | P8: Not Executed | Q8: Tender R1 (Education Account); Register NEW-03, 1.1.3 Required Data Validation | R8: CP-R1-01 | S8: ASM-R1-31: FS 1.1.3, register NEW-03 | T8: ASM-R1-01, ASM-R1-02, ASM-R1-31, ASM-R1-32 | U8: Functional | V8: Draft | W8: Register NEW-03 says a dual citizen counts as Singaporean. FS 1.1.3 requires a recognised Citizenship value but gives no list, so the way a dual citizen is shown is an assumption.
A9: TC-R1-03-03 | B9: R1 | C9: Education Account | D9: 1 | E9: SCN-R1-03 | F9: Permanent Resident gets no account | G9: Citizenship decides whether an account is created. Case: Permanent Resident gets no account | H9: High | I9: 2 | J9: negative | K9: 1. The SIT environment is ready and both synchronizations can be run for a chosen business date (ASM-R1-01) 2. The Mock Government Citizen API holds the records of the Test Data. Every record has a Full Name and a Gender and has no address unless the Test Data says otherwise (ASM-R1-32) 3. The Initial Synchronization has already run 4. Student A is in the Mock Government Citizen API and has no Education Account | L9: Data created or changed by the steps stays in the SIT test data | M9: Student A: NRIC T9903031Z, Permanent Resident, DOB 15 Oct 2019. Business date 15 Oct 2026 | N9: 1. Set the business date to 15 Oct 2026 2. Run the Daily Incremental Synchronization 3. Look up the Education Account of student A by NRIC T9903031Z | O9: 1. The System creates no Education Account for student A | P9: Not Executed | Q9: Tender R1 (Education Account); FS R1 V1.0 F01-AC03, F01-AF01 | R9: CP-R1-01 | S9: N/A | T9: ASM-R1-01, ASM-R1-02, ASM-R1-14, ASM-R1-32 | U9: Functional | V9: Approve | W9: F01-AC03 says a Permanent Resident gets no account.
A10: TC-R1-03-04 | B10: R1 | C10: Education Account | D10: 1 | E10: SCN-R1-03 | F10: Foreign student gets no account | G10: Citizenship decides whether an account is created. Case: Foreign student gets no account | H10: High | I10: 2 | J10: negative | K10: 1. The SIT environment is ready and both synchronizations can be run for a chosen business date (ASM-R1-01) 2. The Mock Government Citizen API holds the records of the Test Data. Every record has a Full Name and a Gender and has no address unless the Test Data says otherwise (ASM-R1-32) 3. The Initial Synchronization has already run 4. Student A is in the Mock Government Citizen API and has no Education Account | L10: Data created or changed by the steps stays in the SIT test data | M10: Student A: NRIC T9903041G, Foreign, DOB 15 Oct 2019. Business date 15 Oct 2026 | N10: 1. Set the business date to 15 Oct 2026 2. Run the Daily Incremental Synchronization 3. Look up the Education Account of student A by NRIC T9903041G | O10: 1. The System creates no Education Account for student A | P10: Not Executed | Q10: Tender R1 (Education Account); FS R1 V1.0 F01-AC03, F01-AF01, 2.1 rules | R10: CP-R1-01 | S10: N/A | T10: ASM-R1-01, ASM-R1-02, ASM-R1-14, ASM-R1-32 | U10: Functional | V10: Approve | W10: F01-AC03 says a non Singapore Citizen gets no account. 2.1 names the Foreign Student as a profile without an account.
A11: TC-R1-03-05 | B11: R1 | C11: Education Account | D11: 1 | E11: SCN-R1-03 | F11: Citizen living overseas gets an account | G11: Citizenship decides whether an account is created. Case: Citizen living overseas gets an account | H11: High | I11: 2 | J11: positive | K11: 1. The SIT environment is ready and both synchronizations can be run for a chosen business date (ASM-R1-01) 2. The Mock Government Citizen API holds the records of the Test Data. Every record has a Full Name and a Gender and has no address unless the Test Data says otherwise (ASM-R1-32) 3. The Initial Synchronization has already run 4. Student A is in the Mock Government Citizen API and has no Education Account | L11: Data created or changed by the steps stays in the SIT test data | M11: Student A: NRIC T9903051D, Singapore Citizen, DOB 15 Oct 2019, residential Country Australia. Business date 15 Oct 2026 | N11: 1. Set the business date to 15 Oct 2026 2. Run the Daily Incremental Synchronization 3. Look up the Education Account of student A by NRIC T9903051D | O11: 1. The System creates one Education Account for student A 2. The Account Status is Active | P11: Not Executed | Q11: Tender R1 (Education Account); Register NEW-04, F01-BR01 [CR], 2.1 Country (optional) | R11: CP-R1-01 | S11: N/A | T11: ASM-R1-01, ASM-R1-02, ASM-R1-14, ASM-R1-32 | U11: Functional | V11: Approve | W11: Register NEW-04 says a citizen studying overseas still gets an account. Inference: the only overseas field in the FS is the optional Country in 2.1, and optional data does not block creation (1.1.3).
A12: TC-R1-04-01 | B12: R1 | C12: Education Account | D12: 1 | E12: SCN-R1-04 | F12: New account starts Active with a zero balance in SGD | G12: A new account is Active with a zero SGD balance, a unique number and a link to the right Student Profile. Case: New account starts Active with a zero balance in SGD | H12: Critical | I12: 1 | J12: positive | K12: 1. The SIT environment is ready and both synchronizations can be run for a chosen business date (ASM-R1-01) 2. The Mock Government Citizen API holds the records of the Test Data. Every record has a Full Name and a Gender and has no address unless the Test Data says otherwise (ASM-R1-32) 3. The Initial Synchronization has already run 4. Student A is a Singapore Citizen in the Mock Government Citizen API and has no Education Account | L12: Data created or changed by the steps stays in the SIT test data | M12: Student A: NRIC T9904011J, Singapore Citizen, DOB 15 Oct 2019. Business date 15 Oct 2026 | N12: 1. Set the business date to 15 Oct 2026 2. Run the Daily Incremental Synchronization 3. Look up the Education Account of student A by NRIC T9904011J 4. Read the Account Status, Account Balance and Currency | O12: 1. The Account Status is Active 2. The Account Balance is SGD 0.00 3. The Currency is SGD | P12: Not Executed | Q12: Tender R1 (Education Account); FS R1 V1.0 F01-AC01, 1.1.4 step 8, 1.1.5 step 10, 1.1.8 table, 2.2, register TBD-15 | R12: CP-R1-03 | S12: N/A | T12: ASM-R1-01, ASM-R1-02, ASM-R1-20, ASM-R1-32 | U12: Functional | V12: Approve | W12: 1.1.4 step 8 and 1.1.5 step 10 give Active, SGD 0.00 and SGD. The table in 1.1.8 lists the status and the balance. Register TBD-15 records that the initial balance is always zero.
A13: TC-R1-04-02 | B13: R1 | C13: Education Account | D13: 1 | E13: SCN-R1-04 | F13: Account number is unique and the account links to the right Student Profile | G13: A new account is Active with a zero SGD balance, a unique number and a link to the right Student Profile. Case: Account number is unique and the account links to the right Student Profile | H13: High | I13: 2 | J13: positive | K13: 1. The SIT environment is ready and both synchronizations can be run for a chosen business date (ASM-R1-01) 2. The Mock Government Citizen API holds the records of the Test Data. Every record has a Full Name and a Gender and has no address unless the Test Data says otherwise (ASM-R1-32) 3. The Initial Synchronization has already run 4. Students A and B are Singapore Citizens in the Mock Government Citizen API, turn 7 on the business date and have no Education Account | L13: Data created or changed by the steps stays in the SIT test data | M13: Student A: NRIC T9904021H, Singapore Citizen, DOB 15 Oct 2019. Student B: NRIC T9904022F, Singapore Citizen, DOB 15 Oct 2019. Business date 15 Oct 2026 | N13: 1. Set the business date to 15 Oct 2026 2. Run the Daily Incremental Synchronization 3. Look up the Education Account of student A by NRIC T9904021H and of student B by NRIC T9904022F 4. Read the Education Account Number and the Account Holder Reference of each account | O13: 1. Each account has an Education Account Number and the two numbers differ 2. The Account Holder Reference of the account of student A points to the Student Profile of T9904021H 3. The Account Holder Reference of the account of student B points to the Student Profile of T9904022F | P13: Not Executed | Q13: Tender R1 (Education Account); FS R1 V1.0 1.1.5 step 9, 1.1.8 table, 2.2 | R13: CP-R1-03 | S13: N/A | T13: ASM-R1-01, ASM-R1-02, ASM-R1-14, ASM-R1-32 | U13: Functional | V13: Approve | W13: 1.1.8 says the Education Account Number is unique and the Account Holder Reference (Student id) links the account to the right Student Profile. 1.1.5 step 9 says the System links the account to the profile.
... A158: TC-R1-32-04 | B158: R1 | C158: Education Account | D158: 1 | E158: SCN-R1-32 | F158: A Government update of the Father or Mother NRIC needs no rescan by R1 | G158: Student data is stored at account creation. The Daily Job and the closure check do not refresh it, and R1 does not rescan a student after a Government update. Case: A Government update of the Father or Mother NRIC needs no rescan by R1 | H158: Medium | I158: 3 | J158: negative | K158: 1. The SIT environment is ready and both synchronizations can be run for a chosen business date (ASM-R1-01) 2. The Mock Government Citizen API holds the records of the Test Data. Every record has a Full Name and a Gender and has no address unless the Test Data says otherwise (ASM-R1-32) 3. The Initial Synchronization has already run 4. Student A, aged 10, has an Active Education Account and a Student Profile with Father NRIC and Mother NRIC empty (seeded as test data) | L158: Data created or changed by the steps stays in the SIT test data | M158: Student A: NRIC T9932041E, DOB 15 Oct 2016, Father NRIC and Mother NRIC empty at creation. Father NRIC T9932042C added in the Mock Government Citizen API on 15 Oct 2026. Business date 15 Oct 2026 | N158: 1. Add the Father NRIC T9932042C to the record of student A in the Mock Government Citizen API 2. Set the business date to 15 Oct 2026 3. Run the Daily Incremental Synchronization 4. Look up the Student Profile of student A by NRIC T9932041E and read the Father NRIC | O158: 1. The Father NRIC in the Student Profile is still empty 2. The System does not rescan student A | P158: Not Executed | Q158: Tender R1 (Education Account); FS R1 V1.0 1.1.1 Cross-Function Dependency R8, F01-AC16, 1.1.5 Notes [TD] | R158: CP-R1-25 | S158: N/A | T158: ASM-R1-01, ASM-R1-02, ASM-R1-14, ASM-R1-32 | U158: Integration | V158: Approve | W158: 1.1.1 (Cross-Function Dependency R8) says a Government update of the Father or Mother NRIC after creation does not make R1 scan the student again. R8 checks the relationship when the parent signs in.

Sheet Scenarios
A1: Scenario ID | B1: Checkpoint | C1: Requirement (Tender clause) | D1: Module | E1: Sprint | F1: Lens | G1: Technique | H1: Title | I1: Condition | J1: Evidence | K1: Open ASM and questions | L1: Test cases | M1: Approve | N1: Draft | O1: Block | P1: Reject | Q1: Status
A2: SCN-R1-01 | B2: CP-R1-02 | C2: R1 | D2: Education Account | E2: 1 | F2: Boundary | G2: BVA | H2: Account is created on the 7th birthday | I2: A Singapore Citizen who turns 7 on the business date gets an Active account, and a citizen who turns 7 the next day does not | J2: FS F01-AC02, 1.1.5 step 2, 1.1.6 examples | K2: N/A | L2: =COUNTIFS(TestCases!$E$2:$E$158,$A2) -> 2 | M2: =COUNTIFS(TestCases!$E$2:$E$158,$A2,TestCases!$V$2:$V$158,"Approve") -> 2 | N2: =COUNTIFS(TestCases!$E$2:$E$158,$A2,TestCases!$V$2:$V$158,"Draft") -> 0 | O2: =COUNTIFS(TestCases!$E$2:$E$158,$A2,TestCases!$V$2:$V$158,"Block") -> 0 | P2: =COUNTIFS(TestCases!$E$2:$E$158,$A2,TestCases!$V$2:$V$158,"Reject") -> 0 | Q2: =IF(P2=L2,"Reject",IF(O2>0,"Block",IF(N2>0,"Draft","Approve"))) -> Approve
A3: SCN-R1-02 | B3: CP-R1-02 | C3: R1 | D3: Education Account | E3: 1 | F3: Data | G3: EP | H3: No account outside the age range | I3: A citizen below 7 or from 16 on, with no account, gets none | J3: FS F01-AC04, F01-AC05, F01-BR05 | K3: Question on 16th birthday rule | L3: =COUNTIFS(TestCases!$E$2:$E$158,$A3) -> 3 | M3: =COUNTIFS(TestCases!$E$2:$E$158,$A3,TestCases!$V$2:$V$158,"Approve") -> 3 | N3: =COUNTIFS(TestCases!$E$2:$E$158,$A3,TestCases!$V$2:$V$158,"Draft") -> 0 | O3: =COUNTIFS(TestCases!$E$2:$E$158,$A3,TestCases!$V$2:$V$158,"Block") -> 0 | P3: =COUNTIFS(TestCases!$E$2:$E$158,$A3,TestCases!$V$2:$V$158,"Reject") -> 0 | Q3: =IF(P3=L3,"Reject",IF(O3>0,"Block",IF(N3>0,"Draft","Approve"))) -> Approve
A4: SCN-R1-03 | B4: CP-R1-01 | C4: R1 | D4: Education Account | E4: 1 | F4: Business Risk | G4: DecisionTable | H4: Eligibility by citizenship | I4: Citizenship decides whether an account is created | J4: FS F01-BR01 [CR], F01-AC03, register NEW-03, NEW-04 | K4: ASM-R1-31 | L4: =COUNTIFS(TestCases!$E$2:$E$158,$A4) -> 5 | M4: =COUNTIFS(TestCases!$E$2:$E$158,$A4,TestCases!$V$2:$V$158,"Approve") -> 4 | N4: =COUNTIFS(TestCases!$E$2:$E$158,$A4,TestCases!$V$2:$V$158,"Draft") -> 1 | O4: =COUNTIFS(TestCases!$E$2:$E$158,$A4,TestCases!$V$2:$V$158,"Block") -> 0 | P4: =COUNTIFS(TestCases!$E$2:$E$158,$A4,TestCases!$V$2:$V$158,"Reject") -> 0 | Q4: =IF(P4=L4,"Reject",IF(O4>0,"Block",IF(N4>0,"Draft","Approve"))) -> Draft
A5: SCN-R1-04 | B5: CP-R1-03 | C5: R1 | D5: Education Account | E5: 1 | F5: Data Integrity | G5: EP | H5: New account starts clean | I5: A new account is Active with a zero SGD balance, a unique number and a link to the right Student Profile | J5: FS 1.1.4 steps 6 to 9, 1.1.5 steps 8 to 11, 1.1.8, 2.2, 2.3 Scope Note, register TBD-15 | K5: ASM-R1-34, ASM-R1-36 | L5: =COUNTIFS(TestCases!$E$2:$E$158,$A5) -> 7 | M5: =COUNTIFS(TestCases!$E$2:$E$158,$A5,TestCases!$V$2:$V$158,"Approve") -> 5 | N5: =COUNTIFS(TestCases!$E$2:$E$158,$A5,TestCases!$V$2:$V$158,"Draft") -> 2 | O5: =COUNTIFS(TestCases!$E$2:$E$158,$A5,TestCases!$V$2:$V$158,"Block") -> 0 | P5: =COUNTIFS(TestCases!$E$2:$E$158,$A5,TestCases!$V$2:$V$158,"Reject") -> 0 | Q5: =IF(P5=L5,"Reject",IF(O5>0,"Block",IF(N5>0,"Draft","Approve"))) -> Draft
A6: SCN-R1-05 | B6: CP-R1-05 | C6: R1 | D6: Education Account | E6: 1 | F6: Data Integrity | G6: EP | H6: One account per citizen | I6: The same NRIC never gets two accounts, whatever the job, rerun or account state | J6: FS 1.1.7, F01-AC06, F01-AC07, F01-AC12, F01-EF03 | K6: ASM-R1-33 | L6: =COUNTIFS(TestCases!$E$2:$E$158,$A6) -> 8 | M6: =COUNTIFS(TestCases!$E$2:$E$158,$A6,TestCases!$V$2:$V$158,"Approve") -> 7 | N6: =COUNTIFS(TestCases!$E$2:$E$158,$A6,TestCases!$V$2:$V$158,"Draft") -> 1 | O6: =COUNTIFS(TestCases!$E$2:$E$158,$A6,TestCases!$V$2:$V$158,"Block") -> 0 | P6: =COUNTIFS(TestCases!$E$2:$E$158,$A6,TestCases!$V$2:$V$158,"Reject") -> 0 | Q6: =IF(P6=L6,"Reject",IF(O6>0,"Block",IF(N6>0,"Draft","Approve"))) -> Draft
A7: SCN-R1-06 | B7: CP-R1-12 | C7: R1 | D7: Education Account | E7: 1 | F7: Boundary | G7: BVA | H7: Late records | I7: A record added to the dataset after the 7th birthday is not picked up by the Daily Job. Manual Account Creation and Bulk Re-synchronization handle it in the next sprint | J7: FS 1.1.1 B [TD, Deferred], 1.1.5 Notes [TD], section 4 [TD], register NEW-02 | K7: Question on Manual Account Creation and Bulk Re-synchronization, Question on late records | L7: =COUNTIFS(TestCases!$E$2:$E$158,$A7) -> 6 | M7: =COUNTIFS(TestCases!$E$2:$E$158,$A7,TestCases!$V$2:$V$158,"Approve") -> 4 | N7: =COUNTIFS(TestCases!$E$2:$E$158,$A7,TestCases!$V$2:$V$158,"Draft") -> 0 | O7: =COUNTIFS(TestCases!$E$2:$E$158,$A7,TestCases!$V$2:$V$158,"Block") -> 2 | P7: =COUNTIFS(TestCases!$E$2:$E$158,$A7,TestCases!$V$2:$V$158,"Reject") -> 0 | Q7: =IF(P7=L7,"Reject",IF(O7>0,"Block",IF(N7>0,"Draft","Approve"))) -> Block
A8: SCN-R1-07 | B8: CP-R1-10 | C8: R1 | D8: Education Account | E8: 1 | F8: Negative | G8: EP | H8: Invalid or missing citizen data | I8: A record without required data creates no account. A record without optional data still creates one. Where the exception is recorded is an open question | J8: FS 1.1.3, F01-EF02, F01-AC08, F01-AC09, 1.1.4 step 5 and Implementation Notes [TD] | K8: ASM-R1-30, Question on exception record | L8: =COUNTIFS(TestCases!$E$2:$E$158,$A8) -> 14 | M8: =COUNTIFS(TestCases!$E$2:$E$158,$A8,TestCases!$V$2:$V$158,"Approve") -> 11 | N8: =COUNTIFS(TestCases!$E$2:$E$158,$A8,TestCases!$V$2:$V$158,"Draft") -> 2 | O8: =COUNTIFS(TestCases!$E$2:$E$158,$A8,TestCases!$V$2:$V$158,"Block") -> 1 | P8: =COUNTIFS(TestCases!$E$2:$E$158,$A8,TestCases!$V$2:$V$158,"Reject") -> 0 | Q8: =IF(P8=L8,"Reject",IF(O8>0,"Block",IF(N8>0,"Draft","Approve"))) -> Block
A9: SCN-R1-08 | B9: CP-R1-12 | C9: R1 | D9: Education Account | E9: 1 | F9: Boundary | G9: BVA | H9: Leap day births | I9: A citizen born on 29 February follows the leap day rule | J9: FS 1.1.6 Leap Year Handling [WA], F01-AC14 [WA], F02-AC15 [WA], register TBD-01 | K9: ASM-R1-22, Question on leap rule in F02 | L9: =COUNTIFS(TestCases!$E$2:$E$158,$A9) -> 5 | M9: =COUNTIFS(TestCases!$E$2:$E$158,$A9,TestCases!$V$2:$V$158,"Approve") -> 4 | N9: =COUNTIFS(TestCases!$E$2:$E$158,$A9,TestCases!$V$2:$V$158,"Draft") -> 1 | O9: =COUNTIFS(TestCases!$E$2:$E$158,$A9,TestCases!$V$2:$V$158,"Block") -> 0 | P9: =COUNTIFS(TestCases!$E$2:$E$158,$A9,TestCases!$V$2:$V$158,"Reject") -> 0 | Q9: =IF(P9=L9,"Reject",IF(O9>0,"Block",IF(N9>0,"Draft","Approve"))) -> Draft
A10: SCN-R1-09 | B10: CP-R1-11 | C10: R1 | D10: Education Account | E10: 1 | F10: Workflow | G10: EP | H10: Citizen data intake | I10: Both synchronizations read the Mock Government Citizen API with the credential and select the right citizens, and a bad record does not stop the others | J10: FS 1.1.1, 1.1.2, 1.1.4, 1.1.5, 1.1.9 (next sprint) | K10: Question on job recovery, Question on weekly frequency | L10: =COUNTIFS(TestCases!$E$2:$E$158,$A10) -> 7 | M10: =COUNTIFS(TestCases!$E$2:$E$158,$A10,TestCases!$V$2:$V$158,"Approve") -> 5 | N10: =COUNTIFS(TestCases!$E$2:$E$158,$A10,TestCases!$V$2:$V$158,"Draft") -> 0 | O10: =COUNTIFS(TestCases!$E$2:$E$158,$A10,TestCases!$V$2:$V$158,"Block") -> 2 | P10: =COUNTIFS(TestCases!$E$2:$E$158,$A10,TestCases!$V$2:$V$158,"Reject") -> 0 | Q10: =IF(P10=L10,"Reject",IF(O10>0,"Block",IF(N10>0,"Draft","Approve"))) -> Block
A11: SCN-R1-10 | B11: CP-R1-12 | C11: R1 | D11: Education Account | E11: 1 | F11: Sequence | G11: StateTransition | H11: Daily run at 00:00 | I11: No account exists before the midnight run and it exists after it. The job runs once a day | J11: FS 1.1.2 Execution Time [WA], Execution Frequency [TD] | K11: ASM-R1-24 | L11: =COUNTIFS(TestCases!$E$2:$E$158,$A11) -> 3 | M11: =COUNTIFS(TestCases!$E$2:$E$158,$A11,TestCases!$V$2:$V$158,"Approve") -> 1 | N11: =COUNTIFS(TestCases!$E$2:$E$158,$A11,TestCases!$V$2:$V$158,"Draft") -> 2 | O11: =COUNTIFS(TestCases!$E$2:$E$158,$A11,TestCases!$V$2:$V$158,"Block") -> 0 | P11: =COUNTIFS(TestCases!$E$2:$E$158,$A11,TestCases!$V$2:$V$158,"Reject") -> 0 | Q11: =IF(P11=L11,"Reject",IF(O11>0,"Block",IF(N11>0,"Draft","Approve"))) -> Draft
A12: SCN-R1-11 | B12: CP-R1-06 | C12: R1 | D12: Education Account | E12: 1 | F12: State | G12: EP | H12: Account does not depend on school status | I12: School transfer, no school record, held back year, drop out and Student Profile Status do not decide the account | J12: FS F01-BR03, F01-BR04, F01-AC10, F02-BR07, register TBD-02 | K12: ASM-R1-17, ASM-R1-35 | L12: =COUNTIFS(TestCases!$E$2:$E$158,$A12) -> 5 | M12: =COUNTIFS(TestCases!$E$2:$E$158,$A12,TestCases!$V$2:$V$158,"Approve") -> 3 | N12: =COUNTIFS(TestCases!$E$2:$E$158,$A12,TestCases!$V$2:$V$158,"Draft") -> 2 | O12: =COUNTIFS(TestCases!$E$2:$E$158,$A12,TestCases!$V$2:$V$158,"Block") -> 0 | P12: =COUNTIFS(TestCases!$E$2:$E$158,$A12,TestCases!$V$2:$V$158,"Reject") -> 0 | Q12: =IF(P12=L12,"Reject",IF(O12>0,"Block",IF(N12>0,"Draft","Approve"))) -> Draft
A13: SCN-R1-12 | B13: CP-R1-17 | C13: R1 | D13: Education Account | E13: 1 | F13: Business Risk | G13: EP | H13: Account is not a login account | I13: Creating an account creates no sign in for the student | J13: Client clarification CD-01 | K13: N/A | L13: =COUNTIFS(TestCases!$E$2:$E$158,$A13) -> 1 | M13: =COUNTIFS(TestCases!$E$2:$E$158,$A13,TestCases!$V$2:$V$158,"Approve") -> 1 | N13: =COUNTIFS(TestCases!$E$2:$E$158,$A13,TestCases!$V$2:$V$158,"Draft") -> 0 | O13: =COUNTIFS(TestCases!$E$2:$E$158,$A13,TestCases!$V$2:$V$158,"Block") -> 0 | P13: =COUNTIFS(TestCases!$E$2:$E$158,$A13,TestCases!$V$2:$V$158,"Reject") -> 0 | Q13: =IF(P13=L13,"Reject",IF(O13>0,"Block",IF(N13>0,"Draft","Approve"))) -> Approve
... A33: SCN-R1-32 | B33: CP-R1-25 | C33: R1 | D33: Education Account | E33: 1 | F33: Data Integrity | G33: EP | H33: Student data stays as stored | I33: Student data is stored at account creation. The Daily Job and the closure check do not refresh it, and R1 does not rescan a student after a Government update | J33: FS F01-AC16, F02-AC13, F02-BR13 [TD], F02-EF05, 1.1.1 (Cross-Function Dependency R8), 1.2.6 [TD] | K33: N/A | L33: =COUNTIFS(TestCases!$E$2:$E$158,$A33) -> 4 | M33: =COUNTIFS(TestCases!$E$2:$E$158,$A33,TestCases!$V$2:$V$158,"Approve") -> 4 | N33: =COUNTIFS(TestCases!$E$2:$E$158,$A33,TestCases!$V$2:$V$158,"Draft") -> 0 | O33: =COUNTIFS(TestCases!$E$2:$E$158,$A33,TestCases!$V$2:$V$158,"Block") -> 0 | P33: =COUNTIFS(TestCases!$E$2:$E$158,$A33,TestCases!$V$2:$V$158,"Reject") -> 0 | Q33: =IF(P33=L33,"Reject",IF(O33>0,"Block",IF(N33>0,"Draft","Approve"))) -> Approve

Sheet Checkpoint
A1: CP ID | B1: Source | C1: Requirement (Tender clause) | D1: Point to test | E1: FS R1 V1.0 items | F1: Module | G1: Sprint | H1: Flag | I1: Test case can be generated | J1: Open ASM and questions | K1: Expected test case status | L1: Short reason | M1: TC IDs | N1: Defect IDs | O1: Approve | P1: Draft | Q1: Block | R1: Reject
A2: CP-R1-01 | B2: Tender R1, FS F01-BR01 [CR], register NEW-03, NEW-04 | C2: R1.1 Education Accounts are for Singapore Citizens only. Dual citizens count as Singaporean. A citizen studying overseas still gets an account. | D2: Only Singapore Citizens, including dual citizens, get an account. Permanent Residents and foreign students do not. | E2: F01-BR01, F01-AC03, F01-AF01, 2.1 rules | F2: Education Account | G2: 1 | H2: =IF(OR(Q2>0,AND(R2>0,O2+P2+Q2=0)),"Open",IF(P2>0,"Assumed","Clear")) -> Assumed | I2: =IF(COUNTIFS(TestCases!$R$2:$R$158,$A2,TestCases!$V$2:$V$158,"<>Reject")>0,"Yes","No") -> Yes | J2: ASM-R1-31 | K2: =IF(O2+P2+Q2=0,"Reject",IF(Q2>0,"Block",IF(P2>0,"Draft","Approve"))) -> Draft | L2: The FS and the register state who is eligible. How a dual citizen is shown is assumed. | M2: TC-R1-03-01, TC-R1-03-02, TC-R1-03-03, TC-R1-03-04, TC-R1-03-05 | N2: N/A | O2: =COUNTIFS(TestCases!$R$2:$R$158,$A2,TestCases!$V$2:$V$158,"Approve") -> 4 | P2: =COUNTIFS(TestCases!$R$2:$R$158,$A2,TestCases!$V$2:$V$158,"Draft") -> 1 | Q2: =COUNTIFS(TestCases!$R$2:$R$158,$A2,TestCases!$V$2:$V$158,"Block") -> 0 | R2: =COUNTIFS(TestCases!$R$2:$R$158,$A2,TestCases!$V$2:$V$158,"Reject") -> 0
A3: CP-R1-02 | B3: Tender R1, FS 1.1.1 [CR], F01-BR02, F01-BR05 | C3: R1.2 The account is created and activated automatically when the child turns 7. | D3: The account appears on the 7th birthday, not before, and not for citizens outside the age range. | E3: F01-AC02, F01-AC04, F01-AC05, F01-BR02, F01-BR05, 1.1.6 examples | F3: Education Account | G3: 1 | H3: =IF(OR(Q3>0,AND(R3>0,O3+P3+Q3=0)),"Open",IF(P3>0,"Assumed","Clear")) -> Clear | I3: =IF(COUNTIFS(TestCases!$R$2:$R$158,$A3,TestCases!$V$2:$V$158,"<>Reject")>0,"Yes","No") -> Yes | J3: Question on 16th birthday rule | K3: =IF(O3+P3+Q3=0,"Reject",IF(Q3>0,"Block",IF(P3>0,"Draft","Approve"))) -> Approve | L3: The FS gives the age rule and dated examples. | M3: TC-R1-01-01, TC-R1-01-02, TC-R1-02-01, TC-R1-02-02, TC-R1-02-03 | N3: N/A | O3: =COUNTIFS(TestCases!$R$2:$R$158,$A3,TestCases!$V$2:$V$158,"Approve") -> 5 | P3: =COUNTIFS(TestCases!$R$2:$R$158,$A3,TestCases!$V$2:$V$158,"Draft") -> 0 | Q3: =COUNTIFS(TestCases!$R$2:$R$158,$A3,TestCases!$V$2:$V$158,"Block") -> 0 | R3: =COUNTIFS(TestCases!$R$2:$R$158,$A3,TestCases!$V$2:$V$158,"Reject") -> 0
A4: CP-R1-03 | B4: Register TBD-15, FS 1.1.8, F01-AC01 | C4: R1.3 A new account starts Active with a zero balance. | D4: Opening state, balance, currency, account number, holder link and creation date of a new account. | E4: 1.1.4 steps 6 to 9, 1.1.5 steps 8 to 11, 1.1.8, 2.2, 2.3 Scope Note | F4: Education Account | G4: 1 | H4: =IF(OR(Q4>0,AND(R4>0,O4+P4+Q4=0)),"Open",IF(P4>0,"Assumed","Clear")) -> Assumed | I4: =IF(COUNTIFS(TestCases!$R$2:$R$158,$A4,TestCases!$V$2:$V$158,"<>Reject")>0,"Yes","No") -> Yes | J4: ASM-R1-34, ASM-R1-36 | K4: =IF(O4+P4+Q4=0,"Reject",IF(Q4>0,"Block",IF(P4>0,"Draft","Approve"))) -> Draft | L4: The flow steps and the 1.1.8 table state the opening values. The opening transaction and the profile of a Permanent Resident are assumptions. | M4: TC-R1-04-01, TC-R1-04-02, TC-R1-04-03, TC-R1-04-04, TC-R1-04-05, TC-R1-04-06, TC-R1-04-07 | N4: N/A | O4: =COUNTIFS(TestCases!$R$2:$R$158,$A4,TestCases!$V$2:$V$158,"Approve") -> 5 | P4: =COUNTIFS(TestCases!$R$2:$R$158,$A4,TestCases!$V$2:$V$158,"Draft") -> 2 | Q4: =COUNTIFS(TestCases!$R$2:$R$158,$A4,TestCases!$V$2:$V$158,"Block") -> 0 | R4: =COUNTIFS(TestCases!$R$2:$R$158,$A4,TestCases!$V$2:$V$158,"Reject") -> 0
A5: CP-R1-04 | B5: Tender R1, FS F02-BR01 [CR] | C5: R1.4 The account is closed automatically when the child reaches 16. | D5: On a backend access the account is Active before the 16th birthday and Closed from it. | E5: F02-BR01, F02-BR02, F02-AC01 to F02-AC03, 1.2.3, 1.2.5 | F5: Education Account | G5: 1 | H5: =IF(OR(Q5>0,AND(R5>0,O5+P5+Q5=0)),"Open",IF(P5>0,"Assumed","Clear")) -> Clear | I5: =IF(COUNTIFS(TestCases!$R$2:$R$158,$A5,TestCases!$V$2:$V$158,"<>Reject")>0,"Yes","No") -> Yes | J5: Question on 16th birthday rule | K5: =IF(O5+P5+Q5=0,"Reject",IF(Q5>0,"Block",IF(P5>0,"Draft","Approve"))) -> Approve | L5: The 16th birthday is [CR]. Closure happens at a backend access [TD]. | M5: TC-R1-13-01, TC-R1-13-02, TC-R1-13-03 | N5: N/A | O5: =COUNTIFS(TestCases!$R$2:$R$158,$A5,TestCases!$V$2:$V$158,"Approve") -> 3 | P5: =COUNTIFS(TestCases!$R$2:$R$158,$A5,TestCases!$V$2:$V$158,"Draft") -> 0 | Q5: =COUNTIFS(TestCases!$R$2:$R$158,$A5,TestCases!$V$2:$V$158,"Block") -> 0 | R5: =COUNTIFS(TestCases!$R$2:$R$158,$A5,TestCases!$V$2:$V$158,"Reject") -> 0
A6: CP-R1-05 | B6: Tender R1, FS 1.1.7 [CR] [TD] | C6: R1.5 Each citizen has one Education Account. A rerun creates no duplicate. | D6: No second account for the same NRIC, whatever the job, rerun or account state. | E6: 1.1.7 table, F01-AC06, F01-AC07, F01-AC12, F01-AF03, F01-EF03 | F6: Education Account | G6: 1 | H6: =IF(OR(Q6>0,AND(R6>0,O6+P6+Q6=0)),"Open",IF(P6>0,"Assumed","Clear")) -> Assumed | I6: =IF(COUNTIFS(TestCases!$R$2:$R$158,$A6,TestCases!$V$2:$V$158,"<>Reject")>0,"Yes","No") -> Yes | J6: ASM-R1-33 | K6: =IF(O6+P6+Q6=0,"Reject",IF(Q6>0,"Block",IF(P6>0,"Draft","Approve"))) -> Draft | L6: One account per citizen is [CR]. Conflicting records are an assumption. | M6: TC-R1-05-01, TC-R1-05-02, TC-R1-05-03, TC-R1-05-04, TC-R1-05-05, TC-R1-05-06, TC-R1-05-07, TC-R1-05-08 | N6: N/A | O6: =COUNTIFS(TestCases!$R$2:$R$158,$A6,TestCases!$V$2:$V$158,"Approve") -> 7 | P6: =COUNTIFS(TestCases!$R$2:$R$158,$A6,TestCases!$V$2:$V$158,"Draft") -> 1 | Q6: =COUNTIFS(TestCases!$R$2:$R$158,$A6,TestCases!$V$2:$V$158,"Block") -> 0 | R6: =COUNTIFS(TestCases!$R$2:$R$158,$A6,TestCases!$V$2:$V$158,"Reject") -> 0
A7: CP-R1-06 | B7: Client clarification CD-06, FS F01-BR03, F01-BR04, F02-BR07 | C7: R1.6 The account does not depend on schooling status, school enrolment or school transfer. | D7: School transfer, class change, held back year, no school record and Student Profile Status do not decide the account. | E7: F01-BR03, F01-BR04, F01-AC10, F02-BR07, 1.1.3 note | F7: Education Account | G7: 1 | H7: =IF(OR(Q7>0,AND(R7>0,O7+P7+Q7=0)),"Open",IF(P7>0,"Assumed","Clear")) -> Assumed | I7: =IF(COUNTIFS(TestCases!$R$2:$R$158,$A7,TestCases!$V$2:$V$158,"<>Reject")>0,"Yes","No") -> Yes | J7: ASM-R1-17, ASM-R1-35 | K7: =IF(O7+P7+Q7=0,"Reject",IF(Q7>0,"Block",IF(P7>0,"Draft","Approve"))) -> Draft | L7: The independence from schooling is stated in the FS (F01-BR03, F01-BR04, F02-BR07). The drop out and the profile status cases are assumptions. | M7: TC-R1-11-01, TC-R1-11-02, TC-R1-11-03, TC-R1-11-04, TC-R1-11-05 | N7: N/A | O7: =COUNTIFS(TestCases!$R$2:$R$158,$A7,TestCases!$V$2:$V$158,"Approve") -> 3 | P7: =COUNTIFS(TestCases!$R$2:$R$158,$A7,TestCases!$V$2:$V$158,"Draft") -> 2 | Q7: =COUNTIFS(TestCases!$R$2:$R$158,$A7,TestCases!$V$2:$V$158,"Block") -> 0 | R7: =COUNTIFS(TestCases!$R$2:$R$158,$A7,TestCases!$V$2:$V$158,"Reject") -> 0
A8: CP-R1-07 | B8: CD-02, register TBD-05, FS 1.2.7 [CR] and [Deferred], first FS F03 | C8: R1.7 At closure the remaining balance is transferred to CPF. A mock API is acceptable. | D8: The remaining balance goes to CPF through the Mock CPF Service, a CPF Transfer Record keeps the result, and a failure, a retry or an interruption never loses or duplicates money. | E8: 1.2.7, F02-AC10, section 4 item 3, first FS F03-BR01 to BR07, F03-AC01 to AC04, 2.4 | F8: Education Account | G8: 1 | H8: =IF(OR(Q8>0,AND(R8>0,O8+P8+Q8=0)),"Open",IF(P8>0,"Assumed","Clear")) -> Assumed | I8: =IF(COUNTIFS(TestCases!$R$2:$R$158,$A8,TestCases!$V$2:$V$158,"<>Reject")>0,"Yes","No") -> Yes | J8: ASM-R1-41, ASM-R1-42, ASM-R1-43, ASM-R1-44, ASM-R1-45, ASM-R1-46, Question on CPF delivery | K8: =IF(O8+P8+Q8=0,"Reject",IF(Q8>0,"Block",IF(P8>0,"Draft","Approve"))) -> Draft | L8: FS R1 V1.0 defers the transfer. The QA lead keeps F03 of the first FS as the rule, so the cases are Draft and wait for the delivery sprint. | M8: TC-R1-14-01, TC-R1-14-02, TC-R1-14-03, TC-R1-14-04, TC-R1-14-05, TC-R1-14-06, TC-R1-14-07, TC-R1-14-08, TC-R1-14-09, TC-R1-14-10, TC-R1-14-11, TC-R1-14-12 | N8: N/A | O8: =COUNTIFS(TestCases!$R$2:$R$158,$A8,TestCases!$V$2:$V$158,"Approve") -> 1 | P8: =COUNTIFS(TestCases!$R$2:$R$158,$A8,TestCases!$V$2:$V$158,"Draft") -> 11 | Q8: =COUNTIFS(TestCases!$R$2:$R$158,$A8,TestCases!$V$2:$V$158,"Block") -> 0 | R8: =COUNTIFS(TestCases!$R$2:$R$158,$A8,TestCases!$V$2:$V$158,"Reject") -> 0
A9: CP-R1-08 | B9: CD-02, FS 1.2.2 [TD], F02-BR09 [TD] | C9: R1.8 There should be no pending transactions at closure. | D9: Closure behaviour when a transaction is pending. | E9: 1.2.2, 1.2.7, F02-BR09 | F9: Education Account | G9: TBD | H9: =IF(OR(Q9>0,AND(R9>0,O9+P9+Q9=0)),"Open",IF(P9>0,"Assumed","Clear")) -> Open | I9: =IF(COUNTIFS(TestCases!$R$2:$R$158,$A9,TestCases!$V$2:$V$158,"<>Reject")>0,"Yes","No") -> No | J9: Question on pending transactions | K9: =IF(O9+P9+Q9=0,"Reject",IF(Q9>0,"Block",IF(P9>0,"Draft","Approve"))) -> Reject | L9: The team assumes none exist and builds no reconciliation. | M9: TC-R1-15-01, TC-R1-15-02 | N9: N/A | O9: =COUNTIFS(TestCases!$R$2:$R$158,$A9,TestCases!$V$2:$V$158,"Approve") -> 0 | P9: =COUNTIFS(TestCases!$R$2:$R$158,$A9,TestCases!$V$2:$V$158,"Draft") -> 0 | Q9: =COUNTIFS(TestCases!$R$2:$R$158,$A9,TestCases!$V$2:$V$158,"Block") -> 0 | R9: =COUNTIFS(TestCases!$R$2:$R$158,$A9,TestCases!$V$2:$V$158,"Reject") -> 2
A10: CP-R1-09 | B10: Register NEW-01 | C10: R1.9 Unpaid fees do not block closure. | D10: Closure when the student has an unpaid fee. | E10: Not in FS V1.0, register NEW-01 | F10: Education Account | G10: 1 | H10: =IF(OR(Q10>0,AND(R10>0,O10+P10+Q10=0)),"Open",IF(P10>0,"Assumed","Clear")) -> Assumed | I10: =IF(COUNTIFS(TestCases!$R$2:$R$158,$A10,TestCases!$V$2:$V$158,"<>Reject")>0,"Yes","No") -> Yes | J10: ASM-R1-42, Question on CPF delivery, Question on unpaid fees | K10: =IF(O10+P10+Q10=0,"Reject",IF(Q10>0,"Block",IF(P10>0,"Draft","Approve"))) -> Draft | L10: The client confirmed that closure is not blocked. The CPF amount waits for the transfer. | M10: TC-R1-16-01, TC-R1-16-02 | N10: N/A | O10: =COUNTIFS(TestCases!$R$2:$R$158,$A10,TestCases!$V$2:$V$158,"Approve") -> 1 | P10: =COUNTIFS(TestCases!$R$2:$R$158,$A10,TestCases!$V$2:$V$158,"Draft") -> 1 | Q10: =COUNTIFS(TestCases!$R$2:$R$158,$A10,TestCases!$V$2:$V$158,"Block") -> 0 | R10: =COUNTIFS(TestCases!$R$2:$R$158,$A10,TestCases!$V$2:$V$158,"Reject") -> 0
A11: CP-R1-10 | B11: CD-03, FS 1.1.3, 2.1 | C11: R1.10 Account setup uses NRIC, name, date of birth, citizenship and gender. Missing or invalid required data creates no account and an exception is recorded. | D11: Required and optional data, and the handling of invalid data. | E11: 1.1.3 Required Data Validation, F01-EF02, F01-AC08, F01-AC09, 1.1.4 step 5, 2.1 Business Rules | F11: Education Account | G11: 1 | H11: =IF(OR(Q11>0,AND(R11>0,O11+P11+Q11=0)),"Open",IF(P11>0,"Assumed","Clear")) -> Open | I11: =IF(COUNTIFS(TestCases!$R$2:$R$158,$A11,TestCases!$V$2:$V$158,"<>Reject")>0,"Yes","No") -> Yes | J11: ASM-R1-30, Question on exception record | K11: =IF(O11+P11+Q11=0,"Reject",IF(Q11>0,"Block",IF(P11>0,"Draft","Approve"))) -> Block | L11: Most rules are stated. The place where the exception is recorded conflicts inside the FS (see the question on the exception record). Gender and the value lists need confirmation. | M11: TC-R1-07-01, TC-R1-07-02, TC-R1-07-03, TC-R1-07-04, TC-R1-07-05, TC-R1-07-06, TC-R1-07-07, TC-R1-07-08, TC-R1-07-09, TC-R1-07-10, TC-R1-07-11, TC-R1-07-12, TC-R1-07-13, TC-R1-07-14 | N11: N/A | O11: =COUNTIFS(TestCases!$R$2:$R$158,$A11,TestCases!$V$2:$V$158,"Approve") -> 11 | P11: =COUNTIFS(TestCases!$R$2:$R$158,$A11,TestCases!$V$2:$V$158,"Draft") -> 2 | Q11: =COUNTIFS(TestCases!$R$2:$R$158,$A11,TestCases!$V$2:$V$158,"Block") -> 1 | R11: =COUNTIFS(TestCases!$R$2:$R$158,$A11,TestCases!$V$2:$V$158,"Reject") -> 0
A12: CP-R1-11 | B12: Register NEW-02, FS 1.1.2, 1.1.4, 1.1.5 | C12: R1.11 Citizenship data comes from the government source. The FS uses a Mock Government Citizen API with an API credential. | D12: Both synchronizations read the Mock Government Citizen API with the credential and select the right citizens. | E12: 1.1.1, 1.1.2, 1.1.4, 1.1.5, F01-AC01, F01-AC02 | F12: Education Account | G12: 1 | H12: =IF(OR(Q12>0,AND(R12>0,O12+P12+Q12=0)),"Open",IF(P12>0,"Assumed","Clear")) -> Open | I12: =IF(COUNTIFS(TestCases!$R$2:$R$158,$A12,TestCases!$V$2:$V$158,"<>Reject")>0,"Yes","No") -> Yes | J12: Question on job recovery, Question on weekly frequency | K12: =IF(O12+P12+Q12=0,"Reject",IF(Q12>0,"Block",IF(P12>0,"Draft","Approve"))) -> Block | L12: The mechanism is a team decision [TD]. Weekly frequency conflicts with the register. The recovery rules of 1.1.9 are next sprint. | M12: TC-R1-09-01, TC-R1-09-02, TC-R1-09-03, TC-R1-09-04, TC-R1-09-05, TC-R1-09-06, TC-R1-09-07 | N12: N/A | O12: =COUNTIFS(TestCases!$R$2:$R$158,$A12,TestCases!$V$2:$V$158,"Approve") -> 5 | P12: =COUNTIFS(TestCases!$R$2:$R$158,$A12,TestCases!$V$2:$V$158,"Draft") -> 0 | Q12: =COUNTIFS(TestCases!$R$2:$R$158,$A12,TestCases!$V$2:$V$158,"Block") -> 2 | R12: =COUNTIFS(TestCases!$R$2:$R$158,$A12,TestCases!$V$2:$V$158,"Reject") -> 0
A13: CP-R1-12 | B13: FS 1.1.1 B, 1.1.2, 1.1.5, 1.1.6 [WA], section 4, register TBD-01 | C13: R1.12 Eligibility is evaluated daily. A 29 February birth follows a leap day rule. | D13: Daily schedule, weekends, holidays, missed days, late records and the leap day rule. | E13: 1.1.1 B, 1.1.2, 1.1.5, 1.1.9 (next sprint), section 4, F01-AC13, F01-AC14, 1.1.6 Leap Year Handling | F13: Education Account | G13: 1 | H13: =IF(OR(Q13>0,AND(R13>0,O13+P13+Q13=0)),"Open",IF(P13>0,"Assumed","Clear")) -> Open | I13: =IF(COUNTIFS(TestCases!$R$2:$R$158,$A13,TestCases!$V$2:$V$158,"<>Reject")>0,"Yes","No") -> Yes | J13: ASM-R1-22, ASM-R1-24, Question on Manual Account Creation and Bulk Re-synchronization, Question on job recovery, Question on late records, Question on leap rule in F02 | K13: =IF(O13+P13+Q13=0,"Reject",IF(Q13>0,"Block",IF(P13>0,"Draft","Approve"))) -> Block | L13: Weekends and holidays have no tag now. The run time and the leap rule are [WA]. Late records and missed days are next sprint (Deferred) and those cases are Block. | M13: TC-R1-06-01, TC-R1-06-02, TC-R1-06-03, TC-R1-06-04, TC-R1-06-05, TC-R1-06-06, TC-R1-08-01, TC-R1-08-02, TC-R1-08-03, TC-R1-08-04, TC-R1-08-05, TC-R1-10-01, TC-R1-10-02, TC-R1-10-03, TC-R1-25-01, TC-R1-25-02, TC-R1-25-03, TC-R1-25-04 | N13: N/A | O13: =COUNTIFS(TestCases!$R$2:$R$158,$A13,TestCases!$V$2:$V$158,"Approve") -> 11 | P13: =COUNTIFS(TestCases!$R$2:$R$158,$A13,TestCases!$V$2:$V$158,"Draft") -> 3 | Q13: =COUNTIFS(TestCases!$R$2:$R$158,$A13,TestCases!$V$2:$V$158,"Block") -> 4 | R13: =COUNTIFS(TestCases!$R$2:$R$158,$A13,TestCases!$V$2:$V$158,"Reject") -> 0
... A26: CP-R1-25 | B26: FS R1 V1.0 F01-AC16, F02-AC13, F02-BR13 [TD], 1.1.1, 1.2.6 | C26: R1.25 Student data is stored at account creation. The Daily Job and the closure check do not refresh it (FS R1 V1.0 only, not in the tender). | D26: A Government update of the address, gender, name, race or parent NRIC after creation is not copied into the Student Profile by the Daily Job or by the closure check. | E26: F01-AC16, F02-AC13, F02-BR13, F02-EF05, 1.1.1 Cross-Function Dependency R8, 1.2.3 Notes, 1.2.6 | F26: Education Account | G26: 1 | H26: =IF(OR(Q26>0,AND(R26>0,O26+P26+Q26=0)),"Open",IF(P26>0,"Assumed","Clear")) -> Clear | I26: =IF(COUNTIFS(TestCases!$R$2:$R$158,$A26,TestCases!$V$2:$V$158,"<>Reject")>0,"Yes","No") -> Yes | J26: ASM-R1-01 only | K26: =IF(O26+P26+Q26=0,"Reject",IF(Q26>0,"Block",IF(P26>0,"Draft","Approve"))) -> Approve | L26: The FS states the boundary with untagged criteria and team decisions. | M26: TC-R1-32-01, TC-R1-32-02, TC-R1-32-03, TC-R1-32-04 | N26: N/A | O26: =COUNTIFS(TestCases!$R$2:$R$158,$A26,TestCases!$V$2:$V$158,"Approve") -> 4 | P26: =COUNTIFS(TestCases!$R$2:$R$158,$A26,TestCases!$V$2:$V$158,"Draft") -> 0 | Q26: =COUNTIFS(TestCases!$R$2:$R$158,$A26,TestCases!$V$2:$V$158,"Block") -> 0 | R26: =COUNTIFS(TestCases!$R$2:$R$158,$A26,TestCases!$V$2:$V$158,"Reject") -> 0

Sheet Assumptions
A1: ASM ID | B1: Type | C1: Requirement | D1: Original gap | E1: Assumption | F1: Source (as in Assumption Ref) | G1: Source detail | H1: Reason | I1: If the answer differs | J1: State | K1: Resolution | L1: Cases that make this assumption (Assumption Ref) | M1: Other cases that depend on it (Dependency Ref) | N1: Question to confirm
A2: ASM-R1-01 | B2: Dependency | C2: All R1 cases | D2: FS R1 V1.0 does not describe the test environment, the Mock Government Citizen API controls or how a backend action is triggered. | E2: The SIT environment is ready. QA can (1) run the Initial Synchronization and the Daily Job for a chosen business date and time, and run the Initial Synchronization again; (2) load records into the Mock Government Citizen API and set it to succeed, reject the credential, time out or fail, and change the data of a record; (3) send the backend requests that read or process an account (parent view, balance and history view, MOE HQ retrieval, Top-Up, Payment, Batch Top-Up), as API calls where a screen or function is not built; (4) seed an account with a status, balance, fee record and transactions; (5) read the job log (Job Failure and errors) and the request log of the Mock Government Citizen API; (6) read the stored status of an account and the stored Student Profile without making a backend access; (7) inject a failure while an account is created or closed or a transaction is posted. | F2: FS 1.1.2 | G2: FS 1.1.2 Sprint 1 Integration: Mock Government Citizen API [TD]. Register TBD-14 (mock integrations acceptable). Sprint Backlog TSK-R1-03. | H2: A test cannot start without an environment and the controls it needs. | I2: A case that needs a missing control moves to unit or API level, or becomes Block. | J2: Open | K2: None yet | L2: None | M2: 154 test cases, see the TestCases sheet | N2: Dev: To run the R1 test cases in SIT, QA needs to do seven things. Run the Initial Synchronization and the Daily Job for a date and time we choose, and run the Initial Synchronization again. Load citizen records into the Mock Government Citizen API and make it succeed, reject the credential, time out or fail. Send the backend requests that read or process an account (parent view, MOE HQ retrieval, Top-Up, Payment, Batch Top-Up) as API calls where there is no screen. Create an account with a chosen status, balance, fee and transactions. Read the job log and the request log of the Mock Government Citizen API. Read the stored status of an account and the stored Student Profile without opening the account. Make a failure happen while an account is created or closed or a transaction is posted. Is each of these possible in SIT, and what is the alternative for the ones that are not?
A3: ASM-R1-02 | B3: Data | C3: All R1 cases | D3: The FS gives examples with dates but the sprint test window needs fixed dates. | E3: Creation cases use the business date 15 Oct 2026. Closure cases use 28 Oct 2026. Dates of birth are set for those dates and shift together if another date is used. The tester sets the business date and starts the job by hand. | F3: Test data design | G3: Test plan 1.0.7 section 4.3. FS 1.1.6 and 1.2.5 give the same offsets (age 7 on the birthday, age 16 on the birthday). | H3: A boundary case needs a fixed date to be repeatable. | I3: Shift every date of birth by the same number of days. The expected results do not change. | J3: Resolved | K3: QA test data choice, no question | L3: None | M3: 141 test cases, see the TestCases sheet | N3: None
A4: ASM-R1-03 | B4: Data | C4: R1 age rules | D4: The tender says age 7 and age 16 but not how age is counted. | E4: Age is counted from the exact date of birth. A citizen is eligible from the 7th birthday up to the day before the 16th birthday. | F4: FS F01-BR02, 1.1.6 | G4: FS F01-BR02, F01-AC04, F01-AC05 and the age examples in 1.1.6 (DOB 15/06/2019: not eligible on 14/06/2026, eligible on 15/06/2026, no new account on 15/06/2035). | H4: The FS gives the rule and three dated examples. | I4: Not applicable, resolved. | J4: Resolved | K4: FS R1 V1.0, 1.1.6 age examples | L4: None | M4: TC-R1-01-01, TC-R1-01-02, TC-R1-02-01, TC-R1-02-02, TC-R1-02-03 | N4: None
