Workbook

Sheet Sprint Backlog 1
B1: PBI Ref | C1: Task ID | D1: Category | E1: Task Title | F1: Description | G1: Assignee | H1: Estimate (Hours) | I1: Priority | J1: Status | K1: Definition of Done (DoD)
A2: R1 | B2: PB-05 | C2: TSK-R1-01 | D2: Documentation | E2: Draft Technical Specification Docx for R1 (Education Account Lifecycle) | F2: Write detailed .docx specification covering business flows for account creation/activation at age 7 and closing/transfer to CPF at age 16; design account state machine, cron triggers, API specs, and edge cases (citizenship change, leap year birthdays). | G2: Kevin,Hugh | H2: 4 | I2: P1 - High | J2: Done | K2: Complete .docx file adhering to team standards; includes full Sequence Diagram, State Transition Diagram; reviewed & signed off by BA and Lead.
A3: R1 | B3: PB-05 | C3: TSK-R1-02 | D3: Database Refinement | E3: Design Data Model & Migrations for Education Account Lifecycle | F3: Design data model and database schema for Education Account lifecycle, balance tracking, and status transitions based on technical specification; create migration scripts with rollback support. | G3: Hugh | H3: 5 | I3: P1 - High | J3: Done | K3: Database schema reflects technical specification; ERD and Data Dictionary fully updated; migration and rollback scripts tested successfully without errors.
A4: R1 | B4: PB-05 | C4: TSK-R1-03 | D4: Backend Core | E4: Build Scheduled Job to automatically create & activate accounts at age 7 | F4: Implement scheduled background job periodically scanning eligible Singapore citizen students turning 7 based on date of birth; initialize Education Account records with active status and zero balance according to business rules. | G4: Kevin | H4: 4 | I4: P2 - Medium | J4: Done | K4: Processing logic accurate by date of birth; idempotent execution (no duplicates on re-run); Unit Test coverage >= 85%; test cases for edge conditions (non-citizen, under 7 years old).
A5: R1 | B5: PB-16 | C5: TSK-R1-04 | D5: Backend Core | E5: Build Scheduled Job to automatically close accounts & transfer settlement to CPF at age 16 | F5: Implement scheduled job checking accounts turning 16: verify no pending transactions or unsettled debts, transition status to closed, and log settlement transfer to CPF system. | G5: Kevin | H5: 4 | I5: P1 - High | J5: Done | K5: Account transitions to closed status, redundant balance sent to CPF; comprehensive audit logging; new transactions blocked on closed accounts
A6: R1 | B6: PB-05 | C6: TSK-R1-05 | D6: Backend / API | E6: Build Wallet CRUD APIs (create, credit, debit, update status, and get wallet) & Wallet Transaction functionality to handle wallet behavior, including APIs to retrieve and reverse transactions. | F6: Implement Wallet APIs to manage wallet lifecycle and balance operations, including creating wallets, crediting and debiting balances, updating wallet status, and retrieving wallet information. Implement Wallet Transaction functionality to handle wallet-related transactions, ensure proper transaction processing, and provide APIs to retrieve transaction history and reverse transactions when needed. | G6: Hugh | H6: 8 | I6: P1 - High | J6: Done | K6: Transactions using the education account must follow business rules; valid Singapore citizen accounts verified; balance deducted accurately with atomic rollback on failure; full transaction logging; Unit Test coverage >= 85%.
A7: R3 | B7: PB-02 | C7: TSK-R3-01 | D7: Documentation | E7: Draft Technical Specification Docx for R3 (Master Data & Fee Management) | F7: Write detailed .docx specification covering school hierarchy (School, Level/Cohort, Class, Student), RBAC permissions matrix (MOE HQ vs School User), and fee structure/components (tuition, miscellaneous fees, optional GST). | G7: Nito, Tyson | H7: 6 | I7: P1 - High | J7: Done | K7: Complete .docx document adhering to team standards; includes ER diagrams, role permission matrix, and fee calculation flow; reviewed and approved by PO and Dev Lead.
A8: R3 | B8: PB-02 | C8: TSK-R3-02 | D8: Database Refinement | E8: Design Data Model & Migrations for School Master Data & Fee Catalog | F8: Design data model and database schema for school organization master data and fee catalog based on technical specification; establish composite indexing, constraints, and migration scripts with rollback. | G8: Nito, Tyson | H8: 7 | I8: P1 - High | J8: Done | K8: Database schema verified against master data and fee requirements; ERD and Data Dictionary finalized; migration and rollback scripts execute smoothly.
A9: R3 | B9: PB-02 | C9: TSK-R3-03 | D9: Backend Core | E9: Build Master Data CRUD APIs (School, Level, Class, Student) and RBAC Guard | F9: Develop master data management APIs for schools, levels, classes, and students; integrate RBAC guard ensuring MOE HQ has broad management access while School users are restricted to their permitted school scope. | G9: Nito, Tyson | H9: 8 | I9: P1 - High | J9: Done | K9: 100% pass on cross-authorization security tests (School User cannot modify other schools); strict API validation via DTO; code review achieves 2 approvals.
A10: R3 | B10: PB-12 | C10: TSK-R3-04 | D10: Backend Core | E10: Build Fee Type Configuration Module & Student Charge Generation | F10: Build backend service allowing configuration of fee types with reusable fee components, and generate payable student charges per cohort/class according to business rules. | G10: Nito, Tyson | H10: 8 | I10: P1 - High | J10: Done | K10: Total calculation and fee component breakdown logic strictly accurate without rounding discrepancies; supports batch charge insertion; Unit Test coverage >= 85%.
A11: R3 | B11: PB-03 | C11: TSK-R3-05 | D11: Frontend / UI | E11: Build School Management & Fee Configuration UI (Admin Portal) | F11: Build data table UI for School, Class, Student management and Fee Type configuration forms on Admin Portal; integrate permissions to show/hide action buttons based on HQ / School roles. | G11: Nito, Tyson | H11: 7 | I11: P2 - Medium | J11: Done | K11: UI complies with Design System; responsive layout; intuitive error/success feedback; client-side role rendering tests pass.
A12: R8 | B12: PB-06 | C12: TSK-R8-01 | D12: Documentation | E12: Draft Technical Specification Docx for R8 (Singpass Auth & Parent Portal) | F12: Write detailed .docx specification covering Singpass OIDC auth flow, Parent-Child Relationship Mapping architecture, PII security/encryption, API specs, and profile update rules. | G12: Ryan, Nathan | H12: 6 | I12: P1 - High | J12: Done | K12: Complete .docx file with OIDC authentication flow and Authorize Access Token sequence; clearly defines editable vs read-only fields; approved by Security and Lead.
A13: R8 | B13: PB-07 | C13: TSK-R8-02 | D13: Database Refinement | E13: Design Data Model & Migrations for Parents, Child Linkage, and Audit Log | F13: Design data model and database schema for parent profiles, parent-child linkages, and profile change audit logs based on technical specification; apply indexing and encryption on sensitive personal data (PII). | G13: Ryan, Nathan | H13: 6 | I13: P1 - High | J13: Done | K13: Migration script executes flawlessly; sensitive fields equipped with audit log schema; consistent foreign keys and constraints.
... A24: R4 | B24: PB-25 | C24: TSK-R4-03 | D24: AI/ML | E24: Synthetic data generate | F24: Base-knowledge for simulate income data | G24: Christian | H24: 4 | I24: P2-Medium | J24: Done | K24: Build in rules for synthetic data generation and having 100_000 samples

Sheet Sprint Backlog 2
A1: PBI Ref | B1: Task ID | C1: Category | D1: Task Title | E1: Description | F1: Assignee | G1: Estimate (Hours) | H1: Priority | I1: Status | J1: Definition of Done (DoD) | K1: Note
A2: US-004 | C2: Backend | D2: Create CPF Service simulation | E2: Simulate CPF service behaviour to later on can transfer money to this service as a real use case for later on integrated API | F2: Kevin | G2: 3h | H2: Low | I2: Done | J2: Create only nessecary fields and simulation, not breaking the current system workflow.
C3: Backend | D3: remaining Education Account funds transferred to CPF after closure | E3: Transfer the remaing money in the education account to the CPF, set the balance to 0 | F3: Kevin | G3: 2h | H3: Low | I3: Done | J3: No account with deactivate status should have money in the wallet
A4: US-010 | D4: view financial assistance information for my children | F4: Lucas, Christian, Nathan, Ryan, Arthur | I4: To do
A5: US-018 | C5: Backend | D5: Desgin Create/Update Profile APIs, get Profile Detail API | F5: Tyson | H5: Low | I5: Done | K5: Personal Information thôi, không liên quan đến School
A6: US-018 | C6: Frontend | D6: Design Profile Page, handle require update profile when login for the first time | F6: Nito | H6: Low | I6: To do
A7: US-026 | C7: Backend | D7: Prview and import academic-year, level and class CSV records | E7: Implement bulk create classes for SU | F7: Nito | G7: 1h | H7: Medium | I7: In progress | K7: Academic-years, Academic-levels, Class undone
A8: US-026 | C8: Frontend | D8: Prview and import academic-year, level and class CSV records | E8: Implement bulk create class page, export .xlxs template | F8: Nito | G8: 1h | H8: Medium | I8: In progress
A9: US-027 | C9: Backend | D9: Import student records with optional class assignments and see per-row processing outcomes | E9: Implement bulk create students for SU | F9: Nito | G9: 1h | H9: Medium | I9: To do
A10: US-027 | C10: Frontend | D10: Import student records with optional class assignments and see per-row processing outcomes | E10: Implment bulk create students page, export .xlxs template | F10: Nito | G10: 1h | H10: Medium | I10: To do
A11: US-028 | C11: Backend | D11: Create API for search content for the eligible education accounts | E11: All the education accounts must can be search by the MOE and the filter should point out exactly all the accounts with the suitable account | F11: Kevin | G11: 2h | H11: High | I11: Done | J11: Search API returns eligible accounts accurately with filter and pagination support.
C12: Frontend | D12: Implement frontend for education accounts list MOE User with search function | E12: All the education accounts must be display within 1 page with pagination and filters function showed clearly with UI/UX | F12: Kevin | G12: 1h | H12: Medium | I12: Done | J12: UI displays account list clearly with pagination, filters, and search functions.
C13: Backend | D13: Create API Top-up for Education Account | E13: Create a working API for top-up function for education accounts with the clean code and consistency in the codebase handling adding money to the education accounts | F13: Hugh | G13: 4h | H13: High | I13: Done | J13: Top-up API successfully credits funds, updates balance, and logs errors properly.
C14: Backend | D14: Create API to get transaction Top-up | E14: Create a working API for transaction of the top-up for education accounts with the clean code and consistency in the codebase handling saving whenever there is a transactions | F14: Hugh | G14: 3h | H14: Medium | I14: Done | J14: API retrieves top-up transactions with accurate filtering and details.
C15: Frontend | D15: Add new UI for the top-up page | E15: Create a seperated UI for top-up page with all the function within must be display clear with good UI/UX and the UI components should be consistent. | F15: Kevin | G15: 2h | H15: High | I15: Done | J15: Top-up UI is fully integrated, validates inputs, and matches design specs.
C16: Frontend | D16: Add table to view transaction Top-up history | E16: Create a transaction top-up history table for MOE user to auditing all the transaction, helping the users can easily view and identified the transaction they made. | F16: Kevin | G16: 1h | H16: Medium | I16: Done | J16: Transaction history table displays records clearly with sorting and pagination.
A17: US-029 | C17: Backend | D17: Create API for the bulk top up campaigns configuration | E17: Create an API to handle CRUD for the campaigns configuration, helping the MOE to later on can use these settings without setting up again | F17: Hugh | G17: 2h | H17: High | I17: Done | J17: Bulk campaign configuration CRUD APIs are implemented and validated.
C18: Frontend | D18: Implement frontend to config the bulk top up within the top up UI page | E18: Display all the configurations were made by the MOE before with good UI/UX | F18: Kevin | G18: 1h | H18: Medium | I18: Done | J18: Bulk config UI enables creating and managing campaign filters seamlessly.
A19: US-030 | C19: Backend | D19: Preview selected acocunt and forecast top up on selected account | E19: Create an API to handle showing education accounts with details after choosing the configuration or filtering the wanted criteria, as well as calculate the total top-up for each account. | F19: Hugh | G19: 2h | H19: Medium | I19: Done | J19: Preview API returns accurate account list and forecasted top-up totals.
C20: Frontend | D20: Implement selected preview modal to identified wrong criteria or spending if occurs | E20: Create a UI modal to display the selected accounts after the configurations or the filter, help the MOE to overview what they chose to identify if there is any wrong information they need to change. | F20: Kevin | G20: 1h | H20: Medium | I20: Done | J20: Preview modal displays selected accounts and total amount with confirmation flow.
A21: US-031 | C21: Backend | D21: Create API for executing bulk top up within the configuration | E21: Create an API for multiple top-up at once with multiple Nric requested within the configuration or the filter | F21: Hugh | G21: 2h | H21: Medium | I21: Done | J21: Bulk top-up API processes multiple NRICs reliably with proper transaction records.
C22: Frontend | D22: Implement frontend and handle bulking logic in UI | E22: Implement clean UI for handle bulking function, can choose multiple account or the whole list after configuration settings or filtering the needed account. | F22: Kevin | G22: 3h | H22: Medium | I22: Done | J22: Bulk execution UI handles multi-select and displays progress and outcome alerts.
A23: US-032 | C23: Backend | D23: Create transaction history for individual and bulk | E23: Create and handle audit logic so that the MOE user can check the consistency of the system after top-up for individuals as well as multiple education accounts | F23: Hugh | G23: 2h | H23: Low | I23: Done | J23: Audit history API records and retrieves individual and bulk operations accurately.
C24: Frontend | D24: Implement the transaction history table to audit the funding allocations and processing outcomes | E24: Implement transaction history table with clean UI within the page so that the MOE user can check the consistency of the system after top-up for individuals as well as multiple education accounts | F24: Kevin | G24: 3h | H24: Medium | I24: Done | J24: Audit table displays funding allocations and processing outcomes clearly.
A25: US-034 | C25: Backend | D25: [API] Design Core CRUD Endpoints for Fee Types, Components, and Rate Rules | E25: Design Core APIs: Establish the base REST API contracts and database schema for FeeTypes, FeeComponents, and FeeRateRules. Ensure standard CRUD operations are documented via Swagger/OpenAPI. | F25: Tyson | G25: 4H | H25: Critical | I25: Done
A26: US-034 | C26: Frontend | D26: Design UI to working with fee-types, fee-components, fee-rate-rules | F26: Nito | H26: Critical | I26: Done
A27: US-035 | C27: Backend | D27: [Security] Implement Tenant Isolation and schoolId Authorization for Fee Configurations | E27: Implement Multi-tenant RBAC APIs: Create robust authorization handlers to validate schoolId claims. Enforce strict tenant isolation on POST/PUT endpoints to ensure school users can only create or modify fee-types and fee-components within their authorized scope. | F27: Tyson | G27: 4H | H27: High | I27: Done
A28: US-035 | C28: Frontend | D28: Implement UI base on user role to meet the requirement | E28: School User can Create Fee-types and Fee-components for their own school by sending their schoolId in the API endpoint | F28: Nito | H28: Medium | I28: Done
A29: US-036 | C29: Backend | D29: [Command] Build Bulk Matrix Generation Logic for Fee Rate Rules | E29: Implement Bulk Generation Command: Build a dedicated CQRS Command to accept the two matrix criteria as inputs and programmatically cross-join them to generate the specific fee-rate-rule combinations. Optimize the resulting bulk database inserts | F29: Tyson | G29: 4H | H29: High | I29: Done
A30: US-036 | C30: Frontend | D30: Implement Fee Rate Rules Config Page for Fee Component | E30: The Rate Rules should be in the matrix format, automatically map 2 criteria to generate each fee-rate-rule | F30: Nito | H30: Critical | I30: Done
A31: US-037 | C31: Backend | D31: [API] Create Initialization Endpoint for Fee Publications | E31: Implement Fee Publication Creation Endpoint: Create an endpoint to accept publication metadata and the target scope criteria. Validate the payload and initialize the publication record in the database with a "Draft" or "Pending" state. | F31: Tyson | G31: 4H | H31: High | I31: Done
A32: US-037 | C32: Frontend | D32: Implement Create Fee Publication Page | E32: Users have to submit basic information and the scope for the batch | F32: Nito | H32: Critical | I32: Done
A33: US-038 | C33: Backend | D33: [Query] Implement Paginated Student Scope Evaluation Preview for Publications | E33: Implement Publication Scope Preview Query: Build a read-only endpoint that dynamically evaluates the publication scope against the student database, returning a paginated preview of affected students and their estimated calculated charges before final execution. | F33: Tyson | G33: 4H | H33: High | I33: Done
A34: US-038 | C34: Frontend | D34: Implement Fee Publication Result Preview Page | E34: Planning | F34: Nito | H34: Low | I34: Done
A35: US-039 | C35: Backend | D35: [Background Job] Build Async Processor and SignalR Hub for Fee Publishing Status | E35: Build the publish endpoint to immediately update the database status to "PROCESSING". Offload the heavy charge calculation and distribution logic to a background processor (e.g., Hangfire or an event-driven worker) and configure a SignalR hub to stream progress tracking percentages back to the client. | F35: Tyson | G35: 4H | H35: Critical | I35: Done
A36: US-039 | C36: Frontend | D36: Implement Publish Button for Fee Publications | E36: When click the publish button, the status of batch instantly change to "PROCESSING". Planning on implement realtime loading UI to check the progress | F36: Nito | H36: Critical | I36: Done
A37: US-040 | C37: Backend | D37: [Integration] Develop Student Charge Detail API and Sync with Billing Service | E37: Implement Charge Detail & Billing Sync: Create an API to aggregate and serve detailed student charge breakdowns. Implement an integration layer to securely communicate with the internal billing microservice (via HTTP client or message bus) to fetch and sync real-time payment statuses. | F37: Tyson | G37: 4H | H37: Critical | I37: Done
A38: US-40 | C38: Frontend | D38: Implement Student Charge Detail Page | E38: The Detail Page should show the real amount of money charged. Planning on integrate with the billing service to check the paying status | F38: Nito | H38: High | I38: To do
A39: US-041 | C39: Backend | D39: Implement FAS Application Submission API in E-Service | E39: As a Parent, I want to submit an FAS Application for a verified EA-linked child using household and income information, so that the child can be assessed for eligible financial assistance. | F39: Christian | I39: In progress | K39: Source Ref: R10
A40: US-041 | C40: Frontend | D40: Implement FAS Application Submission Form UI in E-service | E40: As a Parent, I want to submit an FAS Application for a verified EA-linked child using household and income information, so that the child can be assessed for eligible financial assistance. | F40: Arthur | H40: Medium | I40: In progress | J40: Integrated APIs and work normally via UI
...

Sheet Overview Sprint Backlog 2
B1: PBI Ref | C1: Task ID | D1: Category | E1: Task Title | F1: Description | G1: Assignee | H1: Estimate (Hours) | I1: Priority | J1: Status | K1: Definition of Done (DoD)
B2: US-004 | G2: Kevin,Hugh | J2: To do
B3: US-010 | G3: Lucas, Christian, Nathan, Ryan, Arthur | J3: To do
B4: US-018 | F4: Personal Information thôi, không liên quan đến School | G4: Nito, Tyson | J4: To do
B5: US-026 | F5: Academic-years, Academic-levels, Class undone | G5: Nito, Tyson | J5: To do
B6: US-027 | G6: Nito, Tyson | J6: To do
B7: US-028 | G7: Kevin,Hugh | J7: To do
B8: US-029 | G8: Kevin,Hugh | J8: To do
B9: US-030 | G9: Kevin,Hugh | J9: To do
B10: US-031 | G10: Kevin,Hugh | J10: To do
B11: US-032 | G11: Kevin,Hugh | J11: To do
B12: US-034 | G12: Nito, Tyson | J12: To do
B13: US-035 | G13: Nito, Tyson | J13: To do
B14: US-036 | G14: Nito, Tyson | J14: To do
B15: US-037 | G15: Nito, Tyson | J15: To do
B16: US-038 | G16: Nito, Tyson | J16: To do
B17: US-039 | G17: Nito, Tyson | J17: To do
B18: US-040 | G18: Nito, Tyson | J18: To do
B19: US-041 | F19: Source Ref: R10 | G19: Lucas, Christian, Nathan, Ryan, Arthur | J19: To do
B20: US-042 | F20: Source Ref: R5 | G20: Lucas, Christian, Nathan, Ryan, Arthur | J20: To do
B21: US-043 | F21: Source Ref: R5 | G21: Lucas, Christian, Nathan, Ryan, Arthur | J21: To do
B22: US-044 | G22: Lucas, Christian, Nathan, Ryan, Arthur | J22: To do
B23: US-045 | F23: Source Ref: R6 | G23: Lucas, Christian, Nathan, Ryan, Arthur | J23: To do
B24: US-046 | G24: Lucas, Christian, Nathan, Ryan, Arthur | J24: To do
B25: US-047 | G25: Lucas, Christian, Nathan, Ryan, Arthur | J25: To do
B26: US-048 | G26: Lucas, Christian, Nathan, Ryan, Arthur | J26: To do
B27: US-049 | G27: Lucas, Christian, Nathan, Ryan, Arthur | J27: To do
B28: US-050 | G28: Lucas, Christian, Nathan, Ryan, Arthur | J28: To do
B29: US-051 | G29: Lucas, Christian, Nathan, Ryan, Arthur | J29: To do
B30: US-052 | G30: Lucas, Christian, Nathan, Ryan, Arthur | J30: To do

Sheet Kanban Board Sprint 1
B1: SPRINT PROGRESS KANBAN BOARD
B2: TOTAL TASKS | D2: TO DO | F2: IN PROGRESS | H2: DONE | J2: COMPLETION RATE | L2: TOTAL HOURS
B3: =COUNTA('Sprint Backlog 1'!C2:C23) -> 22 | D3: =COUNTIF('Sprint Backlog 1'!J2:J23, "To Do") -> 0 | F3: =COUNTIF('Sprint Backlog 1'!J2:J23, "In progress") -> 0 | H3: =COUNTIF('Sprint Backlog 1'!J2:J23, "Done") -> 22 | J3: =H3/B3 -> 1 | L3: =SUM('Sprint Backlog 1'!H2:H23) -> 130
B4: 100% of sprint scope | D4: =TEXT(D3/$B$3, "0.0%") & " of total" -> 0,0% of total | F4: =TEXT(F3/$B$3, "0.0%") & " of total" -> 0,0% of total | H4: =TEXT(H3/$B$3, "0.0%") & " of total" -> 100,0% of total | J4: Target: 100% | L4: Estimated hours (h)
B6: ="TO DO (" & D3 & ")" -> TO DO (0) | F6: ="IN PROGRESS (" & F3 & ")" -> IN PROGRESS (0) | J6: =" DONE (" & H3 & ")" -> DONE (22)
B7: Task ID | C7: Task Title | D7: Assignee | E7: Estimate (h) | F7: Task ID | G7: Task Title | H7: Assignee | I7: Estimate (h) | J7: Task ID | K7: Task Title | L7: Assignee | M7: Estimate (h)
J8: =IFERROR(__xludf.DUMMYFUNCTION("IFERROR(CHOOSECOLS(FILTER('Sprint Backlog 1'!$C$2:$H$23, 'Sprint Backlog 1'!$J$2:$J$23 = ""Done""), 1, 3, 5, 6), """")"),"TSK-R1-01") -> TSK-R1-01 | K8: =IFERROR(__xludf.DUMMYFUNCTION("""COMPUTED_VALUE"""),"Draft Technical Specification Docx for R1 (Education Account Lifecycle)") -> Draft Technical Specification Docx for R1 (Education Account Lifecycle) | L8: =IFERROR(__xludf.DUMMYFUNCTION("""COMPUTED_VALUE"""),"Kevin,Hugh") -> Kevin,Hugh | M8: =IFERROR(__xludf.DUMMYFUNCTION("""COMPUTED_VALUE"""),4.0) -> 4
J9: =IFERROR(__xludf.DUMMYFUNCTION("""COMPUTED_VALUE"""),"TSK-R1-02") -> TSK-R1-02 | K9: =IFERROR(__xludf.DUMMYFUNCTION("""COMPUTED_VALUE"""),"Design Data Model & Migrations for Education Account Lifecycle") -> Design Data Model & Migrations for Education Account Lifecycle | L9: =IFERROR(__xludf.DUMMYFUNCTION("""COMPUTED_VALUE""")," Hugh") -> Hugh | M9: =IFERROR(__xludf.DUMMYFUNCTION("""COMPUTED_VALUE"""),5.0) -> 5
J10: =IFERROR(__xludf.DUMMYFUNCTION("""COMPUTED_VALUE"""),"TSK-R1-03") -> TSK-R1-03 | K10: =IFERROR(__xludf.DUMMYFUNCTION("""COMPUTED_VALUE"""),"Build Scheduled Job to automatically create & activate accounts at age 7") -> Build Scheduled Job to automatically create & activate accounts at age 7 | L10: =IFERROR(__xludf.DUMMYFUNCTION("""COMPUTED_VALUE"""),"Kevin") -> Kevin | M10: =IFERROR(__xludf.DUMMYFUNCTION("""COMPUTED_VALUE"""),4.0) -> 4
J11: =IFERROR(__xludf.DUMMYFUNCTION("""COMPUTED_VALUE"""),"TSK-R1-04") -> TSK-R1-04 | K11: =IFERROR(__xludf.DUMMYFUNCTION("""COMPUTED_VALUE"""),"Build Scheduled Job to automatically close accounts & transfer settlement to CPF at age 16") -> Build Scheduled Job to automatically close accounts & transfer settlement to CPF at age 16 | L11: =IFERROR(__xludf.DUMMYFUNCTION("""COMPUTED_VALUE"""),"Kevin") -> Kevin | M11: =IFERROR(__xludf.DUMMYFUNCTION("""COMPUTED_VALUE"""),4.0) -> 4
J12: =IFERROR(__xludf.DUMMYFUNCTION("""COMPUTED_VALUE"""),"TSK-R1-05") -> TSK-R1-05 | K12: =IFERROR(__xludf.DUMMYFUNCTION("""COMPUTED_VALUE"""),"Build Wallet CRUD APIs (create, credit, debit, update status, and get wallet) & Wallet Transaction functionality to handle wallet behavior, including APIs to retrieve and reverse transactions.") -> Build Wallet CRUD APIs (create, credit, debit, update status, and get wallet) & Wallet Transaction functionality to handle wallet behavior, including APIs to retrieve and reverse transactions. | L12: =IFERROR(__xludf.DUMMYFUNCTION("""COMPUTED_VALUE""")," Hugh") -> Hugh | M12: =IFERROR(__xludf.DUMMYFUNCTION("""COMPUTED_VALUE"""),8.0) -> 8
J13: =IFERROR(__xludf.DUMMYFUNCTION("""COMPUTED_VALUE"""),"TSK-R3-01") -> TSK-R3-01 | K13: =IFERROR(__xludf.DUMMYFUNCTION("""COMPUTED_VALUE"""),"Draft Technical Specification Docx for R3 (Master Data & Fee Management)") -> Draft Technical Specification Docx for R3 (Master Data & Fee Management) | L13: =IFERROR(__xludf.DUMMYFUNCTION("""COMPUTED_VALUE"""),"Nito, Tyson") -> Nito, Tyson | M13: =IFERROR(__xludf.DUMMYFUNCTION("""COMPUTED_VALUE"""),6.0) -> 6
J14: =IFERROR(__xludf.DUMMYFUNCTION("""COMPUTED_VALUE"""),"TSK-R3-02") -> TSK-R3-02 | K14: =IFERROR(__xludf.DUMMYFUNCTION("""COMPUTED_VALUE"""),"Design Data Model & Migrations for School Master Data & Fee Catalog") -> Design Data Model & Migrations for School Master Data & Fee Catalog | L14: =IFERROR(__xludf.DUMMYFUNCTION("""COMPUTED_VALUE"""),"Nito, Tyson") -> Nito, Tyson | M14: =IFERROR(__xludf.DUMMYFUNCTION("""COMPUTED_VALUE"""),7.0) -> 7
J15: =IFERROR(__xludf.DUMMYFUNCTION("""COMPUTED_VALUE"""),"TSK-R3-03") -> TSK-R3-03 | K15: =IFERROR(__xludf.DUMMYFUNCTION("""COMPUTED_VALUE"""),"Build Master Data CRUD APIs (School, Level, Class, Student) and RBAC Guard") -> Build Master Data CRUD APIs (School, Level, Class, Student) and RBAC Guard | L15: =IFERROR(__xludf.DUMMYFUNCTION("""COMPUTED_VALUE"""),"Nito, Tyson") -> Nito, Tyson | M15: =IFERROR(__xludf.DUMMYFUNCTION("""COMPUTED_VALUE"""),8.0) -> 8
J16: =IFERROR(__xludf.DUMMYFUNCTION("""COMPUTED_VALUE"""),"TSK-R3-04") -> TSK-R3-04 | K16: =IFERROR(__xludf.DUMMYFUNCTION("""COMPUTED_VALUE"""),"Build Fee Type Configuration Module & Student Charge Generation") -> Build Fee Type Configuration Module & Student Charge Generation | L16: =IFERROR(__xludf.DUMMYFUNCTION("""COMPUTED_VALUE"""),"Nito, Tyson") -> Nito, Tyson | M16: =IFERROR(__xludf.DUMMYFUNCTION("""COMPUTED_VALUE"""),8.0) -> 8
J17: =IFERROR(__xludf.DUMMYFUNCTION("""COMPUTED_VALUE"""),"TSK-R3-05") -> TSK-R3-05 | K17: =IFERROR(__xludf.DUMMYFUNCTION("""COMPUTED_VALUE"""),"Build School Management & Fee Configuration UI (Admin Portal)") -> Build School Management & Fee Configuration UI (Admin Portal) | L17: =IFERROR(__xludf.DUMMYFUNCTION("""COMPUTED_VALUE"""),"Nito, Tyson") -> Nito, Tyson | M17: =IFERROR(__xludf.DUMMYFUNCTION("""COMPUTED_VALUE"""),7.0) -> 7
J18: =IFERROR(__xludf.DUMMYFUNCTION("""COMPUTED_VALUE"""),"TSK-R8-01") -> TSK-R8-01 | K18: =IFERROR(__xludf.DUMMYFUNCTION("""COMPUTED_VALUE"""),"Draft Technical Specification Docx for R8 (Singpass Auth & Parent Portal)") -> Draft Technical Specification Docx for R8 (Singpass Auth & Parent Portal) | L18: =IFERROR(__xludf.DUMMYFUNCTION("""COMPUTED_VALUE"""),"Ryan, Nathan") -> Ryan, Nathan | M18: =IFERROR(__xludf.DUMMYFUNCTION("""COMPUTED_VALUE"""),6.0) -> 6
J19: =IFERROR(__xludf.DUMMYFUNCTION("""COMPUTED_VALUE"""),"TSK-R8-02") -> TSK-R8-02 | K19: =IFERROR(__xludf.DUMMYFUNCTION("""COMPUTED_VALUE"""),"Design Data Model & Migrations for Parents, Child Linkage, and Audit Log") -> Design Data Model & Migrations for Parents, Child Linkage, and Audit Log | L19: =IFERROR(__xludf.DUMMYFUNCTION("""COMPUTED_VALUE"""),"Ryan, Nathan") -> Ryan, Nathan | M19: =IFERROR(__xludf.DUMMYFUNCTION("""COMPUTED_VALUE"""),6.0) -> 6
J20: =IFERROR(__xludf.DUMMYFUNCTION("""COMPUTED_VALUE"""),"TSK-R8-03") -> TSK-R8-03 | K20: =IFERROR(__xludf.DUMMYFUNCTION("""COMPUTED_VALUE"""),"Integrate Singpass Authentication (Mock/Sandbox) & Parent-Student Authorization") -> Integrate Singpass Authentication (Mock/Sandbox) & Parent-Student Authorization | L20: =IFERROR(__xludf.DUMMYFUNCTION("""COMPUTED_VALUE"""),"Ryan, Nathan") -> Ryan, Nathan | M20: =IFERROR(__xludf.DUMMYFUNCTION("""COMPUTED_VALUE"""),8.0) -> 8
J21: =IFERROR(__xludf.DUMMYFUNCTION("""COMPUTED_VALUE"""),"TSK-R8-04") -> TSK-R8-04 | K21: =IFERROR(__xludf.DUMMYFUNCTION("""COMPUTED_VALUE"""),"Build API for Account Details & Parent Profile Update") -> Build API for Account Details & Parent Profile Update | L21: =IFERROR(__xludf.DUMMYFUNCTION("""COMPUTED_VALUE"""),"Ryan, Nathan") -> Ryan, Nathan | M21: =IFERROR(__xludf.DUMMYFUNCTION("""COMPUTED_VALUE"""),7.0) -> 7
J22: =IFERROR(__xludf.DUMMYFUNCTION("""COMPUTED_VALUE"""),"TSK-R8-05") -> TSK-R8-05 | K22: =IFERROR(__xludf.DUMMYFUNCTION("""COMPUTED_VALUE"""),"Build e-Service Portal UI: Account Dashboard & Profile Management") -> Build e-Service Portal UI: Account Dashboard & Profile Management | L22: =IFERROR(__xludf.DUMMYFUNCTION("""COMPUTED_VALUE"""),"Ryan, Nathan") -> Ryan, Nathan | M22: =IFERROR(__xludf.DUMMYFUNCTION("""COMPUTED_VALUE"""),8.0) -> 8
J23: =IFERROR(__xludf.DUMMYFUNCTION("""COMPUTED_VALUE"""),"TSK-R9-01") -> TSK-R9-01 | K23: =IFERROR(__xludf.DUMMYFUNCTION("""COMPUTED_VALUE"""),"Draft Technical Specification Docx for R9 (Payment Engine & Outstanding Dues)") -> Draft Technical Specification Docx for R9 (Payment Engine & Outstanding Dues) | L23: =IFERROR(__xludf.DUMMYFUNCTION("""COMPUTED_VALUE"""),"Lucas, Arthur") -> Lucas, Arthur | M23: =IFERROR(__xludf.DUMMYFUNCTION("""COMPUTED_VALUE"""),4.0) -> 4
J24: =IFERROR(__xludf.DUMMYFUNCTION("""COMPUTED_VALUE"""),"TSK-R9-02") -> TSK-R9-02 | K24: =IFERROR(__xludf.DUMMYFUNCTION("""COMPUTED_VALUE"""),"Design Data Model & Migrations for Transaction Management & Payment Gateway") -> Design Data Model & Migrations for Transaction Management & Payment Gateway | L24: =IFERROR(__xludf.DUMMYFUNCTION("""COMPUTED_VALUE"""),"Lucas, Arthur") -> Lucas, Arthur | M24: =IFERROR(__xludf.DUMMYFUNCTION("""COMPUTED_VALUE"""),5.0) -> 5
J25: =IFERROR(__xludf.DUMMYFUNCTION("""COMPUTED_VALUE"""),"TSK-R9-03") -> TSK-R9-03 | K25: =IFERROR(__xludf.DUMMYFUNCTION("""COMPUTED_VALUE"""),"Build API for Outstanding Dues & Payment Logic using Education Account") -> Build API for Outstanding Dues & Payment Logic using Education Account | L25: =IFERROR(__xludf.DUMMYFUNCTION("""COMPUTED_VALUE"""),"Lucas, Arthur") -> Lucas, Arthur | M25: =IFERROR(__xludf.DUMMYFUNCTION("""COMPUTED_VALUE"""),6.0) -> 6
J26: =IFERROR(__xludf.DUMMYFUNCTION("""COMPUTED_VALUE"""),"TSK-R9-04") -> TSK-R9-04 | K26: =IFERROR(__xludf.DUMMYFUNCTION("""COMPUTED_VALUE"""),"Integrate Online Payment Gateway (Sandbox Gateway & Webhook)") -> Integrate Online Payment Gateway (Sandbox Gateway & Webhook) | L26: =IFERROR(__xludf.DUMMYFUNCTION("""COMPUTED_VALUE"""),"Lucas, Arthur") -> Lucas, Arthur | M26: =IFERROR(__xludf.DUMMYFUNCTION("""COMPUTED_VALUE"""),6.0) -> 6
J27: =IFERROR(__xludf.DUMMYFUNCTION("""COMPUTED_VALUE"""),"TSK-R9-05") -> TSK-R9-05 | K27: =IFERROR(__xludf.DUMMYFUNCTION("""COMPUTED_VALUE"""),"Build e-Service Portal UI: Outstanding Dues Lookup & Checkout Flow") -> Build e-Service Portal UI: Outstanding Dues Lookup & Checkout Flow | L27: =IFERROR(__xludf.DUMMYFUNCTION("""COMPUTED_VALUE"""),"Lucas, Arthur") -> Lucas, Arthur | M27: =IFERROR(__xludf.DUMMYFUNCTION("""COMPUTED_VALUE"""),5.0) -> 5
J28: =IFERROR(__xludf.DUMMYFUNCTION("""COMPUTED_VALUE"""),"TSK-R4-01") -> TSK-R4-01 | K28: =IFERROR(__xludf.DUMMYFUNCTION("""COMPUTED_VALUE"""),"Research document for rule-based") -> Research document for rule-based | L28: =IFERROR(__xludf.DUMMYFUNCTION("""COMPUTED_VALUE"""),"Christian") -> Christian | M28: =IFERROR(__xludf.DUMMYFUNCTION("""COMPUTED_VALUE"""),4.0) -> 4
J29: =IFERROR(__xludf.DUMMYFUNCTION("""COMPUTED_VALUE"""),"TSK-R4-02") -> TSK-R4-02 | K29: =IFERROR(__xludf.DUMMYFUNCTION("""COMPUTED_VALUE"""),"Build demo static rule-based") -> Build demo static rule-based | L29: =IFERROR(__xludf.DUMMYFUNCTION("""COMPUTED_VALUE"""),"Christian") -> Christian | M29: =IFERROR(__xludf.DUMMYFUNCTION("""COMPUTED_VALUE"""),4.0) -> 4
