Workbook

Sheet Summary
A1: Tender Test Cases and Defects: Summary (Training Management: Enrolment, Assessment, Funding)
A2: All counts are formulas over TestCases, Checkpoint and Defects. No test case has been executed.
A4: Test cases by Status
A5: Status | B5: Count | C5: Percent | D5: Meaning
A6: Approve | B6: =COUNTIF(TestCases!$Y$2:$Y$328,A6) -> 90 | C6: =B6/B9 -> 0.27522936 | D6: Expected result comes from the clause, no open assumption
A7: Draft | B7: =COUNTIF(TestCases!$Y$2:$Y$328,A7) -> 233 | C7: =B7/B9 -> 0.71253823 | D7: Needs an assumption to write the expected result
A8: Reject | B8: =COUNTIF(TestCases!$Y$2:$Y$328,A8) -> 4 | C8: =B8/B9 -> 0.012232416 | D8: Clause gives no testable expectation, steps not written
A9: Total | B9: =SUM(B6:B8) -> 327 | C9: =SUM(C6:C8) -> 1
A11: Status by Priority
A12: Priority | B12: Approve | C12: Draft | D12: Reject | E12: Total
A13: Critical | B13: =COUNTIFS(TestCases!$J$2:$J$328,$A13,TestCases!$Y$2:$Y$328,"Approve") -> 21 | C13: =COUNTIFS(TestCases!$J$2:$J$328,$A13,TestCases!$Y$2:$Y$328,"Draft") -> 64 | D13: =COUNTIFS(TestCases!$J$2:$J$328,$A13,TestCases!$Y$2:$Y$328,"Reject") -> 0 | E13: =SUM(B13:D13) -> 85
A14: High | B14: =COUNTIFS(TestCases!$J$2:$J$328,$A14,TestCases!$Y$2:$Y$328,"Approve") -> 27 | C14: =COUNTIFS(TestCases!$J$2:$J$328,$A14,TestCases!$Y$2:$Y$328,"Draft") -> 78 | D14: =COUNTIFS(TestCases!$J$2:$J$328,$A14,TestCases!$Y$2:$Y$328,"Reject") -> 1 | E14: =SUM(B14:D14) -> 106
A15: Medium | B15: =COUNTIFS(TestCases!$J$2:$J$328,$A15,TestCases!$Y$2:$Y$328,"Approve") -> 24 | C15: =COUNTIFS(TestCases!$J$2:$J$328,$A15,TestCases!$Y$2:$Y$328,"Draft") -> 68 | D15: =COUNTIFS(TestCases!$J$2:$J$328,$A15,TestCases!$Y$2:$Y$328,"Reject") -> 1 | E15: =SUM(B15:D15) -> 93
A16: Low | B16: =COUNTIFS(TestCases!$J$2:$J$328,$A16,TestCases!$Y$2:$Y$328,"Approve") -> 18 | C16: =COUNTIFS(TestCases!$J$2:$J$328,$A16,TestCases!$Y$2:$Y$328,"Draft") -> 23 | D16: =COUNTIFS(TestCases!$J$2:$J$328,$A16,TestCases!$Y$2:$Y$328,"Reject") -> 2 | E16: =SUM(B16:D16) -> 43
A17: Total | B17: =SUM(B13:B16) -> 90 | C17: =SUM(C13:C16) -> 233 | D17: =SUM(D13:D16) -> 4 | E17: =SUM(E13:E16) -> 327
A19: Status by Severity (1 is the most severe)
A20: Severity | B20: Approve | C20: Draft | D20: Reject | E20: Total | F20: Meaning
A21: 1 | B21: =COUNTIFS(TestCases!$K$2:$K$328,$A21,TestCases!$Y$2:$Y$328,"Approve") -> 6 | C21: =COUNTIFS(TestCases!$K$2:$K$328,$A21,TestCases!$Y$2:$Y$328,"Draft") -> 45 | D21: =COUNTIFS(TestCases!$K$2:$K$328,$A21,TestCases!$Y$2:$Y$328,"Reject") -> 0 | E21: =SUM(B21:D21) -> 51 | F21: Blocker, or money, funding or compliance break
A22: 2 | B22: =COUNTIFS(TestCases!$K$2:$K$328,$A22,TestCases!$Y$2:$Y$328,"Approve") -> 44 | C22: =COUNTIFS(TestCases!$K$2:$K$328,$A22,TestCases!$Y$2:$Y$328,"Draft") -> 130 | D22: =COUNTIFS(TestCases!$K$2:$K$328,$A22,TestCases!$Y$2:$Y$328,"Reject") -> 1 | E22: =SUM(B22:D22) -> 175 | F22: Critical or major function fails
A23: 3 | B23: =COUNTIFS(TestCases!$K$2:$K$328,$A23,TestCases!$Y$2:$Y$328,"Approve") -> 32 | C23: =COUNTIFS(TestCases!$K$2:$K$328,$A23,TestCases!$Y$2:$Y$328,"Draft") -> 57 | D23: =COUNTIFS(TestCases!$K$2:$K$328,$A23,TestCases!$Y$2:$Y$328,"Reject") -> 3 | E23: =SUM(B23:D23) -> 92 | F23: Normal: wrong result with a workaround
A24: 4 | B24: =COUNTIFS(TestCases!$K$2:$K$328,$A24,TestCases!$Y$2:$Y$328,"Approve") -> 8 | C24: =COUNTIFS(TestCases!$K$2:$K$328,$A24,TestCases!$Y$2:$Y$328,"Draft") -> 1 | D24: =COUNTIFS(TestCases!$K$2:$K$328,$A24,TestCases!$Y$2:$Y$328,"Reject") -> 0 | E24: =SUM(B24:D24) -> 9 | F24: Minor or cosmetic
A25: Total | B25: =SUM(B21:B24) -> 90 | C25: =SUM(C21:C24) -> 233 | D25: =SUM(D21:D24) -> 4 | E25: =SUM(E21:E24) -> 327
A27: Priority by Severity (test cases)
A28: Priority | B28: Severity 1 | C28: Severity 2 | D28: Severity 3 | E28: Severity 4 | F28: Total
A29: Critical | B29: =COUNTIFS(TestCases!$J$2:$J$328,$A29,TestCases!$K$2:$K$328,1) -> 36 | C29: =COUNTIFS(TestCases!$J$2:$J$328,$A29,TestCases!$K$2:$K$328,2) -> 49 | D29: =COUNTIFS(TestCases!$J$2:$J$328,$A29,TestCases!$K$2:$K$328,3) -> 0 | E29: =COUNTIFS(TestCases!$J$2:$J$328,$A29,TestCases!$K$2:$K$328,4) -> 0 | F29: =SUM(B29:E29) -> 85
A30: High | B30: =COUNTIFS(TestCases!$J$2:$J$328,$A30,TestCases!$K$2:$K$328,1) -> 15 | C30: =COUNTIFS(TestCases!$J$2:$J$328,$A30,TestCases!$K$2:$K$328,2) -> 65 | D30: =COUNTIFS(TestCases!$J$2:$J$328,$A30,TestCases!$K$2:$K$328,3) -> 26 | E30: =COUNTIFS(TestCases!$J$2:$J$328,$A30,TestCases!$K$2:$K$328,4) -> 0 | F30: =SUM(B30:E30) -> 106
A31: Medium | B31: =COUNTIFS(TestCases!$J$2:$J$328,$A31,TestCases!$K$2:$K$328,1) -> 0 | C31: =COUNTIFS(TestCases!$J$2:$J$328,$A31,TestCases!$K$2:$K$328,2) -> 61 | D31: =COUNTIFS(TestCases!$J$2:$J$328,$A31,TestCases!$K$2:$K$328,3) -> 31 | E31: =COUNTIFS(TestCases!$J$2:$J$328,$A31,TestCases!$K$2:$K$328,4) -> 1 | F31: =SUM(B31:E31) -> 93
A32: Low | B32: =COUNTIFS(TestCases!$J$2:$J$328,$A32,TestCases!$K$2:$K$328,1) -> 0 | C32: =COUNTIFS(TestCases!$J$2:$J$328,$A32,TestCases!$K$2:$K$328,2) -> 0 | D32: =COUNTIFS(TestCases!$J$2:$J$328,$A32,TestCases!$K$2:$K$328,3) -> 35 | E32: =COUNTIFS(TestCases!$J$2:$J$328,$A32,TestCases!$K$2:$K$328,4) -> 8 | F32: =SUM(B32:E32) -> 43
A33: Total | B33: =SUM(B29:B32) -> 51 | C33: =SUM(C29:C32) -> 175 | D33: =SUM(D29:D32) -> 92 | E33: =SUM(E29:E32) -> 9 | F33: =SUM(F29:F32) -> 327
A35: Test cases by Module and Sprint (a clause in several sprints counts in each)
A36: Module | B36: Sprint 1 | C36: Sprint 2 | D36: Sprint 3 | E36: Unscheduled | F36: Rows
A37: Enrolment | B37: =COUNTIFS(TestCases!$C$2:$C$328,$A37,TestCases!$D$2:$D$328,"*1*") -> 45 | C37: =COUNTIFS(TestCases!$C$2:$C$328,$A37,TestCases!$D$2:$D$328,"*2*") -> 57 | D37: =COUNTIFS(TestCases!$C$2:$C$328,$A37,TestCases!$D$2:$D$328,"*3*") -> 18 | E37: =COUNTIFS(TestCases!$C$2:$C$328,$A37,TestCases!$D$2:$D$328,"Unscheduled") -> 1 | F37: =COUNTIFS(TestCases!$C$2:$C$328,$A37) -> 117
A38: Assessment | B38: =COUNTIFS(TestCases!$C$2:$C$328,$A38,TestCases!$D$2:$D$328,"*1*") -> 7 | C38: =COUNTIFS(TestCases!$C$2:$C$328,$A38,TestCases!$D$2:$D$328,"*2*") -> 3 | D38: =COUNTIFS(TestCases!$C$2:$C$328,$A38,TestCases!$D$2:$D$328,"*3*") -> 64 | E38: =COUNTIFS(TestCases!$C$2:$C$328,$A38,TestCases!$D$2:$D$328,"Unscheduled") -> 0 | F38: =COUNTIFS(TestCases!$C$2:$C$328,$A38) -> 68
A39: Funding | B39: =COUNTIFS(TestCases!$C$2:$C$328,$A39,TestCases!$D$2:$D$328,"*1*") -> 34 | C39: =COUNTIFS(TestCases!$C$2:$C$328,$A39,TestCases!$D$2:$D$328,"*2*") -> 92 | D39: =COUNTIFS(TestCases!$C$2:$C$328,$A39,TestCases!$D$2:$D$328,"*3*") -> 46 | E39: =COUNTIFS(TestCases!$C$2:$C$328,$A39,TestCases!$D$2:$D$328,"Unscheduled") -> 9 | F39: =COUNTIFS(TestCases!$C$2:$C$328,$A39) -> 142
A40: Total | B40: =SUM(B37:B39) -> 86 | C40: =SUM(C37:C39) -> 152 | D40: =SUM(D37:D39) -> 128 | E40: =SUM(E37:E39) -> 10 | F40: =SUM(F37:F39) -> 327
A42: Status by Module
A43: Module | B43: Approve | C43: Draft | D43: Reject | E43: Total
A44: Enrolment | B44: =COUNTIFS(TestCases!$C$2:$C$328,$A44,TestCases!$Y$2:$Y$328,"Approve") -> 36 | C44: =COUNTIFS(TestCases!$C$2:$C$328,$A44,TestCases!$Y$2:$Y$328,"Draft") -> 80 | D44: =COUNTIFS(TestCases!$C$2:$C$328,$A44,TestCases!$Y$2:$Y$328,"Reject") -> 1 | E44: =SUM(B44:D44) -> 117
A45: Assessment | B45: =COUNTIFS(TestCases!$C$2:$C$328,$A45,TestCases!$Y$2:$Y$328,"Approve") -> 24 | C45: =COUNTIFS(TestCases!$C$2:$C$328,$A45,TestCases!$Y$2:$Y$328,"Draft") -> 43 | D45: =COUNTIFS(TestCases!$C$2:$C$328,$A45,TestCases!$Y$2:$Y$328,"Reject") -> 1 | E45: =SUM(B45:D45) -> 68
A46: Funding | B46: =COUNTIFS(TestCases!$C$2:$C$328,$A46,TestCases!$Y$2:$Y$328,"Approve") -> 30 | C46: =COUNTIFS(TestCases!$C$2:$C$328,$A46,TestCases!$Y$2:$Y$328,"Draft") -> 110 | D46: =COUNTIFS(TestCases!$C$2:$C$328,$A46,TestCases!$Y$2:$Y$328,"Reject") -> 2 | E46: =SUM(B46:D46) -> 142
...

Sheet TestCases
A1: TC ID | B1: Requirement (Tender clause) | C1: Module | D1: Sprint | E1: Scenario ID | F1: Scenario Name | G1: Title | H1: Objective | I1: Lens | J1: Priority | K1: Severity | L1: Type | M1: Precondition | N1: Postcondition | O1: Test Data | P1: Steps | Q1: Expected Result | R1: Actual Result | S1: Traceability Requirement | T1: Technique | U1: Checkpoint Ref | V1: Assumption Ref | W1: Dependency Ref | X1: Test Type | Y1: Status | Z1: Reason
A2: TC-SCN-001-01 | B2: 2.2 | C2: Enrolment | D2: 1 | E2: SCN-001 | F2: Resident signs in with SingPass | G2: Resident signs in through SingPass | H2: A Singapore Resident authenticates through SingPass and is signed in. Case: Resident signs in through SingPass | I2: Happy Path | J2: Critical | K2: 1 | L2: positive | M2: 1. A test resident identity exists in the SingPass test service (ASM-01) | N2: Data created or changed by the steps stays in the SIT test data | O2: Test identity: test resident 01 | P2: 1. Open the Learner login URL 2. Select the SingPass option 3. Authenticate with a test resident identity at SingPass 4. Observe the page after authentication | Q2: 1. The System sends the resident to SingPass for authentication 2. After successful authentication the System signs the resident in 3. The learner landing page opens | R2: Not Executed | S2: Tender 2.2 (Enrolment, Sprint 1) | T2: EP | U2: CP-001 | V2: N/A | W2: ASM-01, ASM-03 | X2: Integration | Y2: Approve | Z2: 2.2 states that SingPass integration authenticates Singapore Residents for login
A3: TC-SCN-001-02 | B3: 2.2 | C3: Enrolment | D3: 1 | E3: SCN-001 | F3: Resident signs in with SingPass | G3: SingPass authentication fails | H3: A Singapore Resident authenticates through SingPass and is signed in. Case: SingPass authentication fails | I3: Failure&Recovery | J3: Critical | K3: 2 | L3: negative | M3: 1. A test resident identity exists in the SingPass test service (ASM-01) | N3: Data created or changed by the steps stays in the SIT test data | O3: Test identity: test resident 01 | P3: 1. Open the Learner login URL 2. Select the SingPass option 3. Cancel the authentication at SingPass 4. Observe the page that opens | Q3: 1. The resident is not signed in 2. The login page is shown again | R3: Not Executed | S3: Tender 2.2 (Enrolment, Sprint 1) | T3: EP | U3: CP-001 | V3: ASM-10 | W3: ASM-01, ASM-03 | X3: Integration | Y3: Draft | Z3: 2.2 requires authentication through SingPass. A failed authentication must not sign the user in
A4: TC-SCN-002-01 | B4: 2.4 | C4: Enrolment | D4: 1 | E4: SCN-002 | F4: Sign in with password and OTP | G4: Learner signs in with ID, password and OTP | H4: A user without SingPass or CorpPass signs in with ID, password and a one time password. Case: Learner signs in with ID, password and OTP | I4: Happy Path | J4: Critical | K4: 2 | L4: positive | M4: 1. A Learner account without SingPass exists (ASM-01) | N4: Data created or changed by the steps stays in the SIT test data | O4: Login ID: learner.test01 OTP: the code received by the tester | P4: 1. Open the Learner login URL 2. Enter a valid login ID and password 3. Enter the one time password received 4. Observe the result | Q4: 1. After the password step the System asks for a one time password 2. After the correct OTP the learner is signed in | R4: Not Executed | S4: Tender 2.4 (Enrolment, Sprint 1) | T4: EP | U4: CP-002 | V4: N/A | W4: ASM-01 | X4: Functional | Y4: Approve | Z4: 2.4 requires login ID, password and 2FA through OTP
A5: TC-SCN-002-02 | B5: 2.4 | C5: Enrolment | D5: 1 | E5: SCN-002 | F5: Sign in with password and OTP | G5: Wrong OTP is rejected | H5: A user without SingPass or CorpPass signs in with ID, password and a one time password. Case: Wrong OTP is rejected | I5: Negative | J5: Critical | K5: 2 | L5: negative | M5: 1. A Learner account without SingPass exists (ASM-01) | N5: Data created or changed by the steps stays in the SIT test data | O5: Login ID: learner.test01 OTP: 000000 | P5: 1. Open the Learner login URL 2. Enter a valid login ID and password 3. Enter an incorrect one time password 4. Observe the result | Q5: 1. The learner is not signed in 2. The login page or OTP page stays open | R5: Not Executed | S5: Tender 2.4 (Enrolment, Sprint 1) | T5: EP | U5: CP-002 | V5: ASM-10 | W5: ASM-01 | X5: Functional | Y5: Draft | Z5: 2.4 requires OTP as the second factor. A wrong OTP must not sign the user in
A6: TC-SCN-003-01 | B6: 5.3.1 | C6: Enrolment | D6: 1 | E6: SCN-003 | F6: Learner portal access | G6: Learner sees catalogue, progress, attendance, assessments and payments | H6: A registered learner uses the portal to browse the catalogue and see own course progress, attendance, assessments and payments. Case: Learner sees catalogue, progress, attendance, assessments and payments | I6: Happy Path | J6: High | K6: 3 | L6: positive | M6: 1. A learner with one enrolled course and one payment exists (ASM-01) | N6: No data is changed by this test | O6: Learner: learner.test01 | P6: 1. Sign in as a registered learner with at least one enrolled course 2. Open the course catalogue 3. Open the page that shows the learner's own courses 4. Check that progress, attendance, assessments and payments are shown | Q6: 1. The learner can browse the course catalogue 2. The learner sees own course progress, attendance, assessments and payments in the portal | R6: Not Executed | S6: Tender 5.3.1 (Enrolment, Sprint 1) | T6: EP | U6: CP-003 | V6: N/A | W6: ASM-01 | X6: Functional | Y6: Approve | Z6: 5.3.1 lists catalogue, progress, attendance, assessments and payments as portal access
A7: TC-SCN-004-01 | B7: 6.1.5 | C7: Enrolment | D7: 1 | E7: SCN-004 | F7: Route choice at registration | G7: Learner registers for the credit bearing route | H7: A course offers both a credit bearing and a non credit bearing route. Case: Learner registers for the credit bearing route | I7: Happy Path | J7: Critical | K7: 2 | L7: positive | M7: 1. A course exists with both routes and an open run (ASM-01) | N7: Data created or changed by the steps stays in the SIT test data | O7: Course: Test Course CB01 | P7: 1. Open a course that offers both routes 2. Select the credit bearing route 3. Complete and submit the registration 4. Open the registration record | Q7: 1. The two routes are shown as different options 2. The registration is saved with the credit bearing route | R7: Not Executed | S7: Tender 6.1.5 (Enrolment, Sprint 1) | T7: EP | U7: CP-004 | V7: N/A | W7: ASM-01 | X7: Functional | Y7: Approve | Z7: 6.1.5 requires the two routes to be differentiated and chosen at registration
A8: TC-SCN-004-02 | B8: 6.1.5 | C8: Enrolment | D8: 1 | E8: SCN-004 | F8: Route choice at registration | G8: Learner registers for the non credit bearing route | H8: A course offers both a credit bearing and a non credit bearing route. Case: Learner registers for the non credit bearing route | I8: Happy Path | J8: Critical | K8: 2 | L8: positive | M8: 1. A course exists with both routes and an open run (ASM-01) | N8: Data created or changed by the steps stays in the SIT test data | O8: Course: Test Course CB01 | P8: 1. Open the same course 2. Select the non credit bearing route 3. Complete and submit the registration 4. Open the registration record | Q8: 1. The registration is saved with the non credit bearing route and not with the credit bearing route | R8: Not Executed | S8: Tender 6.1.5 (Enrolment, Sprint 1) | T8: EP | U8: CP-004 | V8: N/A | W8: ASM-01 | X8: Functional | Y8: Approve | Z8: 6.1.5 requires both routes to be selectable
A9: TC-SCN-005-01 | B9: 6.1.6 | C9: Assessment | D9: 3 | E9: SCN-005 | F9: Assessment types and components | G9: Components and subcomponents are configured for an assessment type | H9: Assessment types and their components are configured per course. Case: Components and subcomponents are configured for an assessment type | I9: Data | J9: Low | K9: 3 | L9: positive | M9: 1. A course exists (ASM-01) | N9: Data created or changed by the steps stays in the SIT test data | O9: Assessment: project work with peer evaluation | P9: 1. Sign in as Course Administrator 2. Create an assessment of type project work 3. Add a peer evaluation component and a subcomponent 4. Save 5. Reopen it | Q9: 1. The assessment type is stored 2. The components and the subcomponent are saved and shown | R9: Not Executed | S9: Tender 6.1.6 (Assessment, Sprint 3) | T9: EP | U9: CP-005 | V9: N/A | W9: ASM-01 | X9: Functional | Y9: Approve | Z9: 6.1.6 requires configuration of components and subcomponents
A10: TC-SCN-006-01 | B10: 6.3.1 | C10: Funding | D10: 1 | E10: SCN-006 | F10: Fee profile creation | G10: Fee profile is created for self sponsored learners | H10: Fee profiles are created for each sponsorship type. Case: Fee profile is created for self sponsored learners | I10: Data | J10: Critical | K10: 2 | L10: positive | M10: 1. A test course exists (ASM-01) | N10: The profile can be selected for a course | O10: Profile: Self Profile 01 Fee: 1000 | P10: 1. Sign in as Finance Administrator 2. Create a fee profile named Self Profile 01 for self sponsored learners 3. Enter the course fee 4. Save 5. Reopen it | Q10: 1. The profile is saved for self sponsored learners with the entered fee | R10: Not Executed | S10: Tender 6.3.1 (Funding, Sprint 1) | T10: EP | U10: CP-006 | V10: N/A | W10: ASM-01 | X10: Functional | Y10: Approve | Z10: 6.3.1 requires a profile for self sponsored cases
A11: TC-SCN-006-02 | B11: 6.3.1 | C11: Funding | D11: 1 | E11: SCN-006 | F11: Fee profile creation | G11: Fee profile is created for company sponsored learners | H11: Fee profiles are created for each sponsorship type. Case: Fee profile is created for company sponsored learners | I11: Data | J11: Critical | K11: 2 | L11: positive | M11: 1. A test course exists (ASM-01) | N11: Data created or changed by the steps stays in the SIT test data | O11: Profile: Company Profile 01 Fee: 1000 | P11: 1. Sign in as Finance Administrator 2. Create a fee profile named Company Profile 01 for company sponsorship 3. Enter the course fee 4. Save 5. Reopen it | Q11: 1. The profile is saved for company sponsorship with the entered fee | R11: Not Executed | S11: Tender 6.3.1 (Funding, Sprint 1) | T11: EP | U11: CP-006 | V11: N/A | W11: ASM-01 | X11: Functional | Y11: Approve | Z11: 6.3.1 requires a profile for company sponsorships
A12: TC-SCN-007-01 | B12: 6.3.2 | C12: Funding | D12: 1 | E12: SCN-007 | F12: Fee and GST calculation | G12: Fee and GST are calculated on a course fee of 1000 | H12: The fee and the GST follow the configured rules. Case: Fee and GST are calculated on a course fee of 1000 | I12: Data Integrity | J12: Critical | K12: 1 | L12: positive | M12: 1. A fee profile with the rule (ASM-01) | N12: Data created or changed by the steps stays in the SIT test data | O12: Fee: 1000 GST rate: 9 percent | P12: 1. Create a calculation rule with GST 9 percent 2. Apply it to a course fee of 1000 3. Open the fee calculation | Q12: 1. The GST is 90.00 and the total is 1090.00 | R12: Not Executed | S12: Tender 6.3.2 (Funding, Sprint 1) | T12: EP | U12: CP-007 | V12: ASM-60 | W12: ASM-01 | X12: Functional | Y12: Draft | Z12: 6.3.2 requires the rules. The rate is configured by the tester
A13: TC-SCN-007-02 | B13: 6.3.2 | C13: Funding | D13: 1 | E13: SCN-007 | F13: Fee and GST calculation | G13: GST is rounded to the cent | H13: The fee and the GST follow the configured rules. Case: GST is rounded to the cent | I13: Boundary | J13: Critical | K13: 2 | L13: boundary | M13: 1. A fee profile with the rule (ASM-01) | N13: Data created or changed by the steps stays in the SIT test data | O13: Fee: 10.05 GST rate: 9 percent | P13: 1. Apply the rule to a fee of 10.05 2. Open the fee calculation | Q13: 1. The GST is 0.90 (0.9045 rounded to the cent) and the total is 10.95 | R13: Not Executed | S13: Tender 6.3.2 (Funding, Sprint 1) | T13: BVA | U13: CP-007 | V13: ASM-60 | W13: ASM-01 | X13: Functional | Y13: Draft | Z13: 6.3.2 requires automatic calculation. The rounding is assumed
... A328: TC-SCN-162-01 | B328: 18.4.5 | C328: Funding | D328: Unscheduled | E328: SCN-162 | F328: Latest PSEA requirements | G328: Verify the System meets the latest MOE PSEA integration requirements | H328: The latest requirements are met. Case: Verify the System meets the latest MOE PSEA integration requirements | I328: Workflow | J328: Low | K328: 3 | L328: negative | M328: N/A | N328: N/A | O328: N/A | P328: N/A | Q328: N/A | R328: Not Executed | S328: Tender 18.4.5 (Funding, Sprint Unscheduled) | T328: N/A | U328: CP-162 | V328: N/A | W328: ASM-01 | X328: Integration | Y328: Reject | Z328: The clause says always enhanced and latest and gives no requirement, version or date to test against

Sheet Scenarios
A1: Scenario ID | B1: Checkpoint | C1: Requirement (Tender clause) | D1: Module | E1: Sprint | F1: Lens | G1: Technique | H1: Title | I1: Condition | J1: Evidence | K1: Open ASM or NEG | L1: Test cases | M1: Approve | N1: Draft | O1: Reject | P1: Status
A2: SCN-001 | B2: CP-001 | C2: 2.2 | D2: Enrolment | E2: 1 | F2: Happy Path | G2: EP | H2: Resident signs in with SingPass | I2: A Singapore Resident authenticates through SingPass and is signed in | J2: Tender 2.2: "The System shall provide integration with SingPass for authentication of Singapore Residents for login." | K2: ASM-03, ASM-10 | L2: =COUNTIFS(TestCases!$E$2:$E$328,$A2) -> 2 | M2: =COUNTIFS(TestCases!$E$2:$E$328,$A2,TestCases!$Y$2:$Y$328,"Approve") -> 1 | N2: =COUNTIFS(TestCases!$E$2:$E$328,$A2,TestCases!$Y$2:$Y$328,"Draft") -> 1 | O2: =COUNTIFS(TestCases!$E$2:$E$328,$A2,TestCases!$Y$2:$Y$328,"Reject") -> 0 | P2: =IF(M2=L2,"Approve",IF(O2=L2,"Reject","Draft")) -> Draft
A3: SCN-002 | B3: CP-002 | C3: 2.4 | D3: Enrolment | E3: 1 | F3: Happy Path | G3: EP | H3: Sign in with password and OTP | I3: A user without SingPass or CorpPass signs in with ID, password and a one time password | J3: Tender 2.4: "The System shall cater for credential login ID, password and 2FA through One Time Password (OTP) for Learners, Corporate Customers and external users (external trainers, both local & overseas) who cannot be authenticated using SingPass and CorpPass for login." | K3: ASM-10 | L3: =COUNTIFS(TestCases!$E$2:$E$328,$A3) -> 2 | M3: =COUNTIFS(TestCases!$E$2:$E$328,$A3,TestCases!$Y$2:$Y$328,"Approve") -> 1 | N3: =COUNTIFS(TestCases!$E$2:$E$328,$A3,TestCases!$Y$2:$Y$328,"Draft") -> 1 | O3: =COUNTIFS(TestCases!$E$2:$E$328,$A3,TestCases!$Y$2:$Y$328,"Reject") -> 0 | P3: =IF(M3=L3,"Approve",IF(O3=L3,"Reject","Draft")) -> Draft
A4: SCN-003 | B4: CP-003 | C4: 5.3.1 | D4: Enrolment | E4: 1 | F4: Workflow | G4: EP | H4: Learner portal access | I4: A registered learner uses the portal to browse the catalogue and see own course progress, attendance, assessments and payments | J4: Tender 5.3.1: "Learners shall have access to browse the course catalogue, their course progress including attendance, assessments, payments and make requests via a portal. SingPass MyInfo integration should be done to allow users to retrieve personal particulars information easily." | K4: N/A | L4: =COUNTIFS(TestCases!$E$2:$E$328,$A4) -> 1 | M4: =COUNTIFS(TestCases!$E$2:$E$328,$A4,TestCases!$Y$2:$Y$328,"Approve") -> 1 | N4: =COUNTIFS(TestCases!$E$2:$E$328,$A4,TestCases!$Y$2:$Y$328,"Draft") -> 0 | O4: =COUNTIFS(TestCases!$E$2:$E$328,$A4,TestCases!$Y$2:$Y$328,"Reject") -> 0 | P4: =IF(M4=L4,"Approve",IF(O4=L4,"Reject","Draft")) -> Approve
A5: SCN-004 | B5: CP-004 | C5: 6.1.5 | D5: Enrolment | E5: 1 | F5: Data | G5: EP | H5: Route choice at registration | I5: A course offers both a credit bearing and a non credit bearing route | J5: Tender 6.1.5: "The System shall allow the differentiation between Credit Bearing and Non-Credit Bearing routes to a course and allow learners to pursue register accordingly." | K5: N/A | L5: =COUNTIFS(TestCases!$E$2:$E$328,$A5) -> 2 | M5: =COUNTIFS(TestCases!$E$2:$E$328,$A5,TestCases!$Y$2:$Y$328,"Approve") -> 2 | N5: =COUNTIFS(TestCases!$E$2:$E$328,$A5,TestCases!$Y$2:$Y$328,"Draft") -> 0 | O5: =COUNTIFS(TestCases!$E$2:$E$328,$A5,TestCases!$Y$2:$Y$328,"Reject") -> 0 | P5: =IF(M5=L5,"Approve",IF(O5=L5,"Reject","Draft")) -> Approve
A6: SCN-005 | B6: CP-005 | C6: 6.1.6 | D6: Assessment | E6: 3 | F6: Data | G6: EP | H6: Assessment types and components | I6: Assessment types and their components are configured per course | J6: Tender 6.1.6: "The System shall have the capability to differentiate the different courses and types of assessments created and allow configuration of assessment components and subcomponents. This would include peer evaluation, multiple choice questions, project work, etc." | K6: N/A | L6: =COUNTIFS(TestCases!$E$2:$E$328,$A6) -> 1 | M6: =COUNTIFS(TestCases!$E$2:$E$328,$A6,TestCases!$Y$2:$Y$328,"Approve") -> 1 | N6: =COUNTIFS(TestCases!$E$2:$E$328,$A6,TestCases!$Y$2:$Y$328,"Draft") -> 0 | O6: =COUNTIFS(TestCases!$E$2:$E$328,$A6,TestCases!$Y$2:$Y$328,"Reject") -> 0 | P6: =IF(M6=L6,"Approve",IF(O6=L6,"Reject","Draft")) -> Approve
A7: SCN-006 | B7: CP-006 | C7: 6.3.1 | D7: Funding | E7: 1 | F7: Data | G7: EP | H7: Fee profile creation | I7: Fee profiles are created for each sponsorship type | J7: Tender 6.3.1: "The System shall allow course fee profile creation for self-sponsored and company sponsorships cases." | K7: N/A | L7: =COUNTIFS(TestCases!$E$2:$E$328,$A7) -> 2 | M7: =COUNTIFS(TestCases!$E$2:$E$328,$A7,TestCases!$Y$2:$Y$328,"Approve") -> 2 | N7: =COUNTIFS(TestCases!$E$2:$E$328,$A7,TestCases!$Y$2:$Y$328,"Draft") -> 0 | O7: =COUNTIFS(TestCases!$E$2:$E$328,$A7,TestCases!$Y$2:$Y$328,"Reject") -> 0 | P7: =IF(M7=L7,"Approve",IF(O7=L7,"Reject","Draft")) -> Approve
A8: SCN-007 | B8: CP-007 | C8: 6.3.2 | D8: Funding | E8: 1 | F8: Data Integrity | G8: BVA | H8: Fee and GST calculation | I8: The fee and the GST follow the configured rules | J8: Tender 6.3.2: "The System shall allow the creation of rules for calculation of course fees and GST." | K8: ASM-60 | L8: =COUNTIFS(TestCases!$E$2:$E$328,$A8) -> 2 | M8: =COUNTIFS(TestCases!$E$2:$E$328,$A8,TestCases!$Y$2:$Y$328,"Approve") -> 0 | N8: =COUNTIFS(TestCases!$E$2:$E$328,$A8,TestCases!$Y$2:$Y$328,"Draft") -> 2 | O8: =COUNTIFS(TestCases!$E$2:$E$328,$A8,TestCases!$Y$2:$Y$328,"Reject") -> 0 | P8: =IF(M8=L8,"Approve",IF(O8=L8,"Reject","Draft")) -> Draft
A9: SCN-008 | B9: CP-008 | C9: 6.3.3 | D9: Funding | E9: 2 | F9: Business Risk | G9: DecisionTable | H9: Fee change by case | I9: Each case changes the fee and needs approval | J9: Tender 6.3.3: "The System shall allow fee changes and approval in cases including but not limited to: // 1) Withdrawals // 2) Leave of Absence (LOA) // 3) Deferrals // 4) Termination" | K9: ASM-61 | L9: =COUNTIFS(TestCases!$E$2:$E$328,$A9) -> 5 | M9: =COUNTIFS(TestCases!$E$2:$E$328,$A9,TestCases!$Y$2:$Y$328,"Approve") -> 0 | N9: =COUNTIFS(TestCases!$E$2:$E$328,$A9,TestCases!$Y$2:$Y$328,"Draft") -> 5 | O9: =COUNTIFS(TestCases!$E$2:$E$328,$A9,TestCases!$Y$2:$Y$328,"Reject") -> 0 | P9: =IF(M9=L9,"Approve",IF(O9=L9,"Reject","Draft")) -> Draft
A10: SCN-009 | B10: CP-009 | C10: 6.3.4 | D10: Funding | E10: 2 | F10: Workflow | G10: EP | H10: Payment processes | I10: Applicant and sponsor payments follow their own process | J10: Tender 6.3.4: "The System shall allow different payment processes for: 1) Applicant Payments, 2) Sponsor Payments." | K10: N/A | L10: =COUNTIFS(TestCases!$E$2:$E$328,$A10) -> 2 | M10: =COUNTIFS(TestCases!$E$2:$E$328,$A10,TestCases!$Y$2:$Y$328,"Approve") -> 2 | N10: =COUNTIFS(TestCases!$E$2:$E$328,$A10,TestCases!$Y$2:$Y$328,"Draft") -> 0 | O10: =COUNTIFS(TestCases!$E$2:$E$328,$A10,TestCases!$Y$2:$Y$328,"Reject") -> 0 | P10: =IF(M10=L10,"Approve",IF(O10=L10,"Reject","Draft")) -> Approve
A11: SCN-010 | B11: CP-010 | C11: 6.3.5 | D11: Funding | E11: 3 | F11: Business Risk | G11: EP | H11: Fees for reschedule and reassessment | I11: A fee is generated when a class or an assessment is rescheduled | J11: Tender 6.3.5: "The System shall have the capability to generate fees in cases including but not limited to: // 1) Rescheduling; // 2) Reassessment." | K11: ASM-61 | L11: =COUNTIFS(TestCases!$E$2:$E$328,$A11) -> 2 | M11: =COUNTIFS(TestCases!$E$2:$E$328,$A11,TestCases!$Y$2:$Y$328,"Approve") -> 0 | N11: =COUNTIFS(TestCases!$E$2:$E$328,$A11,TestCases!$Y$2:$Y$328,"Draft") -> 2 | O11: =COUNTIFS(TestCases!$E$2:$E$328,$A11,TestCases!$Y$2:$Y$328,"Reject") -> 0 | P11: =IF(M11=L11,"Approve",IF(O11=L11,"Reject","Draft")) -> Draft
A12: SCN-011 | B12: CP-011 | C12: 6.3.6 | D12: Funding | E12: 1,2,3 | F12: Business Risk | G12: DecisionTable | H12: Fee by criteria | I12: The fee payable changes with the learner or company criteria | J12: Tender 6.3.6: "The System shall have the capability to generate fees payable with automatic calculation based on criteria including but not limited to: // 1) Nationality/citizenship of candidates; // 2) Age/Date of Birth; // 3) Income; // 4) Alumni status // 5) Alumni credits // 6) Company SME ..." | K12: ASM-62, ASM-71 | L12: =COUNTIFS(TestCases!$E$2:$E$328,$A12) -> 6 | M12: =COUNTIFS(TestCases!$E$2:$E$328,$A12,TestCases!$Y$2:$Y$328,"Approve") -> 0 | N12: =COUNTIFS(TestCases!$E$2:$E$328,$A12,TestCases!$Y$2:$Y$328,"Draft") -> 6 | O12: =COUNTIFS(TestCases!$E$2:$E$328,$A12,TestCases!$Y$2:$Y$328,"Reject") -> 0 | P12: =IF(M12=L12,"Approve",IF(O12=L12,"Reject","Draft")) -> Draft
A13: SCN-012 | B13: CP-012 | C13: 6.3.7 | D13: Funding | E13: 2 | F13: Business Risk | G13: EP | H13: Fee structure setup and approval | I13: A fee structure is set up and approved by a checker and an approver | J13: Tender 6.3.7: "The System shall have the capability to setup various course fee structures and associated administration fee, volume discount, material fee, reassessment fee, registration fee, course exemption fee, etc including but not limited to: 1) Installment payments; 2) Late payments. The..." | K13: ASM-63, ASM-73 | L13: =COUNTIFS(TestCases!$E$2:$E$328,$A13) -> 5 | M13: =COUNTIFS(TestCases!$E$2:$E$328,$A13,TestCases!$Y$2:$Y$328,"Approve") -> 1 | N13: =COUNTIFS(TestCases!$E$2:$E$328,$A13,TestCases!$Y$2:$Y$328,"Draft") -> 4 | O13: =COUNTIFS(TestCases!$E$2:$E$328,$A13,TestCases!$Y$2:$Y$328,"Reject") -> 0 | P13: =IF(M13=L13,"Approve",IF(O13=L13,"Reject","Draft")) -> Draft
... A163: SCN-162 | B163: CP-162 | C163: 18.4.5 | D163: Funding | E163: Unscheduled | F163: Workflow | G163: EP | H163: Latest PSEA requirements | I163: The latest requirements are met | J163: Tender 18.4.5: "The System shall be always enhanced and updated with the latest MOE PSEA integration requirements." | K163: NEG-08 | L163: =COUNTIFS(TestCases!$E$2:$E$328,$A163) -> 1 | M163: =COUNTIFS(TestCases!$E$2:$E$328,$A163,TestCases!$Y$2:$Y$328,"Approve") -> 0 | N163: =COUNTIFS(TestCases!$E$2:$E$328,$A163,TestCases!$Y$2:$Y$328,"Draft") -> 0 | O163: =COUNTIFS(TestCases!$E$2:$E$328,$A163,TestCases!$Y$2:$Y$328,"Reject") -> 1 | P163: =IF(M163=L163,"Approve",IF(O163=L163,"Reject","Draft")) -> Reject

Sheet Checkpoint
A1: CP ID | B1: Location in Tender | C1: Requirement (Tender clause) | D1: Point to test | E1: Module | F1: Sprint | G1: Flag | H1: Test case can be generated | I1: Open ASM or NEG and Dependency | J1: Expected test case status | K1: Short reason | L1: TC IDs | M1: Defect IDs | N1: Approve | O1: Draft | P1: Reject
A2: CP-001 | B2: Tender row 24 | C2: 2.2 | D2: Singapore Residents are authenticated through SingPass for login | E2: Enrolment | F2: 1 | G2: Clear | H2: =IF(COUNTIFS(TestCases!$U$2:$U$328,$A2,TestCases!$Y$2:$Y$328,"<>Reject")>0,"Yes","No") -> Yes | I2: ASM-03, ASM-10 | J2: Approve | K2: The expected result is read from the clause text | L2: TC-SCN-001-01, TC-SCN-001-02 | M2: DEF-001 | N2: =COUNTIFS(TestCases!$U$2:$U$328,$A2,TestCases!$Y$2:$Y$328,"Approve") -> 1 | O2: =COUNTIFS(TestCases!$U$2:$U$328,$A2,TestCases!$Y$2:$Y$328,"Draft") -> 1 | P2: =COUNTIFS(TestCases!$U$2:$U$328,$A2,TestCases!$Y$2:$Y$328,"Reject") -> 0
A3: CP-002 | B3: Tender row 26 | C3: 2.4 | D3: Learners, Corporate Customers and external users who cannot use SingPass or CorpPass log in with ID, password and OTP | E3: Enrolment | F3: 1 | G3: Assumed | H3: =IF(COUNTIFS(TestCases!$U$2:$U$328,$A3,TestCases!$Y$2:$Y$328,"<>Reject")>0,"Yes","No") -> Yes | I3: ASM-10 | J3: Draft | K3: Draft cases need ASM-10 to write the expected result | L3: TC-SCN-002-01, TC-SCN-002-02 | M3: N/A | N3: =COUNTIFS(TestCases!$U$2:$U$328,$A3,TestCases!$Y$2:$Y$328,"Approve") -> 1 | O3: =COUNTIFS(TestCases!$U$2:$U$328,$A3,TestCases!$Y$2:$Y$328,"Draft") -> 1 | P3: =COUNTIFS(TestCases!$U$2:$U$328,$A3,TestCases!$Y$2:$Y$328,"Reject") -> 0
A4: CP-003 | B4: Tender row 180 | C4: 5.3.1 | D4: Registered learners browse the catalogue, their progress, attendance, assessments and payments, and make requests in the portal | E4: Enrolment | F4: 1 | G4: Clear | H4: =IF(COUNTIFS(TestCases!$U$2:$U$328,$A4,TestCases!$Y$2:$Y$328,"<>Reject")>0,"Yes","No") -> Yes | I4: N/A | J4: Approve | K4: The expected result is read from the clause text | L4: TC-SCN-003-01 | M4: N/A | N4: =COUNTIFS(TestCases!$U$2:$U$328,$A4,TestCases!$Y$2:$Y$328,"Approve") -> 1 | O4: =COUNTIFS(TestCases!$U$2:$U$328,$A4,TestCases!$Y$2:$Y$328,"Draft") -> 0 | P4: =COUNTIFS(TestCases!$U$2:$U$328,$A4,TestCases!$Y$2:$Y$328,"Reject") -> 0
A5: CP-004 | B5: Tender row 202 | C5: 6.1.5 | D5: Credit bearing and non credit bearing routes are different and learners register for the route they choose | E5: Enrolment | F5: 1 | G5: Clear | H5: =IF(COUNTIFS(TestCases!$U$2:$U$328,$A5,TestCases!$Y$2:$Y$328,"<>Reject")>0,"Yes","No") -> Yes | I5: N/A | J5: Approve | K5: The expected result is read from the clause text | L5: TC-SCN-004-01, TC-SCN-004-02 | M5: N/A | N5: =COUNTIFS(TestCases!$U$2:$U$328,$A5,TestCases!$Y$2:$Y$328,"Approve") -> 2 | O5: =COUNTIFS(TestCases!$U$2:$U$328,$A5,TestCases!$Y$2:$Y$328,"Draft") -> 0 | P5: =COUNTIFS(TestCases!$U$2:$U$328,$A5,TestCases!$Y$2:$Y$328,"Reject") -> 0
A6: CP-005 | B6: Tender row 203 | C6: 6.1.6 | D6: Assessments of different courses and types are differentiated and components and subcomponents are configurable (peer evaluation, multiple choice, project work) | E6: Assessment | F6: 3 | G6: Clear | H6: =IF(COUNTIFS(TestCases!$U$2:$U$328,$A6,TestCases!$Y$2:$Y$328,"<>Reject")>0,"Yes","No") -> Yes | I6: N/A | J6: Approve | K6: The expected result is read from the clause text | L6: TC-SCN-005-01 | M6: N/A | N6: =COUNTIFS(TestCases!$U$2:$U$328,$A6,TestCases!$Y$2:$Y$328,"Approve") -> 1 | O6: =COUNTIFS(TestCases!$U$2:$U$328,$A6,TestCases!$Y$2:$Y$328,"Draft") -> 0 | P6: =COUNTIFS(TestCases!$U$2:$U$328,$A6,TestCases!$Y$2:$Y$328,"Reject") -> 0
A7: CP-006 | B7: Tender row 222 | C7: 6.3.1 | D7: Course fee profiles are created for self sponsored and company sponsored cases | E7: Funding | F7: 1 | G7: Clear | H7: =IF(COUNTIFS(TestCases!$U$2:$U$328,$A7,TestCases!$Y$2:$Y$328,"<>Reject")>0,"Yes","No") -> Yes | I7: N/A | J7: Approve | K7: The expected result is read from the clause text | L7: TC-SCN-006-01, TC-SCN-006-02 | M7: N/A | N7: =COUNTIFS(TestCases!$U$2:$U$328,$A7,TestCases!$Y$2:$Y$328,"Approve") -> 2 | O7: =COUNTIFS(TestCases!$U$2:$U$328,$A7,TestCases!$Y$2:$Y$328,"Draft") -> 0 | P7: =COUNTIFS(TestCases!$U$2:$U$328,$A7,TestCases!$Y$2:$Y$328,"Reject") -> 0
A8: CP-007 | B8: Tender row 223 | C8: 6.3.2 | D8: Rules for calculation of course fees and GST are created | E8: Funding | F8: 1 | G8: Assumed | H8: =IF(COUNTIFS(TestCases!$U$2:$U$328,$A8,TestCases!$Y$2:$Y$328,"<>Reject")>0,"Yes","No") -> Yes | I8: ASM-60 | J8: Draft | K8: Draft cases need ASM-60 to write the expected result | L8: TC-SCN-007-01, TC-SCN-007-02 | M8: DEF-002 | N8: =COUNTIFS(TestCases!$U$2:$U$328,$A8,TestCases!$Y$2:$Y$328,"Approve") -> 0 | O8: =COUNTIFS(TestCases!$U$2:$U$328,$A8,TestCases!$Y$2:$Y$328,"Draft") -> 2 | P8: =COUNTIFS(TestCases!$U$2:$U$328,$A8,TestCases!$Y$2:$Y$328,"Reject") -> 0
A9: CP-008 | B9: Tender rows 224 to 228 | C9: 6.3.3 | D9: Fee changes and approval for withdrawals, leave of absence, deferrals and termination | E9: Funding | F9: 2 | G9: Assumed | H9: =IF(COUNTIFS(TestCases!$U$2:$U$328,$A9,TestCases!$Y$2:$Y$328,"<>Reject")>0,"Yes","No") -> Yes | I9: ASM-61 | J9: Draft | K9: Draft cases need ASM-61 to write the expected result | L9: TC-SCN-008-01, TC-SCN-008-02, TC-SCN-008-03, TC-SCN-008-04, TC-SCN-008-05 | M9: DEF-003 | N9: =COUNTIFS(TestCases!$U$2:$U$328,$A9,TestCases!$Y$2:$Y$328,"Approve") -> 0 | O9: =COUNTIFS(TestCases!$U$2:$U$328,$A9,TestCases!$Y$2:$Y$328,"Draft") -> 5 | P9: =COUNTIFS(TestCases!$U$2:$U$328,$A9,TestCases!$Y$2:$Y$328,"Reject") -> 0
A10: CP-009 | B10: Tender row 229 | C10: 6.3.4 | D10: Different payment processes for applicant payments and sponsor payments | E10: Funding | F10: 2 | G10: Clear | H10: =IF(COUNTIFS(TestCases!$U$2:$U$328,$A10,TestCases!$Y$2:$Y$328,"<>Reject")>0,"Yes","No") -> Yes | I10: N/A | J10: Approve | K10: The expected result is read from the clause text | L10: TC-SCN-009-01, TC-SCN-009-02 | M10: N/A | N10: =COUNTIFS(TestCases!$U$2:$U$328,$A10,TestCases!$Y$2:$Y$328,"Approve") -> 2 | O10: =COUNTIFS(TestCases!$U$2:$U$328,$A10,TestCases!$Y$2:$Y$328,"Draft") -> 0 | P10: =COUNTIFS(TestCases!$U$2:$U$328,$A10,TestCases!$Y$2:$Y$328,"Reject") -> 0
A11: CP-010 | B11: Tender rows 230 to 232 | C11: 6.3.5 | D11: Fees are generated for rescheduling and reassessment | E11: Funding | F11: 3 | G11: Assumed | H11: =IF(COUNTIFS(TestCases!$U$2:$U$328,$A11,TestCases!$Y$2:$Y$328,"<>Reject")>0,"Yes","No") -> Yes | I11: ASM-61 | J11: Draft | K11: Draft cases need ASM-61 to write the expected result | L11: TC-SCN-010-01, TC-SCN-010-02 | M11: N/A | N11: =COUNTIFS(TestCases!$U$2:$U$328,$A11,TestCases!$Y$2:$Y$328,"Approve") -> 0 | O11: =COUNTIFS(TestCases!$U$2:$U$328,$A11,TestCases!$Y$2:$Y$328,"Draft") -> 2 | P11: =COUNTIFS(TestCases!$U$2:$U$328,$A11,TestCases!$Y$2:$Y$328,"Reject") -> 0
A12: CP-011 | B12: Tender rows 233 to 240 | C12: 6.3.6 | D12: Fees payable are calculated automatically by nationality, age, income, alumni status, alumni credits, company SME status and MOE teacher | E12: Funding | F12: 1,2,3 | G12: Assumed | H12: =IF(COUNTIFS(TestCases!$U$2:$U$328,$A12,TestCases!$Y$2:$Y$328,"<>Reject")>0,"Yes","No") -> Yes | I12: ASM-62, ASM-71 | J12: Draft | K12: Draft cases need ASM-62, ASM-71 to write the expected result | L12: TC-SCN-011-01, TC-SCN-011-02, TC-SCN-011-03, TC-SCN-011-04, TC-SCN-011-05, TC-SCN-011-06 | M12: DEF-004, DEF-005 | N12: =COUNTIFS(TestCases!$U$2:$U$328,$A12,TestCases!$Y$2:$Y$328,"Approve") -> 0 | O12: =COUNTIFS(TestCases!$U$2:$U$328,$A12,TestCases!$Y$2:$Y$328,"Draft") -> 6 | P12: =COUNTIFS(TestCases!$U$2:$U$328,$A12,TestCases!$Y$2:$Y$328,"Reject") -> 0
A13: CP-012 | B13: Tender row 241 | C13: 6.3.7 | D13: Fee structures with administration, volume discount, material, reassessment, registration and exemption fees, installments, late payments and checker and approver | E13: Funding | F13: 2 | G13: Assumed | H13: =IF(COUNTIFS(TestCases!$U$2:$U$328,$A13,TestCases!$Y$2:$Y$328,"<>Reject")>0,"Yes","No") -> Yes | I13: ASM-63, ASM-73 | J13: Draft | K13: Draft cases need ASM-63, ASM-73 to write the expected result | L13: TC-SCN-012-01, TC-SCN-012-02, TC-SCN-012-03, TC-SCN-012-04, TC-SCN-012-05 | M13: DEF-006 | N13: =COUNTIFS(TestCases!$U$2:$U$328,$A13,TestCases!$Y$2:$Y$328,"Approve") -> 1 | O13: =COUNTIFS(TestCases!$U$2:$U$328,$A13,TestCases!$Y$2:$Y$328,"Draft") -> 4 | P13: =COUNTIFS(TestCases!$U$2:$U$328,$A13,TestCases!$Y$2:$Y$328,"Reject") -> 0
... A163: CP-162 | B163: Tender row 969 | C163: 18.4.5 | D163: The System is always enhanced and updated with the latest MOE PSEA integration requirements | E163: Funding | F163: Unscheduled | G163: Blocked | H163: =IF(COUNTIFS(TestCases!$U$2:$U$328,$A163,TestCases!$Y$2:$Y$328,"<>Reject")>0,"Yes","No") -> No | I163: NEG-08 | J163: Reject | K163: No expected result can be written from this clause | L163: TC-SCN-162-01 | M163: N/A | N163: =COUNTIFS(TestCases!$U$2:$U$328,$A163,TestCases!$Y$2:$Y$328,"Approve") -> 0 | O163: =COUNTIFS(TestCases!$U$2:$U$328,$A163,TestCases!$Y$2:$Y$328,"Draft") -> 0 | P163: =COUNTIFS(TestCases!$U$2:$U$328,$A163,TestCases!$Y$2:$Y$328,"Reject") -> 1

Sheet Defects
A1: Defect ID | B1: Module | C1: Sprint | D1: Tender clause | E1: Flow step (draft) | F1: Related TC IDs | G1: Summary | H1: Environment | I1: Preconditions | J1: Steps to Reproduce | K1: Expected Result | L1: Potential Actual Result (hypothetical) | M1: Business impact | N1: Severity | O1: Impact level | P1: Urgency | Q1: Priority | R1: Triage rationale | S1: Evidence | T1: Status | U1: Suggested regression suite
A2: DEF-001 | B2: Enrolment | C2: 1 | D2: 2.2 | E2: 1 Login and MyInfo | F2: TC-SCN-001-01 | G2: [Login] Resident is not signed in after successful SingPass authentication, the login page reloads | H2: SIT (assumed, ASM-01) | I2: 1. A test resident identity exists in the SingPass test service | J2: 1. Open the Learner login URL 2. Select the SingPass option 3. Authenticate with a test resident identity at SingPass 4. Observe the page after authentication | K2: 1. The System sends the resident to SingPass for authentication 2. After successful authentication the System signs the resident in 3. The learner landing page opens | L2: The login page loads again after SingPass returns success; no session is created | M2: Residents cannot reach the learner portal, so self enrolment cannot start | N2: 1 | O2: =IF(N2<=2,"High","Low") -> High | P2: High | Q2: =IF(O2="High",IF(P2="High","Critical","High"),IF(P2="High","Medium","Low")) -> Critical | R2: Blocks the first step of Self-Enrol. Severity 1: Blocker, or money, funding or compliance break. Urgency High by ASM-92. | S2: Tender 2.2: "The System shall provide integration with SingPass for authentication of Singapore Residents for login." | T2: Potential | U2: =IF(N2=1,"Smoke",IF(N2=2,"Regression Core","Regression Extended")) -> Smoke
A3: DEF-002 | B3: Funding | C3: 1 | D3: 6.3.2 | E3: 6 Net fee and invoice | F3: TC-SCN-007-01 | G3: [Funding] GST is charged twice on the course fee | H3: SIT (assumed, ASM-01) | I3: 1. A fee profile with the rule | J3: 1. Create a calculation rule with GST 9 percent 2. Apply it to a course fee of 1000 3. Open the fee calculation | K3: 1. The GST is 90.00 and the total is 1090.00 | L3: The GST is 180.00 and the total is 1180.00 for a fee of 1000 with a rate of 9 percent | M3: The learner is overcharged and the finance records are wrong | N3: 1 | O3: =IF(N3<=2,"High","Low") -> High | P3: High | Q3: =IF(O3="High",IF(P3="High","Critical","High"),IF(P3="High","Medium","Low")) -> Critical | R3: Money is calculated wrongly on every invoice. Severity 1: Blocker, or money, funding or compliance break. Urgency High by ASM-92. | S3: Tender 6.3.2: "The System shall allow the creation of rules for calculation of course fees and GST." | T3: Potential | U3: =IF(N3=1,"Smoke",IF(N3=2,"Regression Core","Regression Extended")) -> Smoke
A4: DEF-003 | B4: Funding | C4: 2 | D4: 6.3.3 | E4: 4 Grant eligibility and fee | F4: TC-SCN-008-05 | G4: [Funding] Fee change of a withdrawal is applied before the approver approves | H4: SIT (assumed, ASM-01) | I4: 1. A paid enrolment and a configured rule | J4: 1. Withdraw a paid learner 2. Submit the fee change 3. Open the fee before the approval | K4: 1. The fee is unchanged until the approver approves | L4: The fee is already changed while the request is pending approval | M4: A fee is reduced without the required approval, an audit finding | N4: 1 | O4: =IF(N4<=2,"High","Low") -> High | P4: High | Q4: =IF(O4="High",IF(P4="High","Critical","High"),IF(P4="High","Medium","Low")) -> Critical | R4: Control for money is bypassed. Severity 1: Blocker, or money, funding or compliance break. Urgency High by ASM-92. | S4: Tender 6.3.3: "The System shall allow fee changes and approval in cases including but not limited to: // 1) Withdrawals // 2) Leave of Absence (LOA) // 3) Deferrals // 4) Termination" | T4: Potential | U4: =IF(N4=1,"Smoke",IF(N4=2,"Regression Core","Regression Extended")) -> Smoke
A5: DEF-004 | B5: Funding | C5: 1,2,3 | D5: 6.3.6 | E5: 4 Grant eligibility and fee | F5: TC-SCN-011-02 | G5: [Funding] Learner at the age limit gets the fee of the younger band | H5: SIT (assumed, ASM-01) | I5: 1. An age limit of 40 is configured | J5: 1. Register a learner exactly at the configured age limit and one a year younger 2. Open the fee payable of each | K5: 1. The learner at the limit and the younger learner each get the fee configured for their age band | L5: The learner aged exactly 40 is charged the fee of the below 40 band | M5: The learner is charged the wrong fee at the boundary | N5: 2 | O5: =IF(N5<=2,"High","Low") -> High | P5: High | Q5: =IF(O5="High",IF(P5="High","Critical","High"),IF(P5="High","Medium","Low")) -> Critical | R5: Boundary error on a money rule. Severity 2: Critical or major function fails. Urgency High by ASM-92. | S5: Tender 6.3.6: "The System shall have the capability to generate fees payable with automatic calculation based on criteria including but not limited to: // 1) Nationality/citizenship of candidates; // 2) Age/Date of Birth; // 3) Income; // 4) Alumni status // 5) Alumni credits // 6) Company SME ..." | T5: Potential | U5: =IF(N5=1,"Smoke",IF(N5=2,"Regression Core","Regression Extended")) -> Regression Core
A6: DEF-005 | B6: Funding | C6: 1,2,3 | D6: 6.3.6 | E6: 4 Grant eligibility and fee | F6: TC-SCN-011-05 | G6: [Funding] SME company is charged the fee of a non SME company | H6: SIT (assumed, ASM-01) | I6: 1. An SME rule is configured | J6: 1. Register a learner for an SME company and a learner for a non SME company 2. Open the fee payable of each | K6: 1. The SME company gets the fee configured for SME status and the other does not | L6: The fee payable of the SME company equals the full fee | M6: The company loses the SME entitlement and complains | N6: 2 | O6: =IF(N6<=2,"High","Low") -> High | P6: High | Q6: =IF(O6="High",IF(P6="High","Critical","High"),IF(P6="High","Medium","Low")) -> Critical | R6: Wrong fee for one group of customers. Severity 2: Critical or major function fails. Urgency High by ASM-92. | S6: Tender 6.3.6: "The System shall have the capability to generate fees payable with automatic calculation based on criteria including but not limited to: // 1) Nationality/citizenship of candidates; // 2) Age/Date of Birth; // 3) Income; // 4) Alumni status // 5) Alumni credits // 6) Company SME ..." | T6: Potential | U6: =IF(N6=1,"Smoke",IF(N6=2,"Regression Core","Regression Extended")) -> Regression Core
A7: DEF-006 | B7: Funding | C7: 2 | D7: 6.3.7 | E7: 4 Grant eligibility and fee | F7: TC-SCN-012-05 | G7: [Funding] The user who prepared a fee structure can approve it | H7: SIT (assumed, ASM-01) | I7: 1. A fee structure prepared by one user | J7: 1. Prepare a fee structure 2. Try to approve it with the same user | K7: 1. The approval is refused for the same user | L7: The same user approves the own setup and it becomes active | M7: Check and balance is lost and fees can be changed without a second person | N7: 1 | O7: =IF(N7<=2,"High","Low") -> High | P7: High | Q7: =IF(O7="High",IF(P7="High","Critical","High"),IF(P7="High","Medium","Low")) -> Critical | R7: Audit control fails on fee setup. Severity 1: Blocker, or money, funding or compliance break. Urgency High by ASM-92. | S7: Tender 6.3.7: "The System shall have the capability to setup various course fee structures and associated administration fee, volume discount, material fee, reassessment fee, registration fee, course exemption fee, etc including but not limited to: 1) Installment payments; 2) Late payments. The..." | T7: Potential | U7: =IF(N7=1,"Smoke",IF(N7=2,"Regression Core","Regression Extended")) -> Smoke
A8: DEF-007 | B8: Funding | C8: 1,2 | D8: 6.4.2 | E8: 4 Grant eligibility and fee | F8: TC-SCN-014-04 | G8: [Funding] Group discount is not applied to the third member of a group | H8: SIT (assumed, ASM-01) | I8: 1. A configured group discount | J8: 1. Configure a group discount 2. Enrol a group 3. Open the fee of each member | K8: 1. The group discount is applied to each member of the group | L8: The first two members get the discount and the third pays the full fee | M8: Some learners are overcharged | N8: 2 | O8: =IF(N8<=2,"High","Low") -> High | P8: High | Q8: =IF(O8="High",IF(P8="High","Critical","High"),IF(P8="High","Medium","Low")) -> Critical | R8: Part of a group is charged wrongly. Severity 2: Critical or major function fails. Urgency High by ASM-92. | S8: Tender 6.4.2: "The System shall allow the Course Administrators to configure various types of discounts with complex and multi-tier hierarchical business rules and eligibility criteria, which include: // 1) Special discount, e.g. staff, alumni, Singapore citizens, etc // 2) Promotional discount..." | T8: Potential | U8: =IF(N8=1,"Smoke",IF(N8=2,"Regression Core","Regression Extended")) -> Regression Core
A9: DEF-008 | B9: Funding | C9: 2,3 | D9: 6.4.3 | E9: 4 Grant eligibility and fee | F9: TC-SCN-015-01 | G9: [Funding] Alumni Course Credit is deducted after the SSG grant instead of before | H9: SIT (assumed, ASM-01) | I9: 1. A course with an SSG grant and an alumnus with credit | J9: 1. Enrol an alumnus with a credit of 200 on a course of fee 1000 with an SSG grant 2. Open the fee calculation | K9: 1. The credit of 200 is deducted from the full fee of 1000 first 2. The SSG grant and the subsidy are then computed on the reduced fee | L9: The grant is computed on the full fee of 1000 and the credit is then deducted | M9: The net fee and the grant claimed from SSG are wrong | N9: 1 | O9: =IF(N9<=2,"High","Low") -> High | P9: High | Q9: =IF(O9="High",IF(P9="High","Critical","High"),IF(P9="High","Medium","Low")) -> Critical | R9: The order is stated in the Tender and affects the funding claim. Severity 1: Blocker, or money, funding or compliance break. Urgency High by ASM-92. | S9: Tender 6.4.3: "The System shall allow automation for application of grant, subsidies, SFC, SFC (mid-career) top up, ETSS, credits, discounts, PSEA, Alumni Course Credit (ACC), and Additional Funding Support (AFS applicable for SkillsFuture Career Transition Programme) for fee calculation. // Fo..." | T9: Potential | U9: =IF(N9=1,"Smoke",IF(N9=2,"Regression Core","Regression Extended")) -> Smoke
A10: DEF-009 | B10: Funding | C10: 2,3 | D10: 6.4.3 | E10: 4 Grant eligibility and fee | F10: TC-SCN-015-05 | G10: [Funding] A non eligible learner receives the SSG grant | H10: SIT (assumed, ASM-01) | I10: 1. An ineligible learner | J10: 1. Enrol an ineligible learner in an SSG funded course 2. Open the fee calculation | K10: 1. No grant or subsidy is applied and the full fee is shown | L10: The fee shows the SSG grant for an ineligible learner | M10: SSG funds are claimed without entitlement, a compliance break | N10: 1 | O10: =IF(N10<=2,"High","Low") -> High | P10: High | Q10: =IF(O10="High",IF(P10="High","Critical","High"),IF(P10="High","Medium","Low")) -> Critical | R10: Funding compliance break. Severity 1: Blocker, or money, funding or compliance break. Urgency High by ASM-92. | S10: Tender 6.4.3: "The System shall allow automation for application of grant, subsidies, SFC, SFC (mid-career) top up, ETSS, credits, discounts, PSEA, Alumni Course Credit (ACC), and Additional Funding Support (AFS applicable for SkillsFuture Career Transition Programme) for fee calculation. // Fo..." | T10: Potential | U10: =IF(N10=1,"Smoke",IF(N10=2,"Regression Core","Regression Extended")) -> Smoke
A11: DEF-010 | B11: Funding | C11: 2 | D11: 6.4.4 | E11: 7 Outcome based funding | F11: TC-SCN-016-02 | G11: [Funding] Learner with 74 percent attendance is marked eligible for SSG funding | H11: SIT (assumed, ASM-01) | I11: 1. A completed SSG funded course and a learner | J11: 1. Set attendance to 74 percent and the result to pass 2. Run the funding decision 3. Open the funding status | K11: 1. The learner is not eligible for the SSG funding | L11: The learner with 74 percent attendance and a pass is shown as funded | M11: SSG funding is claimed for a learner who does not qualify | N11: 1 | O11: =IF(N11<=2,"High","Low") -> High | P11: High | Q11: =IF(O11="High",IF(P11="High","Critical","High"),IF(P11="High","Medium","Low")) -> Critical | R11: Compliance break that can lead to a claw back. Severity 1: Blocker, or money, funding or compliance break. Urgency High by ASM-92. | S11: Tender 6.4.4: "The System shall support automated outcome based SkillsFuture Singapore (SSG) funding based on the following requirements: // 1) Minimum 75% attendance // 2) Passing the assessment" | T11: Potential | U11: =IF(N11=1,"Smoke",IF(N11=2,"Regression Core","Regression Extended")) -> Smoke
A12: DEF-011 | B12: Funding | C12: 2 | D12: 6.4.4 | E12: 7 Outcome based funding | F12: TC-SCN-016-03 | G12: [Funding] Learner who failed the assessment is marked eligible for SSG funding | H12: SIT (assumed, ASM-01) | I12: 1. A completed SSG funded course and a learner | J12: 1. Set attendance to 100 percent and the result to fail 2. Run the funding decision 3. Open the funding status | K12: 1. The learner is not eligible for the SSG funding | L12: The learner with 100 percent attendance and a fail is shown as funded | M12: Funding is claimed without a pass | N12: 1 | O12: =IF(N12<=2,"High","Low") -> High | P12: High | Q12: =IF(O12="High",IF(P12="High","Critical","High"),IF(P12="High","Medium","Low")) -> Critical | R12: Compliance break. Severity 1: Blocker, or money, funding or compliance break. Urgency High by ASM-92. | S12: Tender 6.4.4: "The System shall support automated outcome based SkillsFuture Singapore (SSG) funding based on the following requirements: // 1) Minimum 75% attendance // 2) Passing the assessment" | T12: Potential | U12: =IF(N12=1,"Smoke",IF(N12=2,"Regression Core","Regression Extended")) -> Smoke
A13: DEF-012 | B13: Funding | C13: 2 | D13: 6.4.5 | E13: 7 Outcome based funding | F13: TC-SCN-017-01 | G13: [Funding] Block grant is drawn down twice for one completed course | H13: SIT (assumed, ASM-01) | I13: 1. A completed funded course and a test endpoint | J13: 1. Complete an SSG funded course 2. Wait for the integration to run 3. Check the TPGateway test endpoint | K13: 1. The block grant of the completed course is drawn down through TPGateway | L13: The TPGateway test endpoint receives two draw downs for the same course | M13: Grant is over claimed | N13: 1 | O13: =IF(N13<=2,"High","Low") -> High | P13: High | Q13: =IF(O13="High",IF(P13="High","Critical","High"),IF(P13="High","Medium","Low")) -> Critical | R13: Money and compliance. Severity 1: Blocker, or money, funding or compliance break. Urgency High by ASM-92. | S13: Tender 6.4.5: "The System shall support the integration with Training Partners Gateway’s (TPGateway) Financial Management System for automated drawing down of block grants for completed courses." | T13: Potential | U13: =IF(N13=1,"Smoke",IF(N13=2,"Regression Core","Regression Extended")) -> Smoke
... A71: DEF-070 | B71: Funding | C71: 2 | D71: 18.3.3 | E71: 6 Net fee and invoice | F71: TC-SCN-160-01 | G71: [Funding] PSEA claim status stays submitted after the MOE file shows disbursed | H71: SIT (assumed, ASM-01) | I71: 1. A submitted PSEA claim and a status file | J71: 1. Load a MOE status file that shows a claim as disbursed 2. Open the PSEA claim | K71: 1. The claim status is disbursed | L71: The status is not updated | M71: The learner and finance see a wrong status | N71: 2 | O71: =IF(N71<=2,"High","Low") -> High | P71: High | Q71: =IF(O71="High",IF(P71="High","Critical","High"),IF(P71="High","Medium","Low")) -> Critical | R71: Status is wrong. Severity 2: Critical or major function fails. Urgency High by ASM-92. | S71: Tender 18.3.3: "The System shall automatically track and update the PSEA Fund Disbursement status based on the payment disbursement file or status received from MOE." | T71: Potential | U71: =IF(N71=1,"Smoke",IF(N71=2,"Regression Core","Regression Extended")) -> Regression Core

Sheet Assumptions
A1: ASM ID | B1: Type | C1: Requirement | D1: Original gap | E1: Assumption | F1: Nearest evidence | G1: Reason | H1: If the input differs | I1: State | J1: Affected TCs | K1: Question to confirm | L1: Resolution
A2: ASM-01 | B2: Dependency | C2: All clauses | D2: The Tender does not describe test environments, roles or sign in | E2: The SIT environment is ready, one account exists for each role named in a test (Learner, Corporate Customer, Course Administrator, Finance Administrator, System Administrator, Trainer) and the tester is signed in with that role | F2: Tender clause text only; no environment section | G2: Level 1: a test cannot start without an environment and a role. This is a condition of every test case, not a Tender requirement | H2: If sign in or roles differ, add a login step to the precondition of the affected test cases | I2: Open | J2: All test cases (327) | K2: Which SIT environment and which role accounts will the tester use?
A3: ASM-03 | B3: Dependency | C3: 2.2, 2.4, 8.2.5, 8.5.16, 18.1.2, 18.2.1, 18.2.2, 6.4.5, 9.1.4, 10.2.9 | D3: External systems are named but their test endpoints are not described | E3: SingPass, MyInfo, CorpPass, SSG, TPGateway, SFC gateway and PSEA are reachable in SIT through test endpoints or stubs | F3: Tender section 18, clauses on integration | G3: Level 1: integration clauses cannot be tested without a test counterpart | H3: If no test endpoint exists, the integration test cases are blocked and move to Reject | I3: Open | J3: TC-SCN-001-01, TC-SCN-001-02, TC-SCN-017-01, TC-SCN-017-02, TC-SCN-056-01, TC-SCN-056-02, TC-SCN-069-01, TC-SCN-069-02, TC-SCN-084-01, TC-SCN-084-02, TC-SCN-104-01, TC-SCN-104-02, TC-SCN-106-01, TC-SCN-112-01, TC-SCN-119-01, TC-SCN-132-01, TC-SCN-132-02, TC-SCN-151-01, TC-SCN-151-02, TC-SCN-152-01, TC-SCN-152-02, TC-SCN-152-03, TC-SCN-153-01, TC-SCN-154-01, TC-SCN-154-02, TC-SCN-155-01, TC-SCN-156-01, TC-SCN-157-01, TC-SCN-157-02 | K3: Which external test endpoints or stubs exist in SIT?
A4: ASM-10 | B4: Assumption | C4: 2.2, 2.4 | D4: The Tender does not state the message or page shown when authentication fails | E4: When authentication fails the user is not signed in and stays on or returns to the login page. The wording of the message is not checked | F4: Tender 2.2 and 2.4 only state that authentication is provided | G4: Level 1: not signing in is the least that a failed authentication must do. A message text would be invented | H4: If the Tender owner defines the message, add the exact text to Expected Result | I4: Open | J4: TC-SCN-001-02, TC-SCN-002-02 | K4: What does the user see when SingPass or OTP authentication fails?
A5: ASM-11 | B5: Assumption | C5: 8.1.4, 8.2.6 | D5: The Tender lists validation types but gives no limits or messages | E5: Validation uses the field rules configured for the registration form under test. The test case checks that each listed validation type exists, not the specific limit | F5: Tender 8.1.4: mandatory field, data type, format, minimum and maximum length, range, consistency, look up | G5: Level 1: no field limits appear in the Tender | H5: If limits are defined, add boundary values to Test Data | I5: Open | J5: TC-SCN-041-01, TC-SCN-041-02, TC-SCN-041-03 | K5: What are the field rules of the registration form?
A6: ASM-12 | B6: Assumption | C6: 8.2.7 | D6: The Tender does not state how long an application can stay incomplete or when reminders are sent | E6: The stipulated time and reminder timing are configured by the Administrator for the test and are not fixed by the Tender | F6: Tender 8.2.6 and 8.2.7 use the words stipulated time and automatic reminders | G6: Level 1: no duration is given | H6: If a duration is defined, use it as boundary data | I6: Open | J6: TC-SCN-057-01, TC-SCN-058-01, TC-SCN-077-01 | K6: What is the stipulated time and the reminder schedule?
A7: ASM-13 | B7: Assumption | C7: 8.1.10, 8.1.11 | D7: The Tender does not state the default minimum or maximum | E7: Minimum and maximum learner numbers are set by the Administrator for each course run. The test uses small values chosen by the tester | F7: Tender 8.1.10 | G7: Level 1: only the capability to configure is stated | H7: None for expected results | I7: Open | J7: TC-SCN-047-01, TC-SCN-047-02 | K7: What are the allowed ranges for minimum and maximum?
